Workbook
Name FAK: #REF!
Name PODNOR: '[1]R5 NOR'!#REF!
Name POLNOR: '[1]R5 NOR'!#REF!
Name RatesNOR: '[1]R5 NOR'!#REF!

Sheet CSE
A1: ONE ASIA-CARIBBEAN RATE GUIDELINE
C3: From | D3: To
A4: Validity period | C4: 46249 | D4: 46255
P5: not offer GTPBR till further notice | BH5: tempoarily suspend to TTPTS
C6: SERVICE SCOPE = CSE
C7: Manzanillo, PA | F7: Colon Free Zone (Door via Manzanillo, PA) | I7: Caucedo | L7: Moin | O7: PUERTO BARRIOS | R7: SANTO TOMAS DE CASTILLA | U7: Puerto Cortes | X7: Port of Spain | AA7: Kingston | AD7: Barranquilla | AG7: SANTA MARTA | AJ7: Cartagena(CONTECAR) | AM7: Georgetown | AP7: San Juan | AS7: Port Au Prince | AV7: Paramaribo | AY7: BRIDGETOWN | BB7: Barcadera | BE7: Willemstad | BH7: Point Liasa | BK7: Rio Haina
C8: PAMIT | F8: PACFZ | I8: DOCAU | L8: CRMOB | O8: GTPBR | R8: GTSTC | U8: HNPCR | X8: TTPOS | AA8: JMKIN | AD8: COBAQ | AG8: COSMR | AJ8: COCNR | AM8: GYGEO | AP8: PRSJU | AS8: HTPAP | AV8: SRPBM | AY8: BBBGI | BB8: AWORJ | BE8: CWWIL | BH8: TTPTS | BK8: DOHAI
A9: PLACE OF ORIGIN (POR) | B9: POR CODE | C9: D2 | D9: D4 | E9: D5 | F9: D2 | G9: D4 | H9: D5 | I9: D2 | J9: D4 | K9: D5 | L9: D2 | M9: D4 | N9: D5 | O9: D2 | P9: D4 | Q9: D5 | R9: D2 | S9: D4 | T9: D5 | U9: D2 | V9: D4 | W9: D5 | X9: D2 | Y9: D4 | Z9: D5 | AA9: D2 | AB9: D4 | AC9: D5 | AD9: D2 | AE9: D4 | AF9: D5 | AG9: D2 | AH9: D4 | AI9: D5 | AJ9: D2 | AK9: D4 | AL9: D5 | AM9: D2 | AN9: D4 | AO9: D5 | AP9: D2 | AQ9: D4 | AR9: D5 | AS9: D2 | AT9: D4 | AU9: D5 | AV9: D2 | AW9: D4 | AX9: D5 | AY9: D2 | AZ9: D4 | BA9: D5 | BB9: D2 | BC9: D4 | BD9: D5 | BE9: D2 | BF9: D4 | BG9: D5 | BH9: D2 | BI9: D4 | BJ9: D5 | BK9: D2 | BL9: D4 | BM9: D5
A10: FAR EAST BASE PORT | B10: FEBP | C10: 6800 | D10: 6800 | E10: 6800 | F10: 6900 | G10: 6900 | H10: 6900 | I10: 7500 | J10: 7500 | K10: 7500 | L10: 7700 | M10: 7700 | N10: 7700 | R10: 7700 | S10: 7700 | T10: 7700 | U10: 7500 | V10: 7500 | W10: 7500 | X10: 7500 | Y10: 7500 | Z10: 7500 | AA10: 7700 | AB10: 7700 | AC10: 7700 | AD10: 7500 | AE10: 7500 | AF10: 7500 | AG10: 7500 | AH10: 7500 | AI10: 7500 | AJ10: 7500 | AK10: 7500 | AL10: 7500 | AM10: 9500 | AN10: 9500 | AO10: 9500 | AP10: 8000 | AQ10: 8000 | AR10: 8000 | AS10: 8200 | AT10: 8200 | AU10: 8200 | AV10: 9500 | AW10: 9500 | AX10: 9500 | AY10: 9500 | AZ10: 9500 | BA10: 9500 | BB10: 9500 | BC10: 9500 | BD10: 9500 | BE10: 10500 | BF10: 10500 | BG10: 10500 | BH10: 6000 | BI10: 6000 | BJ10: 6000 | BK10: 7800 | BL10: 7800 | BM10: 7800
A11: KOREA | B11: KRPUS | C11: 6800 | D11: 6800 | E11: 6800 | F11: 6900 | G11: 6900 | H11: 6900 | I11: 7500 | J11: 7500 | K11: 7500 | L11: 7700 | M11: 7700 | N11: 7700 | R11: 7700 | S11: 7700 | T11: 7700 | U11: 7500 | V11: 7500 | W11: 7500 | X11: 7500 | Y11: 7500 | Z11: 7500 | AA11: 7700 | AB11: 7700 | AC11: 7700 | AD11: 7500 | AE11: 7500 | AF11: 7500 | AG11: 7500 | AH11: 7500 | AI11: 7500 | AJ11: 7500 | AK11: 7500 | AL11: 7500 | AM11: 9500 | AN11: 9500 | AO11: 9500 | AP11: 8000 | AQ11: 8000 | AR11: 8000 | AS11: 8200 | AT11: 8200 | AU11: 8200 | AV11: 9500 | AW11: 9500 | AX11: 9500 | AY11: 9500 | AZ11: 9500 | BA11: 9500 | BB11: 9500 | BC11: 9500 | BD11: 9500 | BE11: 10500 | BF11: 10500 | BG11: 10500 | BH11: 6000 | BI11: 6000 | BJ11: 6000 | BK11: 7800 | BL11: 7800 | BM11: 7800
A12: Taichung | B12: TWTXG | C12: 6800 | D12: 6800 | E12: 6800 | F12: 6900 | G12: 6900 | H12: 6900 | I12: 7500 | J12: 7500 | K12: 7500 | L12: 7700 | M12: 7700 | N12: 7700 | R12: 7700 | S12: 7700 | T12: 7700 | U12: 7500 | V12: 7500 | W12: 7500 | X12: 7500 | Y12: 7500 | Z12: 7500 | AA12: 7700 | AB12: 7700 | AC12: 7700 | AD12: 7500 | AE12: 7500 | AF12: 7500 | AG12: 7500 | AH12: 7500 | AI12: 7500 | AJ12: 7500 | AK12: 7500 | AL12: 7500 | AM12: 9500 | AN12: 9500 | AO12: 9500 | AP12: 8000 | AQ12: 8000 | AR12: 8000 | AS12: 8200 | AT12: 8200 | AU12: 8200 | AV12: 9500 | AW12: 9500 | AX12: 9500 | AY12: 9500 | AZ12: 9500 | BA12: 9500 | BB12: 9500 | BC12: 9500 | BD12: 9500 | BE12: 10500 | BF12: 10500 | BG12: 10500 | BH12: 6000 | BI12: 6000 | BJ12: 6000 | BK12: 7800 | BL12: 7800 | BM12: 7800
A13: Dalian | B13: CNDLC | C13: 6850 | D13: 6800 | E13: 6800 | F13: 6950 | G13: 6900 | H13: 6900 | I13: 7550 | J13: 7500 | K13: 7500 | L13: 7750 | M13: 7700 | N13: 7700 | R13: 7750 | S13: 7700 | T13: 7700 | U13: 7550 | V13: 7500 | W13: 7500 | X13: 7550 | Y13: 7500 | Z13: 7500 | AA13: 7750 | AB13: 7700 | AC13: 7700 | AD13: 7550 | AE13: 7500 | AF13: 7500 | AG13: 7550 | AH13: 7500 | AI13: 7500 | AJ13: 7550 | AK13: 7500 | AL13: 7500 | AM13: 9550 | AN13: 9500 | AO13: 9500 | AP13: 8050 | AQ13: 8000 | AR13: 8000 | AS13: 8250 | AT13: 8200 | AU13: 8200 | AV13: 9550 | AW13: 9500 | AX13: 9500 | AY13: 9550 | AZ13: 9500 | BA13: 9500 | BB13: 9550 | BC13: 9500 | BD13: 9500 | BE13: 10550 | BF13: 10500 | BG13: 10500 | BH13: 6050 | BI13: 6000 | BJ13: 6000 | BK13: 7850 | BL13: 7800 | BM13: 7800
A14: Xingang | B14: CNTXG | C14: 6850 | D14: 6800 | E14: 6800 | F14: 6950 | G14: 6900 | H14: 6900 | I14: 7550 | J14: 7500 | K14: 7500 | L14: 7750 | M14: 7700 | N14: 7700 | R14: 7750 | S14: 7700 | T14: 7700 | U14: 7550 | V14: 7500 | W14: 7500 | X14: 7550 | Y14: 7500 | Z14: 7500 | AA14: 7750 | AB14: 7700 | AC14: 7700 | AD14: 7550 | AE14: 7500 | AF14: 7500 | AG14: 7550 | AH14: 7500 | AI14: 7500 | AJ14: 7550 | AK14: 7500 | AL14: 7500 | AM14: 9550 | AN14: 9500 | AO14: 9500 | AP14: 8050 | AQ14: 8000 | AR14: 8000 | AS14: 8250 | AT14: 8200 | AU14: 8200 | AV14: 9550 | AW14: 9500 | AX14: 9500 | AY14: 9550 | AZ14: 9500 | BA14: 9500 | BB14: 9550 | BC14: 9500 | BD14: 9500 | BE14: 10550 | BF14: 10500 | BG14: 10500 | BH14: 6050 | BI14: 6000 | BJ14: 6000 | BK14: 7850 | BL14: 7800 | BM14: 7800
A15: Fuzhou | B15: CNFOC | C15: 6900 | D15: 7000 | E15: 7000 | F15: 7000 | G15: 7100 | H15: 7100 | I15: 7600 | J15: 7700 | K15: 7700 | L15: 7800 | M15: 7900 | N15: 7900 | R15: 7800 | S15: 7900 | T15: 7900 | U15: 7600 | V15: 7700 | W15: 7700 | X15: 7600 | Y15: 7700 | Z15: 7700 | AA15: 7800 | AB15: 7900 | AC15: 7900 | AD15: 7600 | AE15: 7700 | AF15: 7700 | AG15: 7600 | AH15: 7700 | AI15: 7700 | AJ15: 7600 | AK15: 7700 | AL15: 7700 | AM15: 9600 | AN15: 9700 | AO15: 9700 | AP15: 8100 | AQ15: 8200 | AR15: 8200 | AS15: 8300 | AT15: 8400 | AU15: 8400 | AV15: 9600 | AW15: 9700 | AX15: 9700 | AY15: 9600 | AZ15: 9700 | BA15: 9700 | BB15: 9600 | BC15: 9700 | BD15: 9700 | BE15: 10600 | BF15: 10700 | BG15: 10700 | BH15: 6100 | BI15: 6200 | BJ15: 6200 | BK15: 7900 | BL15: 8000 | BM15: 8000
A16: Fuqing | B16: CNFUG | C16: 6900 | D16: 7000 | E16: 7000 | F16: 7000 | G16: 7100 | H16: 7100 | I16: 7600 | J16: 7700 | K16: 7700 | L16: 7800 | M16: 7900 | N16: 7900 | R16: 7800 | S16: 7900 | T16: 7900 | U16: 7600 | V16: 7700 | W16: 7700 | X16: 7600 | Y16: 7700 | Z16: 7700 | AA16: 7800 | AB16: 7900 | AC16: 7900 | AD16: 7600 | AE16: 7700 | AF16: 7700 | AG16: 7600 | AH16: 7700 | AI16: 7700 | AJ16: 7600 | AK16: 7700 | AL16: 7700 | AM16: 9600 | AN16: 9700 | AO16: 9700 | AP16: 8100 | AQ16: 8200 | AR16: 8200 | AS16: 8300 | AT16: 8400 | AU16: 8400 | AV16: 9600 | AW16: 9700 | AX16: 9700 | AY16: 9600 | AZ16: 9700 | BA16: 9700 | BB16: 9600 | BC16: 9700 | BD16: 9700 | BE16: 10600 | BF16: 10700 | BG16: 10700 | BH16: 6100 | BI16: 6200 | BJ16: 6200 | BK16: 7900 | BL16: 8000 | BM16: 8000
A17: Huangpu | B17: CNHUA | C17: 6850 | D17: 6900 | E17: 6900 | F17: 6950 | G17: 7000 | H17: 7000 | I17: 7550 | J17: 7600 | K17: 7600 | L17: 7750 | M17: 7800 | N17: 7800 | R17: 7750 | S17: 7800 | T17: 7800 | U17: 7550 | V17: 7600 | W17: 7600 | X17: 7550 | Y17: 7600 | Z17: 7600 | AA17: 7750 | AB17: 7800 | AC17: 7800 | AD17: 7550 | AE17: 7600 | AF17: 7600 | AG17: 7550 | AH17: 7600 | AI17: 7600 | AJ17: 7550 | AK17: 7600 | AL17: 7600 | AM17: 9550 | AN17: 9600 | AO17: 9600 | AP17: 8050 | AQ17: 8100 | AR17: 8100 | AS17: 8250 | AT17: 8300 | AU17: 8300 | AV17: 9550 | AW17: 9600 | AX17: 9600 | AY17: 9550 | AZ17: 9600 | BA17: 9600 | BB17: 9550 | BC17: 9600 | BD17: 9600 | BE17: 10550 | BF17: 10600 | BG17: 10600 | BH17: 6050 | BI17: 6100 | BJ17: 6100 | BK17: 7850 | BL17: 7900 | BM17: 7900
A18: PEARL RIVER DELTA | B18: WPRD | C18: 6875 | D18: 6950 | E18: 6950 | F18: 6975 | G18: 7050 | H18: 7050 | I18: 7575 | J18: 7650 | K18: 7650 | L18: 7775 | M18: 7850 | N18: 7850 | R18: 7775 | S18: 7850 | T18: 7850 | U18: 7575 | V18: 7650 | W18: 7650 | X18: 7575 | Y18: 7650 | Z18: 7650 | AA18: 7775 | AB18: 7850 | AC18: 7850 | AD18: 7575 | AE18: 7650 | AF18: 7650 | AG18: 7575 | AH18: 7650 | AI18: 7650 | AJ18: 7575 | AK18: 7650 | AL18: 7650 | AM18: 9575 | AN18: 9650 | AO18: 9650 | AP18: 8075 | AQ18: 8150 | AR18: 8150 | AS18: 8275 | AT18: 8350 | AU18: 8350 | AV18: 9575 | AW18: 9650 | AX18: 9650 | AY18: 9575 | AZ18: 9650 | BA18: 9650 | BB18: 9575 | BC18: 9650 | BD18: 9650 | BE18: 10575 | BF18: 10650 | BG18: 10650 | BH18: 6075 | BI18: 6150 | BJ18: 6150 | BK18: 7875 | BL18: 7950 | BM18: 7950
A19: Qinzhou | B19: CNQZH | C19: 6900 | D19: 7050 | E19: 7050 | F19: 7000 | G19: 7150 | H19: 7150 | I19: 7600 | J19: 7750 | K19: 7750 | L19: 7800 | M19: 7950 | N19: 7950 | R19: 7800 | S19: 7950 | T19: 7950 | U19: 7600 | V19: 7750 | W19: 7750 | X19: 7600 | Y19: 7750 | Z19: 7750 | AA19: 7800 | AB19: 7950 | AC19: 7950 | AD19: 7600 | AE19: 7750 | AF19: 7750 | AG19: 7600 | AH19: 7750 | AI19: 7750 | AJ19: 7600 | AK19: 7750 | AL19: 7750 | AM19: 9600 | AN19: 9750 | AO19: 9750 | AP19: 8100 | AQ19: 8250 | AR19: 8250 | AS19: 8300 | AT19: 8450 | AU19: 8450 | AV19: 9600 | AW19: 9750 | AX19: 9750 | AY19: 9600 | AZ19: 9750 | BA19: 9750 | BB19: 9600 | BC19: 9750 | BD19: 9750 | BE19: 10600 | BF19: 10750 | BG19: 10750 | BH19: 6100 | BI19: 6250 | BJ19: 6250 | BK19: 7900 | BL19: 8050 | BM19: 8050
A20: Ho Chi Minh | B20: VNSGN | C20: 6850 | D20: 6900 | E20: 6900 | F20: 6950 | G20: 7000 | H20: 7000 | I20: 7550 | J20: 7600 | K20: 7600 | L20: 7750 | M20: 7800 | N20: 7800 | R20: 7750 | S20: 7800 | T20: 7800 | U20: 7550 | V20: 7600 | W20: 7600 | X20: 7550 | Y20: 7600 | Z20: 7600 | AA20: 7750 | AB20: 7800 | AC20: 7800 | AD20: 7550 | AE20: 7600 | AF20: 7600 | AG20: 7550 | AH20: 7600 | AI20: 7600 | AJ20: 7550 | AK20: 7600 | AL20: 7600 | AM20: 9550 | AN20: 9600 | AO20: 9600 | AP20: 8050 | AQ20: 8100 | AR20: 8100 | AS20: 8250 | AT20: 8300 | AU20: 8300 | AV20: 9550 | AW20: 9600 | AX20: 9600 | AY20: 9550 | AZ20: 9600 | BA20: 9600 | BB20: 9550 | BC20: 9600 | BD20: 9600 | BE20: 10550 | BF20: 10600 | BG20: 10600 | BH20: 6050 | BI20: 6100 | BJ20: 6100 | BK20: 7850 | BL20: 7900 | BM20: 7900
A21: BIEN HOA | B21: VNBHA | C21: 6850 | D21: 6900 | E21: 6900 | F21: 6950 | G21: 7000 | H21: 7000 | I21: 7550 | J21: 7600 | K21: 7600 | L21: 7750 | M21: 7800 | N21: 7800 | R21: 7750 | S21: 7800 | T21: 7800 | U21: 7550 | V21: 7600 | W21: 7600 | X21: 7550 | Y21: 7600 | Z21: 7600 | AA21: 7750 | AB21: 7800 | AC21: 7800 | AD21: 7550 | AE21: 7600 | AF21: 7600 | AG21: 7550 | AH21: 7600 | AI21: 7600 | AJ21: 7550 | AK21: 7600 | AL21: 7600 | AM21: 9550 | AN21: 9600 | AO21: 9600 | AP21: 8050 | AQ21: 8100 | AR21: 8100 | AS21: 8250 | AT21: 8300 | AU21: 8300 | AV21: 9550 | AW21: 9600 | AX21: 9600 | AY21: 9550 | AZ21: 9600 | BA21: 9600 | BB21: 9550 | BC21: 9600 | BD21: 9600 | BE21: 10550 | BF21: 10600 | BG21: 10600 | BH21: 6050 | BI21: 6100 | BJ21: 6100 | BK21: 7850 | BL21: 7900 | BM21: 7900
... A78: Bahrain | B78: BHBAH | C78: 7300 | D78: 7550 | E78: 7550 | F78: 7400 | G78: 7650 | H78: 7650 | I78: 8000 | J78: 8250 | K78: 8250 | L78: 8200 | M78: 8450 | N78: 8450 | R78: 8200 | S78: 8450 | T78: 8450 | U78: 8000 | V78: 8250 | W78: 8250 | X78: 8000 | Y78: 8250 | Z78: 8250 | AA78: 8200 | AB78: 8450 | AC78: 8450 | AD78: 8000 | AE78: 8250 | AF78: 8250 | AG78: 8000 | AH78: 8250 | AI78: 8250 | AJ78: 8000 | AK78: 8250 | AL78: 8250 | AM78: 10000 | AN78: 10250 | AO78: 10250 | AP78: 8500 | AQ78: 8750 | AR78: 8750 | AS78: 8700 | AT78: 8950 | AU78: 8950 | AV78: 10000 | AW78: 10250 | AX78: 10250 | AY78: 10000 | AZ78: 10250 | BA78: 10250 | BB78: 10000 | BC78: 10250 | BD78: 10250 | BE78: 11000 | BF78: 11250 | BG78: 11250 | BH78: 6500 | BI78: 6750 | BJ78: 6750 | BK78: 8300 | BL78: 8550 | BM78: 8550
A82: FEBP = current base port : Pusan/Shanghai/Ningbo/Qingdao/Xiamen/Yantian/Shekou /Hong Kong/Keelung/Kaohsiung/Taoyuan/Singapore
A83: WPRD = current PRD ports : Zhongshan/Zhuhai/Jiangmen/Nansha/Foshan/Sanshan/Rongqi/Beijiao/Xiaolan/Zhanjiang/Shantou/Gaolan/Leliu/Gaoming/Sanshui/Zhoaqing/Jiujiang,guangdong
A85: - Above rate offer is applicable for non-DG commodity only.
A86: Rates are incl. PSS/OBS/EFS /MBS only, subject to CSS/THL/THD/Tariff Surcharges both ends/ PCT/HEA/ADD/CCC/EVC/ISL/AMS & GAT(for CR destination)/IFD
A87: Heavy Weight surcharge (HEA): Nil for cargo weight upto 17.99 tons. USD200 per 20ft for cargo weight over 18 tons
A90: ONE Bunker Surcharge (OBS): usd 320/640/640/640 per D2/D4/D5/R5 NOR during Q3 2026 (Jul-Sep)
A91: * Chittagong: Rates are incl. THL/PSS/OBS/EFS/MBS subject to CSS/THD/Tariff Surcharges both ends/PCT/HEA/ CCC/EVC/ISL /AMS(for CR destination)/IFD
A92: * Colombo: Rates are incl.THL/CSS/SLF /PSS/OBS/EFS/MBS subject to THD/destination tariff surcharges/ PCT /HEA/CCC/EVC/ISL/AMS(for CR destination) /IFD
A93: * Jebel Ali/Jeddah (Gulf area): Rates are incl. PSS/OBS/EFS/MBS subject to WRC/CSS/THL/THD/Tariff Surcharges both ends/PCT /HEA/CCC/EVC/ISL/AMS(for CR destination) /IFD
A95: PCT amount increased eff from 10 AUG 2026 . USD 100/TEU
A98: IMPORTANT
A99: Note:
... A101: 2. Haiti is one of the country under "Need Due Diligence list ", due diligence procedures is required . Haiti's Booking checking procedure would be the SAME AS the one placed in Nicaragua.

Sheet NOR(PA)
A1: ONE ASIA-CARIBBEAN RATE GUIDELINE
C3: From | D3: To
A4: Validity period | C4: =CSE!C4 -> 46249 | D4: =CSE!D4 -> 46255
C6: Manzanillo, PA | D6: Colon Free Zone (Door via Manzanillo, PA)
C7: PAMIT | D7: PACFZ
A8: PLACE OF ORIGIN (POR) | B8: POR CODE | C8: R5 NOR | D8: R5 NOR
A9: FAR EAST BASE PORT | B9: FEBP | C9: 5800 | D9: 5900
A10: Korea | B10: KRPUS | C10: 5800 | D10: 5900
A11: Dalian | B11: CNDLC | C11: 5800 | D11: 5900
A12: Xingang | B12: CNTXG | C12: 5800 | D12: 5900
A13: Taichung | B13: TWTXG | C13: 5800 | D13: 5900
A14: Huangpu | B14: CNHUA | C14: 5900 | D14: 6000
A15: PEARL RIVER DELTA | B15: WPRD | C15: 5950 | D15: 6050
A16: Ho Chi Minh | B16: VNSGN | C16: 5900 | D16: 6000
A17: BIEN HOA | B17: VNBHA | C17: 5900 | D17: 6000
A18: DI AN | B18: VNDIA | C18: 5900 | D18: 6000
A19: CAI MEP | B19: VNCMP | C19: 5900 | D19: 6000
A20: Haiphong | B20: VNHPH | C20: 5900 | D20: 6000
... A25: Manila | B25: PHMNL | C25: 6000 | D25: 6100
A27: FEBP = current base port : Pusan/Shanghai/Ningbo/Qingdao/Xiamen/Yantian/Shekou /Hong Kong/Keelung/Kaohsiung/Taoyuan/Singapore
A28: WPRD = current PRD ports : Zhongshan/Zhuhai/Jiangmen/Nansha/Foshan/Sanshan/Rongqi/Beijiao/Xiaolan/Zhanjiang/Shantou/Gaolan/Leliu/Gaoming/Sanshui/Zhoaqing/Jiujiang,guangdong
A30: - Above rate offer is applicable for non-DG commodity only.
A31: Rates are incl. PSS /OBS/EFS/MBS subject to CSS/THL/THD/Tariff Surcharges both ends/ PCT /HEA/ADD /IFD
A32: Heavy Weight surcharge (HEA): Nil for cargo weight upto 17.99 tons. USD200 per 20ft for cargo weight over 18 tons
A33: PCT amount increased eff from 10 AUG 2026 . USD 100/TEU
A34: ONE Bunker Surcharge (OBS): usd 119/238/238/238 per D2/D4/D5/R5 NOR during Q2 2026 (Apr-Jun)

Sheet CSE (MAOVLD)
A1: ONE ASIA-CARIBBEAN RATE GUIDELINE
C3: From | D3: To
A4: Validity period | C4: =CSE!C4 -> 46249 | D4: =CSE!D4 -> 46255
C6: Manaus | F6: Vila do Conde
C7: BRMAO | F7: BRVLD
A8: PLACE OF ORIGIN (POR) | B8: POR CODE | C8: D2 | D8: D4 | E8: D5 | F8: D2 | G8: D4 | H8: D5
A9: FAR EAST BASE PORT | B9: FEBP | C9: 8600 | D9: 8600 | E9: 8600 | F9: 8600 | G9: 8600 | H9: 8600
A10: Korea | B10: KRPUS | C10: 8600 | D10: 8600 | E10: 8600 | F10: 8600 | G10: 8600 | H10: 8600
A11: Taichung | B11: TWTXG | C11: 8600 | D11: 8600 | E11: 8600 | F11: 8600 | G11: 8600 | H11: 8600
A12: Dalian | B12: CNDLC | C12: 8650 | D12: 8600 | E12: 8600 | F12: 8650 | G12: 8600 | H12: 8600
A13: Xingang | B13: CNTXG | C13: 8650 | D13: 8600 | E13: 8600 | F13: 8650 | G13: 8600 | H13: 8600
A14: Fuzhou | B14: CNFOC | C14: 8700 | D14: 8800 | E14: 8800 | F14: 8700 | G14: 8800 | H14: 8800
A15: Fuqing | B15: CNFUG | C15: 8700 | D15: 8800 | E15: 8800 | F15: 8700 | G15: 8800 | H15: 8800
A16: Huangpu | B16: CNHUA | C16: 8650 | D16: 8700 | E16: 8700 | F16: 8650 | G16: 8700 | H16: 8700
A17: PEARL RIVER DELTA | B17: WPRD | C17: 8675 | D17: 8750 | E17: 8750 | F17: 8675 | G17: 8750 | H17: 8750
A18: Qinzhou | B18: CNQZH | C18: 8700 | D18: 8850 | E18: 8850 | F18: 8700 | G18: 8850 | H18: 8850
A19: Ho Chi Minh | B19: VNSGN | C19: 8650 | D19: 8700 | E19: 8700 | F19: 8650 | G19: 8700 | H19: 8700
A20: BIEN HOA | B20: VNBHA | C20: 8650 | D20: 8700 | E20: 8700 | F20: 8650 | G20: 8700 | H20: 8700
... A77: Bahrain | B77: BHBAH | C77: 9100 | D77: 9350 | E77: 9350 | F77: 9100 | G77: 9350 | H77: 9350
A79: FEBP = current base port : Pusan/Shanghai/Ningbo/Qingdao/Xiamen/Yantian/Shekou /Hong Kong/Keelung/Kaohsiung/Taoyuan/Singapore
A80: WPRD = current PRD ports : Zhongshan/Zhuhai/Jiangmen/Nansha/Foshan/Sanshan/Rongqi/Beijiao/Xiaolan/Zhanjiang/Shantou/Gaolan/Leliu/Gaoming/Sanshui/Zhoaqing/Jiujiang,guangdong
A82: - Above rate offer is applicable for non-DG commodity only.
A83: Rates are incl. PSS/OBS/EFS/MBS subject to CSS/THL/THD/Tariff Surcharges both ends/ PCT /HEA /CCC
A85: Heavy Weight surcharge (HEA): Nil for cargo weight upto 17.99 tons. USD200 per 20ft for cargo weight over 18 tons
A86: Sulphur Fuel surcharge (LSF) of US$3/TEU for all Korea export and import cargoes as from November 1st 2020 (based on freight application date at origin side).
A87: * Chittagong: Rates are incl. THL/PSS /OBS/EFS /MBS subject to CSS/THD/Tariff Surcharges both ends/PCT /HEA/CCC
A88: * Colombo: Rates are incl.THL/CSS/SLF/PSS/OBS /EFS/MBS , subject to THD/destination tariff surcharges/ PCT /HEA/CCC
A89: * Jebel Ali/Jeddah (Gulf area): Rates are incl. PSS/OBS /EFS/MBS subject to WRC/CSS/THL/THD/Tariff Surcharges both ends/PCT / HEA/CCC
A92: =CSE!A90 -> ONE Bunker Surcharge (OBS): usd 320/640/640/640 per D2/D4/D5/R5 NOR during Q3 2026 (Jul-Sep)
A95: PCT amount increased eff from 10 AUG 2026 . USD 100/TEU

Sheet NOR (MAOVLD)
A1: ONE ASIA-CARIBBEAN RATE GUIDELINE
C3: From | D3: To
A4: Validity period | C4: =CSE!C4 -> 46249 | D4: =CSE!D4 -> 46255
C6: Manaus | D6: Vila do Conde
C7: BRMAO | D7: BRVLD
A8: PLACE OF ORIGIN (POR) | B8: POR CODE | C8: R5 NOR | D8: R5 NOR
A9: FAR EAST BASE PORT | B9: FEBP | C9: 7300 | D9: 7300
A10: Korea | B10: KRPUS | C10: 7300 | D10: 7300
A11: Dalian | B11: CNDLC | C11: 7300 | D11: 7300
A12: Xingang | B12: CNTXG | C12: 7300 | D12: 7300
A13: Taichung | B13: TWTXG | C13: 7300 | D13: 7300
A14: Huangpu | B14: CNHUA | C14: 7400 | D14: 7400
A15: PEARL RIVER DELTA | B15: WPRD | C15: 7450 | D15: 7450
A16: Ho Chi Minh | B16: VNSGN | C16: 7400 | D16: 7400
A17: BIEN HOA | B17: VNBHA | C17: 7400 | D17: 7400
A18: DI AN | B18: VNDIA | C18: 7400 | D18: 7400
A19: CAI MEP | B19: VNCMP | C19: 7400 | D19: 7400
A20: Haiphong | B20: VNHPH | C20: 7400 | D20: 7400
... A25: Manila | B25: PHMNL | C25: 7500 | D25: 7500
A27: FEBP = current base port : Pusan/Shanghai/Ningbo/Qingdao/Xiamen/Yantian/Shekou /Hong Kong/Keelung/Kaohsiung/Taoyuan/Singapore
A28: WPRD = current PRD ports : Zhongshan/Zhuhai/Jiangmen/Nansha/Foshan/Sanshan/Rongqi/Beijiao/Xiaolan/Zhanjiang/Shantou/Gaolan/Leliu/Gaoming/Sanshui/Zhoaqing/Jiujiang,guangdong
A30: - Above rate offer is applicable for non-DG commodity only.
A31: Rates are incl. PSS/OBS/EFS/MBS subject to CSS/THL/THD/Tariff Surcharges both ends/ PCT /HEA /CCC
A33: Heavy Weight surcharge (HEA): Nil for cargo weight upto 17.99 tons. USD200 per 20ft for cargo weight over 18 tons
A37: =CSE!A90 -> ONE Bunker Surcharge (OBS): usd 320/640/640/640 per D2/D4/D5/R5 NOR during Q3 2026 (Jul-Sep)
A40: PCT amount increased eff from 10 AUG 2026 . USD 100/TEU

Sheet In guage guideline
A1: ONE ASIA-CARIBBEAN RATE GUIDELINE
C3: From | D3: To
A4: Validity period | C4: =CSE!C4 -> 46249 | D4: =CSE!D4 -> 46255
W5: we offer COCNR only | AE5: tempoarily suspend to TTPTS
C6: Manzanillo, PA | E6: Colon Free Zone (Door via Manzanillo, PA) | G6: Caucedo | I6: Moin | K6: SANTO TOMAS DE CASTILLA | M6: Puerto Cortes | O6: Port of Spain | Q6: Kingston | S6: Barranquilla | U6: Cartagena(CONTECAR) | W6: Cartagena(SPRC) | Y6: SAN JUAN | AA6: Manaus | AC6: Vila do Conde | AE6: Point Lisas | AG6: Georgetown
C7: PAMIT | E7: PACFZ | G7: DOCAU | I7: CRMOB | K7: GTSTC | M7: HNPCR | O7: TTPOS | Q7: JMKIN | S7: COBAQ | U7: COCNR | W7: COSPC | Y7: PRSJU | AA7: BRMAO | AC7: BRVLD | AE7: TTPTS | AG7: GYGEO
A8: PLACE OF ORIGIN (POR) | B8: POR CODE | C8: 20'OT/FR (IG) | D8: 40'OT/FR (IG) | E8: 20'OT/FR (IG) | F8: 40'OT/FR (IG) | G8: 20'OT/FR (IG) | H8: 40'OT/FR (IG) | I8: 20'OT/FR (IG) | J8: 40'OT/FR (IG) | K8: 20'OT/FR (IG) | L8: 40'OT/FR (IG) | M8: 20'OT/FR (IG) | N8: 40'OT/FR (IG) | O8: 20'OT/FR (IG) | P8: 40'OT/FR (IG) | Q8: 20'OT/FR (IG) | R8: 40'OT/FR (IG) | S8: 20'OT/FR (IG) | T8: 40'OT/FR (IG) | U8: 20'OT/FR (IG) | V8: 40'OT/FR (IG) | Y8: 20'OT/FR (IG) | Z8: 40'OT/FR (IG) | AA8: 20'OT/FR (IG) | AB8: 40'OT/FR (IG) | AC8: 20'OT/FR (IG) | AD8: 40'OT/FR (IG) | AG8: 20'OT/FR (IG) | AH8: 40'OT/FR (IG)
A9: FAR EAST BASE PORT | B9: FEBP | C9: 7400 | D9: 7800 | E9: 7500 | F9: 7900 | G9: 8100 | H9: 8500 | I9: 8300 | J9: 8700 | K9: 8300 | L9: 8700 | M9: 8100 | N9: 8500 | O9: 8100 | P9: 8500 | Q9: 8300 | R9: 8700 | S9: 8100 | T9: 8500 | U9: 8100 | V9: 8500 | Y9: 8600 | Z9: 9000 | AA9: 9200 | AB9: 9600 | AC9: 9200 | AD9: 9600 | AE9: 8600 | AF9: 9000 | AG9: 10100 | AH9: 10500
A10: Korea | B10: KRPUS | C10: 7400 | D10: 7800 | E10: 7500 | F10: 7900 | G10: 8100 | H10: 8500 | I10: 8300 | J10: 8700 | K10: 8300 | L10: 8700 | M10: 8100 | N10: 8500 | O10: 8100 | P10: 8500 | Q10: 8300 | R10: 8700 | S10: 8100 | T10: 8500 | U10: 8100 | V10: 8500 | Y10: 8600 | Z10: 9000 | AA10: 9200 | AB10: 9600 | AC10: 9200 | AD10: 9600 | AE10: 8600 | AF10: 9000 | AG10: 10100 | AH10: 10500
A11: Taichung | B11: TWTXG | C11: 7400 | D11: 7800 | E11: 7500 | F11: 7900 | G11: 8100 | H11: 8500 | I11: 8300 | J11: 8700 | K11: 8300 | L11: 8700 | M11: 8100 | N11: 8500 | O11: 8100 | P11: 8500 | Q11: 8300 | R11: 8700 | S11: 8100 | T11: 8500 | U11: 8100 | V11: 8500 | Y11: 8600 | Z11: 9000 | AA11: 9200 | AB11: 9600 | AC11: 9200 | AD11: 9600 | AE11: 8600 | AF11: 9000 | AG11: 10100 | AH11: 10500
A12: Dalian | B12: CNDLC | C12: 7450 | D12: 7800 | E12: 7550 | F12: 7900 | G12: 8150 | H12: 8500 | I12: 8350 | J12: 8700 | K12: 8350 | L12: 8700 | M12: 8150 | N12: 8500 | O12: 8150 | P12: 8500 | Q12: 8350 | R12: 8700 | S12: 8150 | T12: 8500 | U12: 8150 | V12: 8500 | Y12: 8650 | Z12: 9000 | AA12: 9250 | AB12: 9600 | AC12: 9250 | AD12: 9600 | AE12: 8650 | AF12: 9000 | AG12: 10150 | AH12: 10500
A13: Xingang | B13: CNTXG | C13: 7450 | D13: 7800 | E13: 7550 | F13: 7900 | G13: 8150 | H13: 8500 | I13: 8350 | J13: 8700 | K13: 8350 | L13: 8700 | M13: 8150 | N13: 8500 | O13: 8150 | P13: 8500 | Q13: 8350 | R13: 8700 | S13: 8150 | T13: 8500 | U13: 8150 | V13: 8500 | Y13: 8650 | Z13: 9000 | AA13: 9250 | AB13: 9600 | AC13: 9250 | AD13: 9600 | AE13: 8650 | AF13: 9000 | AG13: 10150 | AH13: 10500
A14: Fuzhou | B14: CNFOC | C14: 7500 | D14: 8000 | E14: 7600 | F14: 8100 | G14: 8200 | H14: 8700 | I14: 8400 | J14: 8900 | K14: 8400 | L14: 8900 | M14: 8200 | N14: 8700 | O14: 8200 | P14: 8700 | Q14: 8400 | R14: 8900 | S14: 8200 | T14: 8700 | U14: 8200 | V14: 8700 | Y14: 8700 | Z14: 9200 | AA14: 9300 | AB14: 9800 | AC14: 9300 | AD14: 9800 | AE14: 8700 | AF14: 9200 | AG14: 10200 | AH14: 10700
A15: Fuqing | B15: CNFUG | C15: 7500 | D15: 8000 | E15: 7600 | F15: 8100 | G15: 8200 | H15: 8700 | I15: 8400 | J15: 8900 | K15: 8400 | L15: 8900 | M15: 8200 | N15: 8700 | O15: 8200 | P15: 8700 | Q15: 8400 | R15: 8900 | S15: 8200 | T15: 8700 | U15: 8200 | V15: 8700 | Y15: 8700 | Z15: 9200 | AA15: 9300 | AB15: 9800 | AC15: 9300 | AD15: 9800 | AE15: 8700 | AF15: 9200 | AG15: 10200 | AH15: 10700
A16: Huangpu | B16: CNHUA | C16: 7450 | D16: 7900 | E16: 7550 | F16: 8000 | G16: 8150 | H16: 8600 | I16: 8350 | J16: 8800 | K16: 8350 | L16: 8800 | M16: 8150 | N16: 8600 | O16: 8150 | P16: 8600 | Q16: 8350 | R16: 8800 | S16: 8150 | T16: 8600 | U16: 8150 | V16: 8600 | Y16: 8650 | Z16: 9100 | AA16: 9250 | AB16: 9700 | AC16: 9250 | AD16: 9700 | AE16: 8650 | AF16: 9100 | AG16: 10150 | AH16: 10600
A17: PEARL RIVER DELTA | B17: WPRD | C17: 7475 | D17: 7750 | E17: 7575 | F17: 7850 | G17: 8175 | H17: 8450 | I17: 8375 | J17: 8650 | K17: 8375 | L17: 8650 | M17: 8175 | N17: 8450 | O17: 8175 | P17: 8450 | Q17: 8375 | R17: 8650 | S17: 8175 | T17: 8450 | U17: 8175 | V17: 8450 | Y17: 8675 | Z17: 8950 | AA17: 9275 | AB17: 9550 | AC17: 9275 | AD17: 9550 | AE17: 8675 | AF17: 8950 | AG17: 10175 | AH17: 10450
A18: Qinzhou | B18: CNQZH | C18: 7500 | D18: 7850 | E18: 7600 | F18: 7950 | G18: 8200 | H18: 8550 | I18: 8400 | J18: 8750 | K18: 8400 | L18: 8750 | M18: 8200 | N18: 8550 | O18: 8200 | P18: 8550 | Q18: 8400 | R18: 8750 | S18: 8200 | T18: 8550 | U18: 8200 | V18: 8550 | Y18: 8700 | Z18: 9050 | AA18: 9300 | AB18: 9650 | AC18: 9300 | AD18: 9650 | AE18: 8700 | AF18: 9050 | AG18: 10200 | AH18: 10550
A19: Ho Chi Minh | B19: VNSGN | C19: 7450 | D19: 7700 | E19: 7550 | F19: 7800 | G19: 8150 | H19: 8400 | I19: 8350 | J19: 8600 | K19: 8350 | L19: 8600 | M19: 8150 | N19: 8400 | O19: 8150 | P19: 8400 | Q19: 8350 | R19: 8600 | S19: 8150 | T19: 8400 | U19: 8150 | V19: 8400 | Y19: 8650 | Z19: 8900 | AA19: 9250 | AB19: 9500 | AC19: 9250 | AD19: 9500 | AE19: 8650 | AF19: 8900 | AG19: 10150 | AH19: 10400
A20: BIEN HOA | B20: VNBHA | C20: 7450 | D20: 7700 | E20: 7550 | F20: 7800 | G20: 8150 | H20: 8400 | I20: 8350 | J20: 8600 | K20: 8350 | L20: 8600 | M20: 8150 | N20: 8400 | O20: 8150 | P20: 8400 | Q20: 8350 | R20: 8600 | S20: 8150 | T20: 8400 | U20: 8150 | V20: 8400 | Y20: 8650 | Z20: 8900 | AA20: 9250 | AB20: 9500 | AC20: 9250 | AD20: 9500 | AE20: 8650 | AF20: 8900 | AG20: 10150 | AH20: 10400
... A77: Bahrain | B77: BHBAH | C77: 7800 | D77: 8550 | E77: 7900 | F77: 8650 | G77: 8500 | H77: 9250 | I77: 8700 | J77: 9450 | K77: 8700 | L77: 9450 | M77: 8500 | N77: 9250 | O77: 8500 | P77: 9250 | Q77: 8700 | R77: 9450 | S77: 8500 | T77: 9250 | U77: 8500 | V77: 9250 | Y77: 9000 | Z77: 9750 | AA77: 9600 | AB77: 10350 | AC77: 9600 | AD77: 10350 | AE77: 9000 | AF77: 9750 | AG77: 10500 | AH77: 11250
A81: FEBP = current base port : Pusan/Shanghai/Ningbo/Qingdao/Xiamen/Yantian/Shekou /Hong Kong/Keelung/Kaohsiung/Taoyuan/Singapore
A82: WPRD = current PRD ports : Zhongshan/Zhuhai/Jiangmen/Nansha/Foshan/Sanshan/Rongqi/Beijiao/Xiaolan/Zhanjiang/Shantou/Gaolan/Leliu/Gaoming/Sanshui/Zhoaqing/Jiujiang,guangdong
A83: 'Heavy Weight surcharge (HEA):Nil for cargo weight upto 17.99 tons. USD200 per 20ft for cargo weight over 18 tons
A85: - Above rate offer is applicable for non-DG commodity only.
A86: Heavy Weight surcharge (HEA):
A87: Nil for cargo weight upto 17.99 tons. USD200 per 20ft for cargo weight over 18 tons
A89: rate structure :
A90: Rates are incl. PSS/OBS/EFS/MBS subject to ADD/CCC/CSS/THL/THD/Tariff Surcharges both ends/ PCT /HEA /AMS & GAT(for CR destination)/IFD
A92: * Chittagong: Rates are incl. THL/PSS/OBS/EFS/MBS subject to ADD/ CSS/THD/Tariff Surcharges both ends/PCT/HEA/CCC /AMS(for CR destination)/IFD
A93: * Colombo: Rates are incl.THL/CSS/SLF /PSS/OBS/EFS/MBS subject to ADD/THD/destination tariff surcharges/ PCT /HEA/CCC/AMS(for CR destination)/IFD
A94: * Jebel Ali/Jeddah (Gulf area): Rates are incl. PSS/OBS/EFS/MBS subject to ADD/WRC/CSS/THL/THD/Tariff Surcharges both ends/PCT /HEA/CCC /AMS(for CR destination)/IFD
A98: PCT amount will be increased eff from 10 AUG 2026 . USD 100/TEU
A99: =CSE!A90 -> ONE Bunker Surcharge (OBS): usd 320/640/640/640 per D2/D4/D5/R5 NOR during Q3 2026 (Jul-Sep)
A103: ** Subject to NON DG shipment **
A104: ** Subject to space & equipment availability **
A105: ** Subject to Marine Ops Approval **
A106: ** Subject to Dims/ Weight of Cargo as presented **
A107: ** Subject to proper* load/block/brace to OT/FR at origin by shipper **
A108: ** Free time as per standard tariff **
A109: ** Both side end walls of Flat rack container must be in standing position **
...

Sheet DG surcharges
A2: IMO Surcharges
A4: Tariff Surcharge (Surcharge code: HAZ) | B4: IMO Class | C4: D20 | D4: D40 | E4: 40HC | F4: Remarks
B5: CLASS 1 | C5: pls check with us case by case
B6: CLASS 2.1 | C6: USD 450 | D6: USD 800 | E6: USD 800
B7: CLASS 2.2 | C7: USD 300 | D7: USD 600 | E7: USD 600
B8: Other class 2 | C8: USD 700 | D8: USD 1400 | E8: USD 1400
B9: CLASS 3 | C9: USD 200 | D9: USD 400 | E9: USD 400
B10: CLASS 4 | C10: USD 200 | D10: USD 400 | E10: USD 400
B11: Class 5 | C11: USD 200 | D11: USD 400 | E11: USD 400
B12: Class 5 .1 | C12: USD 500 | D12: USD 1000 | E12: USD 1000
B13: CLASS 6.1/6.2 | C13: USD 200 | D13: USD 400 | E13: USD 400
B14: CLASS 7 | C14: pls check with us case by case
B15: CLASS 8 | C15: USD 100 | D15: USD 200 | E15: USD 200
B16: CLASS 9 | C16: USD 100 | D16: USD 200 | E16: USD 200
A17: ** All HAZ shpt is subject to DG desk approval & vessel operator's acceptance.
A21: PSA T/S charge (for any shpt tranship via Singapore) (Surcharge code: PSA) | B21: PSA Class | C21: D20 | D21: D40 | E21: 40HC | F21: Remarks
B22: Dangerous Goods (DG) - Class 1D , 2 & 2B (Non-Storable in PSA) | C22: USD 538 | D22: USD 753 | E22: USD 753 | F22: applicable on top of above tariff HAZ surcharge in case of transshipment via Singapore
B23: Dangerous Goods (DG) - Class 1S, 2S, 2A, 2F (Storable in PSA) | C23: 0 | D23: 0 | E23: 0 | F23: applicable on top of above tariff HAZ surcharge in case of transshipment via Singapore
B24: Dangerous Goods (DG) - Class 3 (Storable in PSA) | C24: 0 | D24: 0 | E24: 0 | F24: no extra t/s charge is needed.

Sheet Yangtze ARB Add-on
C1: Effective Date: | G1: From Jul 1 - Sept 31, 2026
A2: Mode | B2: Province | C2: Origin | D2: Origin Code | E2: Via | F2: Via Code | G2: POR Add-on
G3: 20GP | H3: 40GP | I3: 40HQ
A4: Barge | B4: Zhejiang | C4: Anji | D4: CNANJ | E4: Shanghai | F4: =VLOOKUP(E4,[2]Lookup!F:G,2,0) -> CNSHA | G4: 145 | H4: 270 | I4: 270
A5: Barge | B5: Anhui | C5: Anqing | D5: CNAQG | E5: Shanghai | F5: =VLOOKUP(E5,[2]Lookup!F:G,2,0) -> CNSHA | G5: 175 | H5: 535 | I5: 535
A6: Rail | B6: Anhui | C6: Bengbu | D6: CNBFU | E6: Shanghai | F6: =VLOOKUP(E6,[2]Lookup!F:G,2,0) -> CNSHA | G6: 320 | H6: 345 | I6: 345
A7: Rail | B7: Jilin | C7: Changchun | D7: CNCGQ | E7: Dalian | F7: =VLOOKUP(E7,[2]Lookup!F:G,2,0) -> CNDLC | G7: 395 | H7: 520 | I7: 520
A8: Barge | B8: Hunan | C8: Changsha | D8: CNCSX | E8: Shanghai | F8: =VLOOKUP(E8,[2]Lookup!F:G,2,0) -> CNSHA | G8: 335 | H8: 615 | I8: 615
A9: Barge | B9: Jiangsu | C9: Changshu | D9: CNCGU | E9: Shanghai | F9: =VLOOKUP(E9,[2]Lookup!F:G,2,0) -> CNSHA | G9: 60 | H9: 245 | I9: 245
A10: Barge | B10: Jiangsu | C10: Changzhou | D10: CNCZX | E10: Shanghai | F10: =VLOOKUP(E10,[2]Lookup!F:G,2,0) -> CNSHA | G10: 215 | H10: 375 | I10: 375
A11: Rail | B11: Jiangsu | C11: Changzhou | D11: CNCZX | E11: Shanghai | F11: =VLOOKUP(E11,[2]Lookup!F:G,2,0) -> CNSHA | G11: 195 | H11: 210 | I11: 210
A12: Barge | B12: Zhejiang | C12: Changxing | D12: CNCH1 | E12: Ningbo | F12: =VLOOKUP(E12,[2]Lookup!F:G,2,0) -> CNNGB | G12: 100 | H12: 115 | I12: 115
A13: Rail | B13: Sichuan | C13: Chengdu | D13: CNCTU | E13: Shanghai | F13: =VLOOKUP(E13,[2]Lookup!F:G,2,0) -> CNSHA | G13: 1210 | H13: 1695 | I13: 1695
A14: Rail | B14: Chengdu | C14: Chengdu | D14: CNCTU | E14: Yantian | F14: =VLOOKUP(E14,[2]Lookup!F:G,2,0) -> CNYTN | G14: Nil | H14: 1050 | I14: 1050
A15: Barge | B15: Chongqing | C15: Chongqing | D15: CNCKG | E15: Shanghai | F15: =VLOOKUP(E15,[2]Lookup!F:G,2,0) -> CNSHA | G15: 210 | H15: 975 | I15: 975 | J15: *** The number of D2 containers must be an even number, odd number of D2 containers are prohibited.
A16: Rail | B16: Chongqing | C16: Chongqing | D16: CNCKG | E16: Ningbo | F16: =VLOOKUP(E16,[2]Lookup!F:G,2,0) -> CNNGB | G16: 870 | H16: 1025 | I16: 1025 | J16: *** The number of D2 containers must be an even number, odd number of D2 containers are prohibited.
A17: Rail | B17: Chongqing | C17: Chongqing | D17: CNCKG | E17: Yantian | F17: =VLOOKUP(E17,[2]Lookup!F:G,2,0) -> CNYTN | G17: 865 | H17: 910 | I17: 910 | J17: *** The number of D2 containers must be an even number, odd number of D2 containers are prohibited.
A18: Rail | B18: Chongqing | C18: Chongqing | D18: CNCKG | E18: Qinzhou (Commodity: for Non-DG cargo only. Except DG, Live Reefer, New Energy Vehicle) | F18: =VLOOKUP(LEFT(E18,7),[2]Lookup!F:G,2,0) -> CNQZH | G18: 400 | H18: 495 | I18: 495 | J18: *** The number of D2 containers must be an even number, odd number of D2 containers are prohibited.
A19: Rail | B19: Chongqing | C19: Chongqing | D19: CNCKG | E19: Qinzhou (Commodity: For DG, Live Reefer, New Energy Vehicle) | F19: =VLOOKUP(LEFT(E19,7),[2]Lookup!F:G,2,0) -> CNQZH | G19: check with SLS for details | J19: *** The number of D2 containers must be an even number, odd number of D2 containers are prohibited.
A20: Rail | B20: Anhui | C20: Chuzhou | D20: CNCZH | E20: Shanghai | F20: =VLOOKUP(E20,[2]Lookup!F:G,2,0) -> CNSHA | G20: 320 | H20: 320 | I20: 320
A21: Barge | B21: Jiangsu | C21: Dafeng | D21: CNDFG | E21: Shanghai | F21: =VLOOKUP(E21,[2]Lookup!F:G,2,0) -> CNSHA | G21: 260 | H21: 420 | I21: 420
A22: Rail | B22: Jiangsu | C22: Hai'An | D22: CNHAI | E22: Shanghai | F22: =VLOOKUP(E22,[2]Lookup!F:G,2,0) -> CNSHA | G22: 225 | H22: 255 | I22: 260
A23: Barge | B23: Anhui | C23: Hefei | D23: CNHFE | E23: Shanghai | F23: =VLOOKUP(E23,[2]Lookup!F:G,2,0) -> CNSHA | G23: 105 | H23: 500 | I23: 460
A24: Rail | B24: Anhui | C24: Hefei | D24: CNHFE | E24: Shanghai | F24: =VLOOKUP(E24,[2]Lookup!F:G,2,0) -> CNSHA | G24: 335 | H24: 345 | I24: 345
A25: Barge | B25: Jiangsu | C25: Huaian | D25: CNHUN | E25: Shanghai | F25: =VLOOKUP(E25,[2]Lookup!F:G,2,0) -> CNSHA | G25: 235 | H25: 365 | I25: 365
A26: Rail | B26: Jiangsu | C26: Huaian | D26: CNHUN | E26: Shanghai | F26: =VLOOKUP(E26,[2]Lookup!F:G,2,0) -> CNSHA | G26: 375 | H26: 360 | I26: 360
A27: Rail | B27: Anhui | C27: Huainan | D27: CNHIA | E27: Shanghai | F27: =VLOOKUP(E27,[2]Lookup!F:G,2,0) -> CNSHA | G27: 290 | H27: 315 | I27: 315
A28: Barge | B28: Hubei | C28: Huangshi | D28: CNHSI | E28: Shanghai | F28: =VLOOKUP(E28,[2]Lookup!F:G,2,0) -> CNSHA | G28: 185 | H28: 385 | I28: 385
A29: Barge | B29: Jiangsu | C29: Jiangyin | D29: CNJIA | E29: Shanghai | F29: =VLOOKUP(E29,[2]Lookup!F:G,2,0) -> CNSHA | G29: 130 | H29: 255 | I29: 255
A30: Barge | B30: Jiangsu | C30: Jiangyin | D30: CNJIA | E30: Ningbo | F30: =VLOOKUP(E30,[2]Lookup!F:G,2,0) -> CNNGB | G30: 160 | H30: 135 | I30: 135
A31: Barge | B31: Hubei | C31: Jingzhou | D31: CNJGZ | E31: Shanghai | F31: =VLOOKUP(E31,[2]Lookup!F:G,2,0) -> CNSHA | G31: 250 | H31: 675 | I31: 675
... A41: Rail | B41: Jiangxi | C41: Nanchang | D41: CNKHN | E41: Ningbo | F41: =VLOOKUP(E41,[2]Lookup!F:G,2,0) -> CNNGB | G41: 595 | H41: 810 | I41: 810
A42: Rail | B42: Hubei | C42: Nanchang | D42: CNKHN | E42: Yantian | F42: =VLOOKUP(E42,[2]Lookup!F:G,2,0) -> CNYTN | G42: 650 | H42: 830 | I42: 830 | J42: Not Applicable for New Energy Vehicle
A43: Rail | B43: Hubei | C43: Nanchang | D43: CNKHN | E43: Shekou | F43: =VLOOKUP(E43,[2]Lookup!F:G,2,0) -> CNSHK | G43: 650 | H43: 830 | I43: 830 | J43: Not Applicable for New Energy Vehicle
A44: Rail | B44: Hubei | C44: Nanchang | D44: CNKHN | E44: Nansha | F44: =VLOOKUP(E44,[2]Lookup!F:G,2,0) -> CNNSA | G44: 625 | H44: 840 | I44: 840 | J44: Not Applicable for New Energy Vehicle
A45: Rail | B45: Hubei | C45: Nanchang | D45: CNKHN | E45: Xiamen | F45: =VLOOKUP(E45,[2]Lookup!F:G,2,0) -> CNXMN | G45: 485 | H45: 645 | I45: 645 | J45: Not Applicable for New Energy Vehicle
A46: Barge | B46: Jiangsu | C46: Nanjing | D46: CNNKG | E46: Shanghai | F46: =VLOOKUP(E46,[2]Lookup!F:G,2,0) -> CNSHA | G46: 220 | H46: 400 | I46: 400
A47: Barge | B47: Jiangsu | C47: Nanjing | D47: CNNKG | E47: Ningbo | F47: =VLOOKUP(E47,[2]Lookup!F:G,2,0) -> CNNGB | G47: 250 | H47: 280 | I47: 280
A48: Barge | B48: Jiangsu | C48: Nantong | D48: CNNTG | E48: Shanghai | F48: =VLOOKUP(E48,[2]Lookup!F:G,2,0) -> CNSHA | G48: 155 | H48: 380 | I48: 380
A49: Barge | B49: Jiangsu | C49: Nantong | D49: CNNTG | E49: Ningbo | F49: =VLOOKUP(E49,[2]Lookup!F:G,2,0) -> CNNGB | G49: 185 | H49: 260 | I49: 260
...

Sheet Free Time 
B5: Free days for FAK DRY cargo( applicable for FAK Dry / DG cargo )
B6: POD | C6: Free line detention combine (port storage and demurrage under cnee own negotiation with terminal) | D6: Expire
B7: Manzanillo, PA | C7: 18 days Dry / 12 days DG | D7: 1 July 2026 to 30 Sept 2026
B8: Colon Free Zone | C8: 18 days Dry / 12 days DG | D8: 1 July 2026 to 30 Sept 2026
B9: Barranquilla | C9: 12 days Dry / 12 days DG | D9: 1 July 2026 to 30 Sept 2026
B10: Cartagena | C10: 12 days Dry / 12 days DG | D10: 1 July 2026 to 30 Sept 2026
B11: Caucedo | C11: 12 days Dry / 12 days DG | D11: 1 July 2026 to 30 Sept 2026
B12: Moin | C12: 12 days Dry / 12 days DG | D12: 1 July 2026 to 30 Sept 2026
B13: Puerto Cortes | C13: 15 days Dry / 15 days DG | D13: 1 July 2026 to 30 Sept 2026
B14: Puerto Barrios | C14: 15 days Dry / 15 days DG | D14: 1 July 2026 to 30 Sept 2026
B15: Kingston | C15: 12 days Dry / 12 days DG | D15: 1 July 2026 to 30 Sept 2026
B16: Port of Spain | C16: 12 days Dry / 12 days DG | D16: 1 July 2026 to 30 Sept 2026
B17: Manaus | C17: 18 days Dry / 12 days DG | D17: 1 July 2026 to 30 Sept 2026
... B21: Georgetown | C21: 15 days Dry Only | D21: 1 July 2026 to 30 Sept 2026
B23: Free days for FAK DRY cargo( applicable for NOR cargo )
B24: POD | C24: Free line detention combine (port storage and demurrage under cnee own negotiation with terminal) | D24: Expire
B25: Manzanillo, PA | C25: 12 | D25: 1 July 2026 to 30 Sept 2026
B26: Colon Free Zone | C26: 12 | D26: 1 July 2026 to 30 Sept 2026
B27: Manaus | C27: 12 | D27: 1 July 2026 to 30 Sept 2026
B28: Vila do Conde | C28: 12 | D28: 1 July 2026 to 30 Sept 2026
