Workbook
Name FAK: #REF!
Name POD: #REF!
Name POD: DRY!$C$9:$AC$9
Name PODNOR: #REF!
Name PODNOR: 'R5 NOR'!#REF!
Name POL: #REF!
Name POL: DRY!$B$11:$B$82
Name POLNOR: #REF!
Name POLNOR: 'R5 NOR'!#REF!
Name Rates: #REF!
Name Rates: DRY!$C$11:$AC$82
Name RatesNOR: #REF!
Name RatesNOR: 'R5 NOR'!#REF!

Sheet DRY
A1: ONE ASIA-LAEC RATE GUIDELINE
C2: POL: Non-ISC | F2: POL: ISC
C3: From | D3: To | F3: From | G3: To
A4: Validity period | C4: 2026-08-01 | D4: 2026-08-07 | F4: =C4 -> 2026-08-01 | G4: =D4 -> 2026-08-07
A6: POL: Non-ISC | C6: PLACE OF DELIVERY (DEL)
C7: SERVICE SCOPE = LEW
C8: Santos | F8: Buenos Aires | I8: Montevideo | L8: Navegantes | O8: Paranagua | R8: Rio Grande | U8: Rio de Janeiro | X8: Itapoa | AA8: Asuncion | AD8: Suape | AG8: Salvador | AJ8: Pecem
C9: BRSSZ | F9: ARBUE | I9: UYMVD | L9: BRNVT | O9: BRPNG | R9: BRRIG | U9: BRRIO | X9: BRIOA | AA9: PYASU | AD9: BRSUA | AG9: BRSSA | AJ9: BRPEC
A10: PLACE OF ORIGIN (POR) | B10: POR CODE | C10: D2 | D10: D4 | E10: D5 | F10: D2 | G10: D4 | H10: D5 | I10: D2 | J10: D4 | K10: D5 | L10: D2 | M10: D4 | N10: D5 | O10: D2 | P10: D4 | Q10: D5 | R10: D2 | S10: D4 | T10: D5 | U10: D2 | V10: D4 | W10: D5 | X10: D2 | Y10: D4 | Z10: D5 | AA10: D2 | AB10: D4 | AC10: D5 | AD10: D2 | AE10: D4 | AF10: D5 | AG10: D2 | AH10: D4 | AI10: D5 | AJ10: D2 | AK10: D4 | AL10: D5
A11: FAR EAST BASE PORT | B11: FEBP | C11: 5700 | D11: 6000 | E11: 6000 | F11: 5700 | G11: 6000 | H11: 6000 | I11: 5800 | J11: 6000 | K11: 6000 | L11: 5800 | M11: 6000 | N11: 6000 | O11: 5800 | P11: 6000 | Q11: 6000 | R11: 5800 | S11: 6000 | T11: 6000 | U11: 5700 | V11: 6000 | W11: 6000 | X11: 5700 | Y11: 6000 | Z11: 6000 | AA11: 6800 | AB11: 7300 | AC11: 7300 | AD11: 6600 | AE11: 6800 | AF11: 6800 | AG11: 6600 | AH11: 6800 | AI11: 6800 | AJ11: 6600 | AK11: 6800 | AL11: 6800
A12: Pusan | B12: KRPUS | C12: 5700 | D12: 6000 | E12: 6000 | F12: 5700 | G12: 6000 | H12: 6000 | I12: 5800 | J12: 6000 | K12: 6000 | L12: 5800 | M12: 6000 | N12: 6000 | O12: 5800 | P12: 6000 | Q12: 6000 | R12: 5800 | S12: 6000 | T12: 6000 | U12: 5700 | V12: 6000 | W12: 6000 | X12: 5700 | Y12: 6000 | Z12: 6000 | AA12: 6800 | AB12: 7300 | AC12: 7300 | AD12: 6600 | AE12: 6800 | AF12: 6800 | AG12: 6600 | AH12: 6800 | AI12: 6800 | AJ12: 6600 | AK12: 6800 | AL12: 6800
A13: Taichung | B13: TWTXG | C13: 5750 | D13: 6100 | E13: 6100 | F13: 5750 | G13: 6100 | H13: 6100 | I13: 5850 | J13: 6100 | K13: 6100 | L13: 5850 | M13: 6100 | N13: 6100 | O13: 5850 | P13: 6100 | Q13: 6100 | R13: 5850 | S13: 6100 | T13: 6100 | U13: 5750 | V13: 6100 | W13: 6100 | X13: 5750 | Y13: 6100 | Z13: 6100 | AA13: 6850 | AB13: 7400 | AC13: 7400 | AD13: 6650 | AE13: 6900 | AF13: 6900 | AG13: 6650 | AH13: 6900 | AI13: 6900 | AJ13: 6650 | AK13: 6900 | AL13: 6900
A14: Dalian | B14: CNDLC | C14: 5750 | D14: 6000 | E14: 6000 | F14: 5750 | G14: 6000 | H14: 6000 | I14: 5850 | J14: 6000 | K14: 6000 | L14: 5850 | M14: 6000 | N14: 6000 | O14: 5850 | P14: 6000 | Q14: 6000 | R14: 5850 | S14: 6000 | T14: 6000 | U14: 5750 | V14: 6000 | W14: 6000 | X14: 5750 | Y14: 6000 | Z14: 6000 | AA14: 6850 | AB14: 7300 | AC14: 7300 | AD14: 6650 | AE14: 6800 | AF14: 6800 | AG14: 6650 | AH14: 6800 | AI14: 6800 | AJ14: 6650 | AK14: 6800 | AL14: 6800
A15: Xingang | B15: CNTXG | C15: 5750 | D15: 6000 | E15: 6000 | F15: 5750 | G15: 6000 | H15: 6000 | I15: 5850 | J15: 6000 | K15: 6000 | L15: 5850 | M15: 6000 | N15: 6000 | O15: 5850 | P15: 6000 | Q15: 6000 | R15: 5850 | S15: 6000 | T15: 6000 | U15: 5750 | V15: 6000 | W15: 6000 | X15: 5750 | Y15: 6000 | Z15: 6000 | AA15: 6850 | AB15: 7300 | AC15: 7300 | AD15: 6650 | AE15: 6800 | AF15: 6800 | AG15: 6650 | AH15: 6800 | AI15: 6800 | AJ15: 6650 | AK15: 6800 | AL15: 6800
A16: Fuzhou | B16: CNFOC | C16: 5800 | D16: 6200 | E16: 6200 | F16: 5800 | G16: 6200 | H16: 6200 | I16: 5900 | J16: 6200 | K16: 6200 | L16: 5900 | M16: 6200 | N16: 6200 | O16: 5900 | P16: 6200 | Q16: 6200 | R16: 5900 | S16: 6200 | T16: 6200 | U16: 5800 | V16: 6200 | W16: 6200 | X16: 5800 | Y16: 6200 | Z16: 6200 | AA16: 6900 | AB16: 7500 | AC16: 7500 | AD16: 6700 | AE16: 7000 | AF16: 7000 | AG16: 6700 | AH16: 7000 | AI16: 7000 | AJ16: 6700 | AK16: 7000 | AL16: 7000
A17: Fuqing | B17: CNFUG | C17: 5800 | D17: 6200 | E17: 6200 | F17: 5800 | G17: 6200 | H17: 6200 | I17: 5900 | J17: 6200 | K17: 6200 | L17: 5900 | M17: 6200 | N17: 6200 | O17: 5900 | P17: 6200 | Q17: 6200 | R17: 5900 | S17: 6200 | T17: 6200 | U17: 5800 | V17: 6200 | W17: 6200 | X17: 5800 | Y17: 6200 | Z17: 6200 | AA17: 6900 | AB17: 7500 | AC17: 7500 | AD17: 6700 | AE17: 7000 | AF17: 7000 | AG17: 6700 | AH17: 7000 | AI17: 7000 | AJ17: 6700 | AK17: 7000 | AL17: 7000
A18: Huangpu | B18: CNHUA | C18: 5750 | D18: 6100 | E18: 6100 | F18: 5750 | G18: 6100 | H18: 6100 | I18: 5850 | J18: 6100 | K18: 6100 | L18: 5850 | M18: 6100 | N18: 6100 | O18: 5850 | P18: 6100 | Q18: 6100 | R18: 5850 | S18: 6100 | T18: 6100 | U18: 5750 | V18: 6100 | W18: 6100 | X18: 5750 | Y18: 6100 | Z18: 6100 | AA18: 6850 | AB18: 7400 | AC18: 7400 | AD18: 6650 | AE18: 6900 | AF18: 6900 | AG18: 6650 | AH18: 6900 | AI18: 6900 | AJ18: 6650 | AK18: 6900 | AL18: 6900
A19: PEARL RIVER DELTA | B19: WPRD | C19: 5775 | D19: 6150 | E19: 6150 | F19: 5775 | G19: 6150 | H19: 6150 | I19: 5875 | J19: 6150 | K19: 6150 | L19: 5875 | M19: 6150 | N19: 6150 | O19: 5875 | P19: 6150 | Q19: 6150 | R19: 5875 | S19: 6150 | T19: 6150 | U19: 5775 | V19: 6150 | W19: 6150 | X19: 5775 | Y19: 6150 | Z19: 6150 | AA19: 6875 | AB19: 7450 | AC19: 7450 | AD19: 6675 | AE19: 6950 | AF19: 6950 | AG19: 6675 | AH19: 6950 | AI19: 6950 | AJ19: 6675 | AK19: 6950 | AL19: 6950
A20: Qinzhou | B20: CNQZH | C20: 5800 | D20: 6250 | E20: 6250 | F20: 5800 | G20: 6250 | H20: 6250 | I20: 5900 | J20: 6250 | K20: 6250 | L20: 5900 | M20: 6250 | N20: 6250 | O20: 5900 | P20: 6250 | Q20: 6250 | R20: 5900 | S20: 6250 | T20: 6250 | U20: 5800 | V20: 6250 | W20: 6250 | X20: 5800 | Y20: 6250 | Z20: 6250 | AA20: 6900 | AB20: 7550 | AC20: 7550 | AD20: 6700 | AE20: 7050 | AF20: 7050 | AG20: 6700 | AH20: 7050 | AI20: 7050 | AJ20: 6700 | AK20: 7050 | AL20: 7050
A21: Fangcheng | B21: CNFAN | C21: 5800 | D21: 6250 | E21: 6250 | F21: 5800 | G21: 6250 | H21: 6250 | I21: 5900 | J21: 6250 | K21: 6250 | L21: 5900 | M21: 6250 | N21: 6250 | O21: 5900 | P21: 6250 | Q21: 6250 | R21: 5900 | S21: 6250 | T21: 6250 | U21: 5800 | V21: 6250 | W21: 6250 | X21: 5800 | Y21: 6250 | Z21: 6250 | AA21: 6900 | AB21: 7550 | AC21: 7550 | AD21: 6700 | AE21: 7050 | AF21: 7050 | AG21: 6700 | AH21: 7050 | AI21: 7050 | AJ21: 6700 | AK21: 7050 | AL21: 7050
A22: Ho Chi Minh | B22: VNSGN | C22: 5750 | D22: 6100 | E22: 6100 | F22: 5750 | G22: 6100 | H22: 6100 | I22: 5850 | J22: 6100 | K22: 6100 | L22: 5850 | M22: 6100 | N22: 6100 | O22: 5850 | P22: 6100 | Q22: 6100 | R22: 5850 | S22: 6100 | T22: 6100 | U22: 5750 | V22: 6100 | W22: 6100 | X22: 5750 | Y22: 6100 | Z22: 6100 | AA22: 6850 | AB22: 7400 | AC22: 7400 | AD22: 6650 | AE22: 6900 | AF22: 6900 | AG22: 6650 | AH22: 6900 | AI22: 6900 | AJ22: 6650 | AK22: 6900 | AL22: 6900
... A66: Jordan | B66: JOAQJ | C66: 6200 | D66: 6500 | E66: 6500 | F66: 6200 | G66: 6500 | H66: 6500 | I66: 6300 | J66: 6500 | K66: 6500 | L66: 6300 | M66: 6500 | N66: 6500 | O66: 6300 | P66: 6500 | Q66: 6500 | R66: 6300 | S66: 6500 | T66: 6500 | U66: 6200 | V66: 6500 | W66: 6500 | X66: 6200 | Y66: 6500 | Z66: 6500 | AA66: 7300 | AB66: 7800 | AC66: 7800 | AD66: 7100 | AE66: 7300 | AF66: 7300 | AG66: 7100 | AH66: 7300 | AI66: 7300 | AJ66: 7100 | AK66: 7300 | AL66: 7300
A69: POL: ISC | C69: PLACE OF DELIVERY (DEL)
C70: SERVICE SCOPE = LEW
C71: Santos | F71: Buenos Aires | I71: Montevideo | L71: Navegantes | O71: Paranagua | R71: Rio Grande | U71: Rio de Janeiro | X71: Itapoa | AA71: Asuncion | AD71: Suape | AG71: Salvador | AJ71: Pecem
C72: BRSSZ | F72: ARBUE | I72: UYMVD | L72: BRNVT | O72: BRPNG | R72: BRRIG | U72: BRRIO | X72: BRIOA | AA72: PYASU | AD72: BRSUA | AG72: BRSSA | AJ72: BRPEC
A73: PLACE OF ORIGIN (POR) | B73: POR CODE | C73: D2 | D73: D4 | E73: D5 | F73: D2 | G73: D4 | H73: D5 | I73: D2 | J73: D4 | K73: D5 | L73: D2 | M73: D4 | N73: D5 | O73: D2 | P73: D4 | Q73: D5 | R73: D2 | S73: D4 | T73: D5 | U73: D2 | V73: D4 | W73: D5 | X73: D2 | Y73: D4 | Z73: D5 | AA73: D2 | AB73: D4 | AC73: D5 | AD73: D2 | AE73: D4 | AF73: D5 | AG73: D2 | AH73: D4 | AI73: D5 | AJ73: D2 | AK73: D4 | AL73: D5
A74: Nhava Sheva | B74: INNSA | C74: 6900 | D74: 7200 | E74: 7200 | F74: 6900 | G74: 7200 | H74: 7200 | I74: 7000 | J74: 7200 | K74: 7200 | L74: 7000 | M74: 7200 | N74: 7200 | O74: 7000 | P74: 7200 | Q74: 7200 | R74: 7000 | S74: 7200 | T74: 7200 | U74: 6900 | V74: 7200 | W74: 7200 | X74: 6900 | Y74: 7200 | Z74: 7200 | AA74: 8000 | AB74: 8500 | AC74: 8500 | AD74: 7700 | AE74: 8000 | AF74: 8000 | AG74: 7700 | AH74: 8000 | AI74: 8000 | AJ74: 7700 | AK74: 8000 | AL74: 8000
A75: Pipavav | B75: INPAV | C75: 6900 | D75: 7200 | E75: 7200 | F75: 6900 | G75: 7200 | H75: 7200 | I75: 7000 | J75: 7200 | K75: 7200 | L75: 7000 | M75: 7200 | N75: 7200 | O75: 7000 | P75: 7200 | Q75: 7200 | R75: 7000 | S75: 7200 | T75: 7200 | U75: 6900 | V75: 7200 | W75: 7200 | X75: 6900 | Y75: 7200 | Z75: 7200 | AA75: 8000 | AB75: 8500 | AC75: 8500 | AD75: 7700 | AE75: 8000 | AF75: 8000 | AG75: 7700 | AH75: 8000 | AI75: 8000 | AJ75: 7700 | AK75: 8000 | AL75: 8000
A76: Mundra | B76: INMUN | C76: 6900 | D76: 7200 | E76: 7200 | F76: 6900 | G76: 7200 | H76: 7200 | I76: 7000 | J76: 7200 | K76: 7200 | L76: 7000 | M76: 7200 | N76: 7200 | O76: 7000 | P76: 7200 | Q76: 7200 | R76: 7000 | S76: 7200 | T76: 7200 | U76: 6900 | V76: 7200 | W76: 7200 | X76: 6900 | Y76: 7200 | Z76: 7200 | AA76: 8000 | AB76: 8500 | AC76: 8500 | AD76: 7700 | AE76: 8000 | AF76: 8000 | AG76: 7700 | AH76: 8000 | AI76: 8000 | AJ76: 7700 | AK76: 8000 | AL76: 8000
A77: Chennai | B77: INMAA | C77: 6900 | D77: 7200 | E77: 7200 | F77: 6900 | G77: 7200 | H77: 7200 | I77: 7000 | J77: 7200 | K77: 7200 | L77: 7000 | M77: 7200 | N77: 7200 | O77: 7000 | P77: 7200 | Q77: 7200 | R77: 7000 | S77: 7200 | T77: 7200 | U77: 6900 | V77: 7200 | W77: 7200 | X77: 6900 | Y77: 7200 | Z77: 7200 | AA77: 8000 | AB77: 8500 | AC77: 8500 | AD77: 7700 | AE77: 8000 | AF77: 8000 | AG77: 7700 | AH77: 8000 | AI77: 8000 | AJ77: 7700 | AK77: 8000 | AL77: 8000
A78: Kattupalli | B78: INKTP | C78: 6900 | D78: 7200 | E78: 7200 | F78: 6900 | G78: 7200 | H78: 7200 | I78: 7000 | J78: 7200 | K78: 7200 | L78: 7000 | M78: 7200 | N78: 7200 | O78: 7000 | P78: 7200 | Q78: 7200 | R78: 7000 | S78: 7200 | T78: 7200 | U78: 6900 | V78: 7200 | W78: 7200 | X78: 6900 | Y78: 7200 | Z78: 7200 | AA78: 8000 | AB78: 8500 | AC78: 8500 | AD78: 7700 | AE78: 8000 | AF78: 8000 | AG78: 7700 | AH78: 8000 | AI78: 8000 | AJ78: 7700 | AK78: 8000 | AL78: 8000
A79: Visakhapatnam | B79: INVTZ | C79: 6900 | D79: 7200 | E79: 7200 | F79: 6900 | G79: 7200 | H79: 7200 | I79: 7000 | J79: 7200 | K79: 7200 | L79: 7000 | M79: 7200 | N79: 7200 | O79: 7000 | P79: 7200 | Q79: 7200 | R79: 7000 | S79: 7200 | T79: 7200 | U79: 6900 | V79: 7200 | W79: 7200 | X79: 6900 | Y79: 7200 | Z79: 7200 | AA79: 8000 | AB79: 8500 | AC79: 8500 | AD79: 7700 | AE79: 8000 | AF79: 8000 | AG79: 7700 | AH79: 8000 | AI79: 8000 | AJ79: 7700 | AK79: 8000 | AL79: 8000
A80: Calcutta | B80: INCCU | C80: 7000 | D80: 7300 | E80: 7300 | F80: 7000 | G80: 7300 | H80: 7300 | I80: 7100 | J80: 7300 | K80: 7300 | L80: 7100 | M80: 7300 | N80: 7300 | O80: 7100 | P80: 7300 | Q80: 7300 | R80: 7100 | S80: 7300 | T80: 7300 | U80: 7000 | V80: 7300 | W80: 7300 | X80: 7000 | Y80: 7300 | Z80: 7300 | AA80: 8100 | AB80: 8600 | AC80: 8600 | AD80: 7800 | AE80: 8100 | AF80: 8100 | AG80: 7800 | AH80: 8100 | AI80: 8100 | AJ80: 7800 | AK80: 8100 | AL80: 8100
A81: Haldia | B81: INHAL | C81: 7000 | D81: 7300 | E81: 7300 | F81: 7000 | G81: 7300 | H81: 7300 | I81: 7100 | J81: 7300 | K81: 7300 | L81: 7100 | M81: 7300 | N81: 7300 | O81: 7100 | P81: 7300 | Q81: 7300 | R81: 7100 | S81: 7300 | T81: 7300 | U81: 7000 | V81: 7300 | W81: 7300 | X81: 7000 | Y81: 7300 | Z81: 7300 | AA81: 8100 | AB81: 8600 | AC81: 8600 | AD81: 7800 | AE81: 8100 | AF81: 8100 | AG81: 7800 | AH81: 8100 | AI81: 8100 | AJ81: 7800 | AK81: 8100 | AL81: 8100
A82: Tuticorin | B82: INTUT | C82: 7100 | D82: 7400 | E82: 7400 | F82: 7100 | G82: 7400 | H82: 7400 | I82: 7200 | J82: 7400 | K82: 7400 | L82: 7200 | M82: 7400 | N82: 7400 | O82: 7200 | P82: 7400 | Q82: 7400 | R82: 7200 | S82: 7400 | T82: 7400 | U82: 7100 | V82: 7400 | W82: 7400 | X82: 7100 | Y82: 7400 | Z82: 7400 | AA82: 8200 | AB82: 8700 | AC82: 8700 | AD82: 7900 | AE82: 8200 | AF82: 8200 | AG82: 7900 | AH82: 8200 | AI82: 8200 | AJ82: 7900 | AK82: 8200 | AL82: 8200
A83: Cochin | B83: INCOK | C83: 7300 | D83: 7600 | E83: 7600 | F83: 7300 | G83: 7600 | H83: 7600 | I83: 7400 | J83: 7600 | K83: 7600 | L83: 7400 | M83: 7600 | N83: 7600 | O83: 7400 | P83: 7600 | Q83: 7600 | R83: 7400 | S83: 7600 | T83: 7600 | U83: 7300 | V83: 7600 | W83: 7600 | X83: 7300 | Y83: 7600 | Z83: 7600 | AA83: 8400 | AB83: 8900 | AC83: 8900 | AD83: 8100 | AE83: 8400 | AF83: 8400 | AG83: 8100 | AH83: 8400 | AI83: 8400 | AJ83: 8100 | AK83: 8400 | AL83: 8400
A84: Hazira | B84: INHZA | C84: 7300 | D84: 7600 | E84: 7600 | F84: 7300 | G84: 7600 | H84: 7600 | I84: 7400 | J84: 7600 | K84: 7600 | L84: 7400 | M84: 7600 | N84: 7600 | O84: 7400 | P84: 7600 | Q84: 7600 | R84: 7400 | S84: 7600 | T84: 7600 | U84: 7300 | V84: 7600 | W84: 7600 | X84: 7300 | Y84: 7600 | Z84: 7600 | AA84: 8400 | AB84: 8900 | AC84: 8900 | AD84: 8100 | AE84: 8400 | AF84: 8400 | AG84: 8100 | AH84: 8400 | AI84: 8400 | AJ84: 8100 | AK84: 8400 | AL84: 8400
A85: Karachi | B85: PKKHI | C85: 6900 | D85: 7200 | E85: 7200 | F85: 6900 | G85: 7200 | H85: 7200 | I85: 7000 | J85: 7200 | K85: 7200 | L85: 7000 | M85: 7200 | N85: 7200 | O85: 7000 | P85: 7200 | Q85: 7200 | R85: 7000 | S85: 7200 | T85: 7200 | U85: 6900 | V85: 7200 | W85: 7200 | X85: 6900 | Y85: 7200 | Z85: 7200 | AA85: 8000 | AB85: 8500 | AC85: 8500 | AD85: 7700 | AE85: 8000 | AF85: 8000 | AG85: 7700 | AH85: 8000 | AI85: 8000 | AJ85: 7700 | AK85: 8000 | AL85: 8000
... A87: Chittagong* | B87: BDCGP | C87: 7000 | D87: 7300 | E87: 7300 | F87: 7000 | G87: 7300 | H87: 7300 | I87: 7100 | J87: 7300 | K87: 7300 | L87: 7100 | M87: 7300 | N87: 7300 | O87: 7100 | P87: 7300 | Q87: 7300 | R87: 7100 | S87: 7300 | T87: 7300 | U87: 7000 | V87: 7300 | W87: 7300 | X87: 7000 | Y87: 7300 | Z87: 7300 | AA87: 8100 | AB87: 8600 | AC87: 8600 | AD87: 7800 | AE87: 8100 | AF87: 8100 | AG87: 7800 | AH87: 8100 | AI87: 8100 | AJ87: 7800 | AK87: 8100 | AL87: 8100
...

Sheet R5 NOR
A1: ONE ASIA-LAEC RATE GUIDELINE
C3: From | D3: To
A4: Validity period | C4: =DRY!C4 -> 2026-08-01 | D4: =DRY!D4 -> 2026-08-07
C6: PLACE OF DELIVERY (DEL)
C7: SERVICE SCOPE = LEW
C8: Santos | D8: Buenos Aires | E8: Montevideo | F8: Navegantes | G8: Paranagua | H8: Rio Grande | I8: Rio de Janeiro | J8: Itapoa
C9: BRSSZ | D9: ARBUE | E9: UYMVD | F9: BRNVT | G9: BRPNG | H9: BRRIG | I9: BRRIO | J9: BRIOA
A10: PLACE OF ORIGIN (POR) | B10: POR CODE | C10: R5 NOR | D10: R5 NOR | E10: R5 NOR | F10: R5 NOR | G10: R5 NOR | H10: R5 NOR | I10: R5 NOR | J10: R5 NOR
A11: FAR EAST BASE PORT | B11: FEBP | C11: 4800 | D11: 4800 | E11: 4800 | F11: 4800 | G11: 4800 | H11: 4800 | I11: 4800 | J11: 4800
A12: Pusan | B12: KRPUS | C12: 4800 | D12: 4800 | E12: 4800 | F12: 4800 | G12: 4800 | H12: 4800 | I12: 4800 | J12: 4800
A13: Taichung | B13: TWTXG | C13: 4900 | D13: 4900 | E13: 4900 | F13: 4900 | G13: 4900 | H13: 4900 | I13: 4900 | J13: 4900
A14: Dalian | B14: CNDLC | C14: 4800 | D14: 4800 | E14: 4800 | F14: 4800 | G14: 4800 | H14: 4800 | I14: 4800 | J14: 4800
A15: Xingang | B15: CNTXG | C15: 4800 | D15: 4800 | E15: 4800 | F15: 4800 | G15: 4800 | H15: 4800 | I15: 4800 | J15: 4800
A16: Huangpu | B16: CNHUA | C16: 4900 | D16: 4900 | E16: 4900 | F16: 4900 | G16: 4900 | H16: 4900 | I16: 4900 | J16: 4900
A17: PEARL RIVER DELTA PORTS | B17: WPRD | C17: 4950 | D17: 4950 | E17: 4950 | F17: 4950 | G17: 4950 | H17: 4950 | I17: 4950 | J17: 4950
A18: Ho Chi Minh | B18: VNSGN | C18: 4900 | D18: 4900 | E18: 4900 | F18: 4900 | G18: 4900 | H18: 4900 | I18: 4900 | J18: 4900
A19: BIEN HOA | B19: VNBHA | C19: 4900 | D19: 4900 | E19: 4900 | F19: 4900 | G19: 4900 | H19: 4900 | I19: 4900 | J19: 4900
A20: DI AN | B20: VNDIA | C20: 4900 | D20: 4900 | E20: 4900 | F20: 4900 | G20: 4900 | H20: 4900 | I20: 4900 | J20: 4900
A21: CAI MEP | B21: VNCMP | C21: 4900 | D21: 4900 | E21: 4900 | F21: 4900 | G21: 4900 | H21: 4900 | I21: 4900 | J21: 4900
A22: Haiphong | B22: VNHPH | C22: 4900 | D22: 4900 | E22: 4900 | F22: 4900 | G22: 4900 | H22: 4900 | I22: 4900 | J22: 4900
... A27: Manila | B27: PHMNL | C27: 5000 | D27: 5000 | E27: 5000 | F27: 5000 | G27: 5000 | H27: 5000 | I27: 5000 | J27: 5000
A30: - Above rate offer is applicable for non-DG commodity only.
A31: Rates are incl HEA/PSS/OBS/EFS/MBS, subject to CSS/THL/THD/Tariff Surcharges both ends
A34: =IF(DRY!A96="","",DRY!A96)
A35: =DRY!A97 -> ONE Bunker Surcharge (OBS): fixed as USD 320 per TEU (Dry) & USD 511 per TEU (RF) during Jul-Sep'26
A38: Peak Season Surcharge (PSS): fixed as USD 500 per teu w.e.f. 15th July, 2021 (B/L date basis) until further notice
A40: Subject to equipment availability.
A41: *ECSA = Santos/Buenos Aires/Montevideo/Navegantes/Itapoa/Paranagua/Rio Grande
A42: *FEBP = current base port : Pusan/Qingdao/Shanghai/Ningbo/Xiamen/Yantian/Shekou/Chiwan/Hong Kong/Keelung/Kaohsiung/Taoyuan/Singapore
A43: *WPRD ports = Zhongshan/Zhuhai/Jiangmen/Nansha/Foshan/Sanshan/Rongqi/Beijiao/Xiaolan/Zhanjiang/Shantou/Gaolan/Leliu/Gaoming/Sanshui/Zhoaqing/Jiujiang,Guangdong
A44: Removed Lanshi from PRD group due to Hard constraint on booking acceptance - Lanshi, Foshan
A46: Free line detention combine at POD (port storage and demurrage under cnee own negotiation with terminal) | B46: NOR/ Reefer General cargo
A48: Santos | B48: 14
A49: Buenos Aires | B49: 10
A50: Montevideo | B50: 14
A51: Navegantes | B51: 14
A52: Paranagua | B52: 14
A53: Rio Grande | B53: 14
A54: Asuncion | B54: 14
A55: Suape | B55: 14
...

Sheet Ingauge FAK
A1: ONE ASIA-LAEC RATE GUIDELINE
C2: POL: Non-ISC | F2: POL: ISC
C3: From | D3: To | F3: From | G3: To
A4: Validity period | C4: =DRY!C4 -> 2026-08-01 | D4: =DRY!D4 -> 2026-08-07 | F4: =DRY!F4 -> 2026-08-01 | G4: =DRY!G4 -> 2026-08-07
A7: POL: Non-ISC | C7: PLACE OF DELIVERY (DEL)
C8: SERVICE SCOPE = LEW
C9: ECSA BASE PORTS | E9: Asuncion
C10: BRSSZ/BRNVT/BRPNG/BRRIG /BRRIO/BRIOA/ARBUE/UYMVD | E10: PYASU
A11: PLACE OF ORIGIN (POR) | B11: POR CODE | C11: 20'FR/OT (IG) | D11: 40'FR/OT (IG) | E11: 20'FR/OT (IG) | F11: 40'FR/OT (IG)
A12: Pusan | B12: KRPUS | C12: 6400 | D12: 6800 | E12: 7400 | F12: 8100
A13: Qingdao | B13: CNTAO | C13: 6400 | D13: 6800 | E13: 7400 | F13: 8100
A14: Shanghai | B14: CNSHA | C14: 6400 | D14: 6800 | E14: 7400 | F14: 8100
A15: Ningbo | B15: CNNGB | C15: 6400 | D15: 6800 | E15: 7400 | F15: 8100
A16: Xiamen | B16: CNXMN | C16: 6400 | D16: 6800 | E16: 7400 | F16: 8100
A17: Shekou | B17: CNSHK | C17: 6400 | D17: 6800 | E17: 7400 | F17: 8100
A18: Chiwan | B18: CNCWN | C18: 6400 | D18: 6800 | E18: 7400 | F18: 8100
A19: Hong Kong | B19: HKHKG | C19: 6400 | D19: 6800 | E19: 7400 | F19: 8100
A20: Keelung | B20: TWKEL | C20: 6400 | D20: 6800 | E20: 7400 | F20: 8100
A21: Kaohsiung | B21: TWKHH | C21: 6400 | D21: 6800 | E21: 7400 | F21: 8100
A22: Taoyuan | B22: TWTYN | C22: 6400 | D22: 6800 | E22: 7400 | F22: 8100
A23: Singapore | B23: SGSIN | C23: 6400 | D23: 6800 | E23: 7400 | F23: 8100
... A71: Jeddah* | B71: SAJED | C71: 7100 | D71: 7500 | E71: 8100 | F71: 8800
A74: POL: ISC | C74: PLACE OF DELIVERY (DEL)
C75: SERVICE SCOPE = LEW
C76: ECSA BASE PORTS | E76: Asuncion
C77: BRSSZ/BRNVT/BRPNG/BRRIG /BRRIO/BRIOA/ARBUE/UYMVD | E77: PYASU
A78: PLACE OF ORIGIN (POR) | B78: POR CODE | C78: 20'FR/OT (IG) | D78: 40'FR/OT (IG) | E78: 20'FR/OT (IG) | F78: 40'FR/OT (IG)
A79: Nhava Sheva | B79: INNSA | C79: 7800 | D79: 8200 | E79: 8800 | F79: 9500
A80: Pipavav | B80: INPAV | C80: 7800 | D80: 8200 | E80: 8800 | F80: 9500
A81: Mundra | B81: INMUN | C81: 7800 | D81: 8200 | E81: 8800 | F81: 9500
A82: Chennai | B82: INMAA | C82: 7800 | D82: 8200 | E82: 8800 | F82: 9500
A83: Kattupalli | B83: INKTP | C83: 7800 | D83: 8200 | E83: 8800 | F83: 9500
A84: Visakhapatnam | B84: INVTZ | C84: 7800 | D84: 8200 | E84: 8800 | F84: 9500
A85: Calcutta | B85: INCCU | C85: 7900 | D85: 8300 | E85: 8900 | F85: 9600
A86: Haldia | B86: INHAL | C86: 7900 | D86: 8300 | E86: 8900 | F86: 9600
A87: Tuticorin | B87: INTUT | C87: 8000 | D87: 8400 | E87: 9000 | F87: 9700
A88: Cochin | B88: INCOK | C88: 8200 | D88: 8600 | E88: 9200 | F88: 9900
A89: Karachi | B89: PKKHI | C89: 7800 | D89: 8200 | E89: 8800 | F89: 9500
A90: Colombo* | B90: LKCMB | C90: 7800 | D90: 8200 | E90: 8800 | F90: 9500
A91: Chittagong* | B91: BDCGP | C91: 7900 | D91: 8300 | E91: 8900 | F91: 9600
...

Sheet Yangtze ARB Add-on
C1: Effective Date: | G1: From Jul 1 - Sept 31, 2026
A2: Mode | B2: Province | C2: Origin | D2: Origin Code | E2: Via | F2: Via Code | G2: POR Add-on
G3: 20GP | H3: 40GP | I3: 40HQ
A4: Barge | B4: Zhejiang | C4: Anji | D4: CNANJ | E4: Shanghai | F4: =VLOOKUP(E4,[1]Lookup!F:G,2,0) -> CNSHA | G4: 145 | H4: 270 | I4: 270
A5: Barge | B5: Anhui | C5: Anqing | D5: CNAQG | E5: Shanghai | F5: =VLOOKUP(E5,[1]Lookup!F:G,2,0) -> CNSHA | G5: 175 | H5: 535 | I5: 535
A6: Rail | B6: Anhui | C6: Bengbu | D6: CNBFU | E6: Shanghai | F6: =VLOOKUP(E6,[1]Lookup!F:G,2,0) -> CNSHA | G6: 320 | H6: 345 | I6: 345
A7: Rail | B7: Jilin | C7: Changchun | D7: CNCGQ | E7: Dalian | F7: =VLOOKUP(E7,[1]Lookup!F:G,2,0) -> CNDLC | G7: 395 | H7: 520 | I7: 520
A8: Barge | B8: Hunan | C8: Changsha | D8: CNCSX | E8: Shanghai | F8: =VLOOKUP(E8,[1]Lookup!F:G,2,0) -> CNSHA | G8: 335 | H8: 615 | I8: 615
A9: Barge | B9: Jiangsu | C9: Changshu | D9: CNCGU | E9: Shanghai | F9: =VLOOKUP(E9,[1]Lookup!F:G,2,0) -> CNSHA | G9: 60 | H9: 245 | I9: 245
A10: Barge | B10: Jiangsu | C10: Changzhou | D10: CNCZX | E10: Shanghai | F10: =VLOOKUP(E10,[1]Lookup!F:G,2,0) -> CNSHA | G10: 215 | H10: 375 | I10: 375
A11: Rail | B11: Jiangsu | C11: Changzhou | D11: CNCZX | E11: Shanghai | F11: =VLOOKUP(E11,[1]Lookup!F:G,2,0) -> CNSHA | G11: 195 | H11: 210 | I11: 210
A12: Barge | B12: Zhejiang | C12: Changxing | D12: CNCH1 | E12: Ningbo | F12: =VLOOKUP(E12,[1]Lookup!F:G,2,0) -> CNNGB | G12: 100 | H12: 115 | I12: 115
A13: Rail | B13: Sichuan | C13: Chengdu | D13: CNCTU | E13: Shanghai | F13: =VLOOKUP(E13,[1]Lookup!F:G,2,0) -> CNSHA | G13: 1210 | H13: 1695 | I13: 1695
A14: Rail | B14: Chengdu | C14: Chengdu | D14: CNCTU | E14: Yantian | F14: =VLOOKUP(E14,[1]Lookup!F:G,2,0) -> CNYTN | G14: Nil | H14: 1050 | I14: 1050
A15: Barge | B15: Chongqing | C15: Chongqing | D15: CNCKG | E15: Shanghai | F15: =VLOOKUP(E15,[1]Lookup!F:G,2,0) -> CNSHA | G15: 210 | H15: 975 | I15: 975 | J15: *** The number of D2 containers must be an even number, odd number of D2 containers are prohibited.
A16: Rail | B16: Chongqing | C16: Chongqing | D16: CNCKG | E16: Ningbo | F16: =VLOOKUP(E16,[1]Lookup!F:G,2,0) -> CNNGB | G16: 870 | H16: 1025 | I16: 1025 | J16: *** The number of D2 containers must be an even number, odd number of D2 containers are prohibited.
A17: Rail | B17: Chongqing | C17: Chongqing | D17: CNCKG | E17: Yantian | F17: =VLOOKUP(E17,[1]Lookup!F:G,2,0) -> CNYTN | G17: 865 | H17: 910 | I17: 910 | J17: *** The number of D2 containers must be an even number, odd number of D2 containers are prohibited.
A18: Rail | B18: Chongqing | C18: Chongqing | D18: CNCKG | E18: Qinzhou (Commodity: for Non-DG cargo only. Except DG, Live Reefer, New Energy Vehicle) | F18: =VLOOKUP(LEFT(E18,7),[1]Lookup!F:G,2,0) -> CNQZH | G18: 400 | H18: 495 | I18: 495 | J18: *** The number of D2 containers must be an even number, odd number of D2 containers are prohibited.
A19: Rail | B19: Chongqing | C19: Chongqing | D19: CNCKG | E19: Qinzhou (Commodity: For DG, Live Reefer, New Energy Vehicle) | F19: =VLOOKUP(LEFT(E19,7),[1]Lookup!F:G,2,0) -> CNQZH | G19: check with SLS for details | J19: *** The number of D2 containers must be an even number, odd number of D2 containers are prohibited.
A20: Rail | B20: Anhui | C20: Chuzhou | D20: CNCZH | E20: Shanghai | F20: =VLOOKUP(E20,[1]Lookup!F:G,2,0) -> CNSHA | G20: 320 | H20: 320 | I20: 320
A21: Barge | B21: Jiangsu | C21: Dafeng | D21: CNDFG | E21: Shanghai | F21: =VLOOKUP(E21,[1]Lookup!F:G,2,0) -> CNSHA | G21: 260 | H21: 420 | I21: 420
A22: Rail | B22: Jiangsu | C22: Hai'An | D22: CNHAI | E22: Shanghai | F22: =VLOOKUP(E22,[1]Lookup!F:G,2,0) -> CNSHA | G22: 225 | H22: 255 | I22: 260
A23: Barge | B23: Anhui | C23: Hefei | D23: CNHFE | E23: Shanghai | F23: =VLOOKUP(E23,[1]Lookup!F:G,2,0) -> CNSHA | G23: 105 | H23: 500 | I23: 460
A24: Rail | B24: Anhui | C24: Hefei | D24: CNHFE | E24: Shanghai | F24: =VLOOKUP(E24,[1]Lookup!F:G,2,0) -> CNSHA | G24: 335 | H24: 345 | I24: 345
A25: Barge | B25: Jiangsu | C25: Huaian | D25: CNHUN | E25: Shanghai | F25: =VLOOKUP(E25,[1]Lookup!F:G,2,0) -> CNSHA | G25: 235 | H25: 365 | I25: 365
A26: Rail | B26: Jiangsu | C26: Huaian | D26: CNHUN | E26: Shanghai | F26: =VLOOKUP(E26,[1]Lookup!F:G,2,0) -> CNSHA | G26: 375 | H26: 360 | I26: 360
A27: Rail | B27: Anhui | C27: Huainan | D27: CNHIA | E27: Shanghai | F27: =VLOOKUP(E27,[1]Lookup!F:G,2,0) -> CNSHA | G27: 290 | H27: 315 | I27: 315
A28: Barge | B28: Hubei | C28: Huangshi | D28: CNHSI | E28: Shanghai | F28: =VLOOKUP(E28,[1]Lookup!F:G,2,0) -> CNSHA | G28: 185 | H28: 385 | I28: 385
A29: Barge | B29: Jiangsu | C29: Jiangyin | D29: CNJIA | E29: Shanghai | F29: =VLOOKUP(E29,[1]Lookup!F:G,2,0) -> CNSHA | G29: 130 | H29: 255 | I29: 255
A30: Barge | B30: Jiangsu | C30: Jiangyin | D30: CNJIA | E30: Ningbo | F30: =VLOOKUP(E30,[1]Lookup!F:G,2,0) -> CNNGB | G30: 160 | H30: 135 | I30: 135
A31: Barge | B31: Hubei | C31: Jingzhou | D31: CNJGZ | E31: Shanghai | F31: =VLOOKUP(E31,[1]Lookup!F:G,2,0) -> CNSHA | G31: 250 | H31: 675 | I31: 675
... A41: Rail | B41: Jiangxi | C41: Nanchang | D41: CNKHN | E41: Ningbo | F41: =VLOOKUP(E41,[1]Lookup!F:G,2,0) -> CNNGB | G41: 595 | H41: 810 | I41: 810
A42: Rail | B42: Hubei | C42: Nanchang | D42: CNKHN | E42: Yantian | F42: =VLOOKUP(E42,[1]Lookup!F:G,2,0) -> CNYTN | G42: 650 | H42: 830 | I42: 830 | J42: Not Applicable for New Energy Vehicle
A43: Rail | B43: Hubei | C43: Nanchang | D43: CNKHN | E43: Shekou | F43: =VLOOKUP(E43,[1]Lookup!F:G,2,0) -> CNSHK | G43: 650 | H43: 830 | I43: 830 | J43: Not Applicable for New Energy Vehicle
A44: Rail | B44: Hubei | C44: Nanchang | D44: CNKHN | E44: Nansha | F44: =VLOOKUP(E44,[1]Lookup!F:G,2,0) -> CNNSA | G44: 625 | H44: 840 | I44: 840 | J44: Not Applicable for New Energy Vehicle
A45: Rail | B45: Hubei | C45: Nanchang | D45: CNKHN | E45: Xiamen | F45: =VLOOKUP(E45,[1]Lookup!F:G,2,0) -> CNXMN | G45: 485 | H45: 645 | I45: 645 | J45: Not Applicable for New Energy Vehicle
A46: Barge | B46: Jiangsu | C46: Nanjing | D46: CNNKG | E46: Shanghai | F46: =VLOOKUP(E46,[1]Lookup!F:G,2,0) -> CNSHA | G46: 220 | H46: 400 | I46: 400
A47: Barge | B47: Jiangsu | C47: Nanjing | D47: CNNKG | E47: Ningbo | F47: =VLOOKUP(E47,[1]Lookup!F:G,2,0) -> CNNGB | G47: 250 | H47: 280 | I47: 280
A48: Barge | B48: Jiangsu | C48: Nantong | D48: CNNTG | E48: Shanghai | F48: =VLOOKUP(E48,[1]Lookup!F:G,2,0) -> CNSHA | G48: 155 | H48: 380 | I48: 380
A49: Barge | B49: Jiangsu | C49: Nantong | D49: CNNTG | E49: Ningbo | F49: =VLOOKUP(E49,[1]Lookup!F:G,2,0) -> CNNGB | G49: 185 | H49: 260 | I49: 260
...

Sheet ECSA Add-On
A1: LAEC Outport Add-on (on top of base port rates)
A2: Destination | C2: T/S Port | D2: Add-on
D3: D2 | E3: D4/D5
A4: Fortaleza | B4: BR | C4: - | D4: No service
A5: Vitoria | B5: BR | C5: - | D5: No service
A6: Ushuaia | B6: AR | C6: ARBUE | D6: 2000 | E6: 3500
A7: Rosario | B7: AR | C7: UYMVD | D7: No service
A8: Zarate | B8: AR | C8: BRRIO | D8: 350 | E8: 600
A9: La Plata | B9: AR | C9: BRRIO | D9: 350 | E9: 500
A11: -Applicable for Non-HAZ DRY ctnrs only, for HAZ shpt, pls check with pricers case by case

Sheet IMO charge
A2: IMO Surcharges
A4: Tariff Surcharge (Surcharge code: HAZ) | B4: IMO Class | C4: D20 | D4: D40 | E4: 40HC | F4: Remarks
B5: CLASS 1 | C5: pls check with us case by case
B6: CLASS 2.1 | C6: USD 450 | D6: USD 800 | E6: USD 800
B7: CLASS 2.2 | C7: USD 300 | D7: USD 600 | E7: USD 600
B8: Other class 2 | C8: USD 700 | D8: USD 1400 | E8: USD 1400
B9: CLASS 3 | C9: USD 200 | D9: USD 400 | E9: USD 400
B10: CLASS 4 | C10: USD 200 | D10: USD 400 | E10: USD 400
B11: Class 5 | C11: USD 200 | D11: USD 400 | E11: USD 400
B12: Class 5.1 | C12: USD 500 | D12: USD 1000 | E12: USD 1000
B13: CLASS 6.1/6.2 | C13: USD 200 | D13: USD 400 | E13: USD 400
B14: CLASS 7 | C14: pls check with us case by case
B15: CLASS 8 | C15: USD 100 | D15: USD 200 | E15: USD 200
B16: CLASS 9 | C16: USD 100 | D16: USD 200 | E16: USD 200
A17: ** All HAZ shpt is subject to DG desk approval & vessel operator's acceptance.
A21: PSA T/S charge (for any shpt tranship via Singapore) (Surcharge code: PSA) | B21: PSA Class | C21: D20 | D21: D40 | E21: 40HC | F21: Remarks
B22: Dangerous Goods (DG) - Class 1D , 2 & 2B (Non-Storable in PSA) | C22: USD 538 | D22: USD 753 | E22: USD 753 | F22: applicable on top of above tariff HAZ surcharge in case of transshipment via Singapore
B23: Dangerous Goods (DG) - Class 1S, 2S, 2A, 2F (Storable in PSA) | C23: 0 | D23: 0 | E23: 0 | F23: applicable on top of above tariff HAZ surcharge in case of transshipment via Singapore
B24: Dangerous Goods (DG) - Class 3 (Storable in PSA) | C24: 0 | D24: 0 | E24: 0 | F24: no extra t/s charge is needed.
