Workbook

Sheet China_TWN_SIN_HKG_KR Dry
D1: LAWC FAK Guideline rates
D3: From | E3: To
A4: Validity period | B4: FAK | D4: 46256 | E4: 46265
D6: POD
D7: Manzanillo,MX | G7: Lazaro Cardenas, MX | J7: Callao, PE | M7: Coronel CL | P7: San Vicente CL | S7: Lirquen, CL | V7: San Antonio, CL | Y7: Valparaiso, CL | AB7: Buenaventura, CO | AE7: Guayaquil, EC | AH7: Posorja, EC | AK7: Iquique, CL | AN7: Antofagasta, CL | AQ7: Puerto Angamos, CL | AT7: Ensenada, MX | AW7: Puerto Quetzal, GT | AZ7: Rodman , PA | BC7: Panama City, PA (Door) (via Rodman, PA) | BF7: Arica, CL | BI7: Puerto Caldera, CR | BL7: Acajutla, SV | BO7: Corinto, NI | BR7: San Lorenzo CY/CY , HN (Via SVAQJ using Marex service - Trucking ) | BU7: San Lorenzo CY/CY, HN (Via NICIO using MAR service - Trucking)
D8: MXZLO | G8: MXLZC | J8: PECLL | M8: CLCNL | P8: CLSVE | S8: CLLQN | V8: CLSAI | Y8: CLVAP | AB8: COBUN | AE8: ECGYE | AH8: ECPSJ | AK8: CLIQQ | AN8: CLANF | AQ8: CLPAG | AT8: MXESE | AW8: GTPRQ | AZ8: PAROD | BC8: PAPTY | BF8: CLARI | BI8: CRCAL | BL8: SVAQJ | BO8: NICIO | BR8: HNSLO | BU8: HNSLO
A9: POR | B9: Via | C9: POR CODE | D9: 20' | E9: 40' | F9: HCD | G9: 20' | H9: 40' | I9: HCD | J9: 20' | K9: 40' | L9: HCD | M9: 20' | N9: 40' | O9: HCD | P9: 20' | Q9: 40' | R9: HCD | S9: 20' | T9: 40' | U9: HCD | V9: 20' | W9: 40' | X9: HCD | Y9: 20' | Z9: 40' | AA9: HCD | AB9: 20' | AC9: 40' | AD9: HCD | AE9: 20' | AF9: 40' | AG9: HCD | AK9: 20' | AL9: 40' | AM9: HCD | AN9: 20' | AO9: 40' | AP9: HCD | AQ9: 20' | AR9: 40' | AS9: HCD | AT9: 20' | AU9: 40' | AV9: HCD | AW9: 20' | AX9: 40' | AY9: HCD | AZ9: 20' | BA9: 40' | BB9: HCD | BC9: 20' | BD9: 40' | BE9: HCD | BF9: 20' | BG9: 40' | BH9: HCD | BI9: 20' | BJ9: 40' | BK9: HCD | BL9: 20' | BM9: 40' | BN9: HCD | BO9: 20' | BP9: 40' | BQ9: HCD | BR9: 20' | BS9: 40' | BT9: HCD | BU9: 20' | BV9: 40' | BW9: HCD
A10: Pusan | C10: KRPUS | D10: 7200 | E10: 7500 | F10: 7500 | G10: 7200 | H10: 7500 | I10: 7500 | J10: 7200 | K10: 7500 | L10: 7500 | M10: 7200 | N10: 7500 | O10: 7500 | P10: 7200 | Q10: 7500 | R10: 7500 | S10: 7200 | T10: 7500 | U10: 7500 | V10: 7200 | W10: 7500 | X10: 7500 | Y10: 7200 | Z10: 7500 | AA10: 7500 | AB10: 7200 | AC10: 7500 | AD10: 7500 | AE10: 7200 | AF10: 7500 | AG10: 7500 | AH10: 7000 | AI10: 7300 | AJ10: 7300 | AK10: 7500 | AL10: 7900 | AM10: 7900 | AN10: V | AO10: 1400 | AP10: 1400 | AQ10: 7840 | AR10: 8465 | AS10: 8465 | AT10: 7325 | AU10: 7700 | AV10: 7700 | AW10: 8200 | AX10: 8500 | AY10: 8500 | AZ10: 7800 | BA10: 8325 | BB10: 8325 | BC10: 7950 | BD10: 8375 | BE10: 8375 | BF10: 8025 | BG10: 8700 | BH10: 8700 | BI10: 8400 | BJ10: 8700 | BK10: 8700 | BL10: 8400 | BM10: 8700 | BN10: 8700 | BO10: 8400 | BP10: 8700 | BQ10: 8700 | BU10: =(BO10+2791)-100 -> 11091 | BV10: =(BP10+2791)-100 -> 11391 | BW10: =(BQ10+2791)-100 -> 11391
A11: Hong Kong | C11: HKHKG | D11: 7200 | E11: 7500 | F11: 7500 | G11: 7200 | H11: 7500 | I11: 7500 | J11: 7200 | K11: 7500 | L11: 7500 | M11: 7200 | N11: 7500 | O11: 7500 | P11: 7200 | Q11: 7500 | R11: 7500 | S11: 7200 | T11: 7500 | U11: 7500 | V11: 7200 | W11: 7500 | X11: 7500 | Y11: 7200 | Z11: 7500 | AA11: 7500 | AB11: 7200 | AC11: 7500 | AD11: 7500 | AE11: 7200 | AF11: 7500 | AG11: 7500 | AH11: 7000 | AI11: 7300 | AJ11: 7300 | AK11: 7500 | AL11: 7900 | AM11: 7900 | AN11: V | AO11: 1400 | AP11: 1400 | AQ11: 7840 | AR11: 8465 | AS11: 8465 | AT11: 7325 | AU11: 7700 | AV11: 7700 | AW11: 8200 | AX11: 8500 | AY11: 8500 | AZ11: 7800 | BA11: 8325 | BB11: 8325 | BC11: 7950 | BD11: 8375 | BE11: 8375 | BF11: 8025 | BG11: 8700 | BH11: 8700 | BI11: 8400 | BJ11: 8700 | BK11: 8700 | BL11: 8400 | BM11: 8700 | BN11: 8700 | BO11: 8400 | BP11: 8700 | BQ11: 8700 | BU11: =(BO11+2791)-100 -> 11091 | BV11: =(BP11+2791)-100 -> 11391 | BW11: =(BQ11+2791)-100 -> 11391
A12: Singapore | C12: SGSIN | D12: 7200 | E12: 7500 | F12: 7500 | G12: 7200 | H12: 7500 | I12: 7500 | J12: 7200 | K12: 7500 | L12: 7500 | M12: 7200 | N12: 7500 | O12: 7500 | P12: 7200 | Q12: 7500 | R12: 7500 | S12: 7200 | T12: 7500 | U12: 7500 | V12: 7200 | W12: 7500 | X12: 7500 | Y12: 7200 | Z12: 7500 | AA12: 7500 | AB12: 7200 | AC12: 7500 | AD12: 7500 | AE12: 7200 | AF12: 7500 | AG12: 7500 | AH12: 7000 | AI12: 7300 | AJ12: 7300 | AK12: 7500 | AL12: 7900 | AM12: 7900 | AN12: 1300 | AO12: 1400 | AP12: 1400 | AQ12: 7840 | AR12: 8465 | AS12: 8465 | AT12: 7325 | AU12: 7700 | AV12: 7700 | AW12: 8200 | AX12: 8500 | AY12: 8500 | AZ12: 7800 | BA12: 8325 | BB12: 8325 | BC12: 7950 | BD12: 8375 | BE12: 8375 | BF12: 8025 | BG12: 8700 | BH12: 8700 | BI12: 8400 | BJ12: 8700 | BK12: 8700 | BL12: 8400 | BM12: 8700 | BN12: 8700 | BO12: 8400 | BP12: 8700 | BQ12: 8700 | BU12: =(BO12+2791)-100 -> 11091 | BV12: =(BP12+2791)-100 -> 11391 | BW12: =(BQ12+2791)-100 -> 11391
A13: Shanghai | C13: CNSHA | D13: 7200 | E13: 7500 | F13: 7500 | G13: 7200 | H13: 7500 | I13: 7500 | J13: 7200 | K13: 7500 | L13: 7500 | M13: 7200 | N13: 7500 | O13: 7500 | P13: 7200 | Q13: 7500 | R13: 7500 | S13: 7200 | T13: 7500 | U13: 7500 | V13: 7200 | W13: 7500 | X13: 7500 | Y13: 7200 | Z13: 7500 | AA13: 7500 | AB13: 7200 | AC13: 7500 | AD13: 7500 | AE13: 7200 | AF13: 7500 | AG13: 7500 | AH13: 7000 | AI13: 7300 | AJ13: 7300 | AK13: 7500 | AL13: 7900 | AM13: 7900 | AN13: 1300 | AO13: 1400 | AP13: 1400 | AQ13: 7840 | AR13: 8465 | AS13: 8465 | AT13: 7325 | AU13: 7700 | AV13: 7700 | AW13: 8200 | AX13: 8500 | AY13: 8500 | AZ13: 7800 | BA13: 8325 | BB13: 8325 | BC13: 7950 | BD13: 8375 | BE13: 8375 | BF13: 8025 | BG13: 8700 | BH13: 8700 | BI13: 8400 | BJ13: 8700 | BK13: 8700 | BL13: 8400 | BM13: 8700 | BN13: 8700 | BO13: 8400 | BP13: 8700 | BQ13: 8700 | BU13: =(BO13+2791)-100 -> 11091 | BV13: =(BP13+2791)-100 -> 11391 | BW13: =(BQ13+2791)-100 -> 11391
A14: Ningbo | C14: CNNGB | D14: 7200 | E14: 7500 | F14: 7500 | G14: 7200 | H14: 7500 | I14: 7500 | J14: 7200 | K14: 7500 | L14: 7500 | M14: 7200 | N14: 7500 | O14: 7500 | P14: 7200 | Q14: 7500 | R14: 7500 | S14: 7200 | T14: 7500 | U14: 7500 | V14: 7200 | W14: 7500 | X14: 7500 | Y14: 7200 | Z14: 7500 | AA14: 7500 | AB14: 7200 | AC14: 7500 | AD14: 7500 | AE14: 7200 | AF14: 7500 | AG14: 7500 | AH14: 7000 | AI14: 7300 | AJ14: 7300 | AK14: 7500 | AL14: 7900 | AM14: 7900 | AN14: 1300 | AO14: 1400 | AP14: 1400 | AQ14: 7840 | AR14: 8465 | AS14: 8465 | AT14: 7325 | AU14: 7700 | AV14: 7700 | AW14: 8200 | AX14: 8500 | AY14: 8500 | AZ14: 7800 | BA14: 8325 | BB14: 8325 | BC14: 7950 | BD14: 8375 | BE14: 8375 | BF14: 8025 | BG14: 8700 | BH14: 8700 | BI14: 8400 | BJ14: 8700 | BK14: 8700 | BL14: 8400 | BM14: 8700 | BN14: 8700 | BO14: 8400 | BP14: 8700 | BQ14: 8700 | BU14: =(BO14+2791)-100 -> 11091 | BV14: =(BP14+2791)-100 -> 11391 | BW14: =(BQ14+2791)-100 -> 11391
A15: Yantian | C15: CNYTN | D15: 7200 | E15: 7500 | F15: 7500 | G15: 7200 | H15: 7500 | I15: 7500 | J15: 7200 | K15: 7500 | L15: 7500 | M15: 7200 | N15: 7500 | O15: 7500 | P15: 7200 | Q15: 7500 | R15: 7500 | S15: 7200 | T15: 7500 | U15: 7500 | V15: 7200 | W15: 7500 | X15: 7500 | Y15: 7200 | Z15: 7500 | AA15: 7500 | AB15: 7200 | AC15: 7500 | AD15: 7500 | AE15: 7200 | AF15: 7500 | AG15: 7500 | AH15: 7000 | AI15: 7300 | AJ15: 7300 | AK15: 7500 | AL15: 7900 | AM15: 7900 | AN15: 1300 | AO15: 1400 | AP15: 1400 | AQ15: 7840 | AR15: 8465 | AS15: 8465 | AT15: 7325 | AU15: 7700 | AV15: 7700 | AW15: 8200 | AX15: 8500 | AY15: 8500 | AZ15: 7800 | BA15: 8325 | BB15: 8325 | BC15: 7950 | BD15: 8375 | BE15: 8375 | BF15: 8025 | BG15: 8700 | BH15: 8700 | BI15: 8400 | BJ15: 8700 | BK15: 8700 | BL15: 8400 | BM15: 8700 | BN15: 8700 | BO15: 8400 | BP15: 8700 | BQ15: 8700 | BU15: =(BO15+2791)-100 -> 11091 | BV15: =(BP15+2791)-100 -> 11391 | BW15: =(BQ15+2791)-100 -> 11391
A16: Shekou | C16: CNSHK | D16: 7200 | E16: 7500 | F16: 7500 | G16: 7200 | H16: 7500 | I16: 7500 | J16: 7200 | K16: 7500 | L16: 7500 | M16: 7200 | N16: 7500 | O16: 7500 | P16: 7200 | Q16: 7500 | R16: 7500 | S16: 7200 | T16: 7500 | U16: 7500 | V16: 7200 | W16: 7500 | X16: 7500 | Y16: 7200 | Z16: 7500 | AA16: 7500 | AB16: 7200 | AC16: 7500 | AD16: 7500 | AE16: 7200 | AF16: 7500 | AG16: 7500 | AH16: 7000 | AI16: 7300 | AJ16: 7300 | AK16: 7500 | AL16: 7900 | AM16: 7900 | AN16: 1300 | AO16: 1400 | AP16: 1400 | AQ16: 7840 | AR16: 8465 | AS16: 8465 | AT16: 7325 | AU16: 7700 | AV16: 7700 | AW16: 8200 | AX16: 8500 | AY16: 8500 | AZ16: 7800 | BA16: 8325 | BB16: 8325 | BC16: 7950 | BD16: 8375 | BE16: 8375 | BF16: 8025 | BG16: 8700 | BH16: 8700 | BI16: 8400 | BJ16: 8700 | BK16: 8700 | BL16: 8400 | BM16: 8700 | BN16: 8700 | BO16: 8400 | BP16: 8700 | BQ16: 8700 | BU16: =(BO16+2791)-100 -> 11091 | BV16: =(BP16+2791)-100 -> 11391 | BW16: =(BQ16+2791)-100 -> 11391
A17: Xiamen | C17: CNXMN | D17: 7200 | E17: 7500 | F17: 7500 | G17: 7200 | H17: 7500 | I17: 7500 | J17: 7200 | K17: 7500 | L17: 7500 | M17: 7200 | N17: 7500 | O17: 7500 | P17: 7200 | Q17: 7500 | R17: 7500 | S17: 7200 | T17: 7500 | U17: 7500 | V17: 7200 | W17: 7500 | X17: 7500 | Y17: 7200 | Z17: 7500 | AA17: 7500 | AB17: 7200 | AC17: 7500 | AD17: 7500 | AE17: 7200 | AF17: 7500 | AG17: 7500 | AH17: 7000 | AI17: 7300 | AJ17: 7300 | AK17: 7500 | AL17: 7900 | AM17: 7900 | AN17: 1300 | AO17: 1400 | AP17: 1400 | AQ17: 7840 | AR17: 8465 | AS17: 8465 | AT17: 7325 | AU17: 7700 | AV17: 7700 | AW17: 8200 | AX17: 8500 | AY17: 8500 | AZ17: 7800 | BA17: 8325 | BB17: 8325 | BC17: 7950 | BD17: 8375 | BE17: 8375 | BF17: 8025 | BG17: 8700 | BH17: 8700 | BI17: 8400 | BJ17: 8700 | BK17: 8700 | BL17: 8400 | BM17: 8700 | BN17: 8700 | BO17: 8400 | BP17: 8700 | BQ17: 8700 | BU17: =(BO17+2791)-100 -> 11091 | BV17: =(BP17+2791)-100 -> 11391 | BW17: =(BQ17+2791)-100 -> 11391
A18: Keelung | C18: TWKEL | D18: 7200 | E18: 7500 | F18: 7500 | G18: 7200 | H18: 7500 | I18: 7500 | J18: 7200 | K18: 7500 | L18: 7500 | M18: 7200 | N18: 7500 | O18: 7500 | P18: 7200 | Q18: 7500 | R18: 7500 | S18: 7200 | T18: 7500 | U18: 7500 | V18: 7200 | W18: 7500 | X18: 7500 | Y18: 7200 | Z18: 7500 | AA18: 7500 | AB18: 7200 | AC18: 7500 | AD18: 7500 | AE18: 7200 | AF18: 7500 | AG18: 7500 | AH18: 7000 | AI18: 7300 | AJ18: 7300 | AK18: 7500 | AL18: 7900 | AM18: 7900 | AN18: 1300 | AO18: 1400 | AP18: 1400 | AQ18: 7675 | AR18: 8465 | AS18: 8465 | AT18: 7325 | AU18: 7700 | AV18: 7700 | AW18: 8200 | AX18: 8500 | AY18: 8500 | AZ18: 7800 | BA18: 8325 | BB18: 8325 | BC18: 7950 | BD18: 8375 | BE18: 8375 | BF18: 8025 | BG18: 8700 | BH18: 8700 | BI18: 8400 | BJ18: 8700 | BK18: 8700 | BL18: 8400 | BM18: 8700 | BN18: 8700 | BO18: 8400 | BP18: 8700 | BQ18: 8700 | BU18: =(BO18+2791)-100 -> 11091 | BV18: =(BP18+2791)-100 -> 11391 | BW18: =(BQ18+2791)-100 -> 11391
A19: Kaohsiung | C19: TWKHH | D19: 7200 | E19: 7500 | F19: 7500 | G19: 7200 | H19: 7500 | I19: 7500 | J19: 7200 | K19: 7500 | L19: 7500 | M19: 7200 | N19: 7500 | O19: 7500 | P19: 7200 | Q19: 7500 | R19: 7500 | S19: 7200 | T19: 7500 | U19: 7500 | V19: 7200 | W19: 7500 | X19: 7500 | Y19: 7200 | Z19: 7500 | AA19: 7500 | AB19: 7200 | AC19: 7500 | AD19: 7500 | AE19: 7200 | AF19: 7500 | AG19: 7500 | AH19: 7000 | AI19: 7300 | AJ19: 7300 | AK19: 7500 | AL19: 7900 | AM19: 7900 | AN19: 1300 | AO19: 1400 | AP19: 1400 | AQ19: 7675 | AR19: 8465 | AS19: 8465 | AT19: 7325 | AU19: 7700 | AV19: 7700 | AW19: 8200 | AX19: 8500 | AY19: 8500 | AZ19: 7800 | BA19: 8325 | BB19: 8325 | BC19: 7950 | BD19: 8375 | BE19: 8375 | BF19: 8025 | BG19: 8700 | BH19: 8700 | BI19: 8400 | BJ19: 8700 | BK19: 8700 | BL19: 8400 | BM19: 8700 | BN19: 8700 | BO19: 8400 | BP19: 8700 | BQ19: 8700 | BU19: =(BO19+2791)-100 -> 11091 | BV19: =(BP19+2791)-100 -> 11391 | BW19: =(BQ19+2791)-100 -> 11391
A20: Taichung | C20: TWTXG | D20: 7200 | E20: 7500 | F20: 7500 | G20: 7200 | H20: 7500 | I20: 7500 | J20: 7200 | K20: 7500 | L20: 7500 | M20: 7200 | N20: 7500 | O20: 7500 | P20: 7200 | Q20: 7500 | R20: 7500 | S20: 7200 | T20: 7500 | U20: 7500 | V20: 7200 | W20: 7500 | X20: 7500 | Y20: 7200 | Z20: 7500 | AA20: 7500 | AB20: 7200 | AC20: 7500 | AD20: 7500 | AE20: 7200 | AF20: 7500 | AG20: 7500 | AH20: 7000 | AI20: 7300 | AJ20: 7300 | AK20: 7500 | AL20: 7900 | AM20: 7900 | AN20: 1300 | AO20: 1400 | AP20: 1400 | AQ20: 7675 | AR20: 8465 | AS20: 8465 | AT20: 7325 | AU20: 7700 | AV20: 7700 | AW20: 8200 | AX20: 8500 | AY20: 8500 | AZ20: 7800 | BA20: 8325 | BB20: 8325 | BC20: 7950 | BD20: 8375 | BE20: 8375 | BF20: 8025 | BG20: 8700 | BH20: 8700 | BI20: 8400 | BJ20: 8700 | BK20: 8700 | BL20: 8400 | BM20: 8700 | BN20: 8700 | BO20: 8400 | BP20: 8700 | BQ20: 8700 | BU20: =(BO20+2791)-100 -> 11091 | BV20: =(BP20+2791)-100 -> 11391 | BW20: =(BQ20+2791)-100 -> 11391
A21: Taoyuan | C21: TWTYN | D21: 7200 | E21: 7500 | F21: 7500 | G21: 7200 | H21: 7500 | I21: 7500 | J21: 7200 | K21: 7500 | L21: 7500 | M21: 7200 | N21: 7500 | O21: 7500 | P21: 7200 | Q21: 7500 | R21: 7500 | S21: 7200 | T21: 7500 | U21: 7500 | V21: 7200 | W21: 7500 | X21: 7500 | Y21: 7200 | Z21: 7500 | AA21: 7500 | AB21: 7200 | AC21: 7500 | AD21: 7500 | AE21: 7200 | AF21: 7500 | AG21: 7500 | AH21: 7000 | AI21: 7300 | AJ21: 7300 | AK21: 7500 | AL21: 7900 | AM21: 7900 | AN21: 1300 | AO21: 1400 | AP21: 1400 | AQ21: 7675 | AR21: 8465 | AS21: 8465 | AT21: 7325 | AU21: 7700 | AV21: 7700 | AW21: 8200 | AX21: 8500 | AY21: 8500 | AZ21: 7800 | BA21: 8325 | BB21: 8325 | BC21: 7950 | BD21: 8375 | BE21: 8375 | BF21: 8025 | BG21: 8700 | BH21: 8700 | BI21: 8400 | BJ21: 8700 | BK21: 8700 | BL21: 8400 | BM21: 8700 | BN21: 8700 | BO21: 8400 | BP21: 8700 | BQ21: 8700 | BU21: =(BO21+2791)-100 -> 11091 | BV21: =(BP21+2791)-100 -> 11391 | BW21: =(BQ21+2791)-100 -> 11391
A22: Dalian | C22: CNDLC | D22: 7200 | E22: 7500 | F22: 7500 | G22: 7200 | H22: 7500 | I22: 7500 | J22: 7200 | K22: 7500 | L22: 7500 | M22: 7200 | N22: 7500 | O22: 7500 | P22: 7200 | Q22: 7500 | R22: 7500 | S22: 7200 | T22: 7500 | U22: 7500 | V22: 7200 | W22: 7500 | X22: 7500 | Y22: 7200 | Z22: 7500 | AA22: 7500 | AB22: 7200 | AC22: 7500 | AD22: 7500 | AE22: 7200 | AF22: 7500 | AG22: 7500 | AH22: 7000 | AI22: 7300 | AJ22: 7300 | AK22: 7500 | AL22: 7900 | AM22: 7900 | AN22: 1300 | AO22: 1400 | AP22: 1400 | AQ22: 7840 | AR22: 8465 | AS22: 8465 | AT22: 7325 | AU22: 7700 | AV22: 7700 | AW22: 8200 | AX22: 8500 | AY22: 8500 | AZ22: 7800 | BA22: 8325 | BB22: 8325 | BC22: 7950 | BD22: 8375 | BE22: 8375 | BF22: 8025 | BG22: 8700 | BH22: 8700 | BI22: 8400 | BJ22: 8700 | BK22: 8700 | BL22: 8400 | BM22: 8700 | BN22: 8700 | BO22: 8400 | BP22: 8700 | BQ22: 8700 | BU22: =(BO22+2791)-100 -> 11091 | BV22: =(BP22+2791)-100 -> 11391 | BW22: =(BQ22+2791)-100 -> 11391
A23: Xingang | C23: CNTXG | D23: 7270 | E23: 7600 | F23: 7600 | G23: 7270 | H23: 7600 | I23: 7600 | J23: 7270 | K23: 7600 | L23: 7600 | M23: 7270 | N23: 7600 | O23: 7600 | P23: 7270 | Q23: 7600 | R23: 7600 | S23: 7270 | T23: 7600 | U23: 7600 | V23: 7270 | W23: 7600 | X23: 7600 | Y23: 7270 | Z23: 7600 | AA23: 7600 | AB23: 7270 | AC23: 7600 | AD23: 7600 | AE23: 7270 | AF23: 7600 | AG23: 7600 | AH23: 7070 | AI23: 7400 | AJ23: 7400 | AK23: 7570 | AL23: 8000 | AM23: 8000 | AN23: 1300 | AO23: 1400 | AP23: 1400 | AQ23: 7910 | AR23: 8565 | AS23: 8565 | AT23: 7395 | AU23: 7800 | AV23: 7800 | AW23: 8270 | AX23: 8600 | AY23: 8600 | AZ23: 7870 | BA23: 8425 | BB23: 8425 | BC23: 8020 | BD23: 8475 | BE23: 8475 | BF23: 8095 | BG23: 8800 | BH23: 8800 | BI23: 8470 | BJ23: 8800 | BK23: 8800 | BL23: 8470 | BM23: 8800 | BN23: 8800 | BO23: 8470 | BP23: 8800 | BQ23: 8800 | BU23: =(BO23+2791)-100 -> 11161 | BV23: =(BP23+2791)-100 -> 11491 | BW23: =(BQ23+2791)-100 -> 11491
... A26: Changsha | C26: CNCSX | D26: 7475 | E26: 8100 | F26: 8100 | G26: 7525 | H26: 8100 | I26: 8100 | J26: 7475 | K26: 8100 | L26: 8100 | M26: 7475 | N26: 8100 | O26: 8100 | P26: 7475 | Q26: 8100 | R26: 8100 | S26: 7475 | T26: 8100 | U26: 8100 | V26: 7475 | W26: 8100 | X26: 8100 | Y26: 7475 | Z26: 8100 | AA26: 8100 | AB26: 7475 | AC26: 8100 | AD26: 8100 | AE26: 7475 | AF26: 8100 | AG26: 8100 | AH26: 7325 | AI26: 7900 | AJ26: 7900 | AK26: 7825 | AL26: 8500 | AM26: 8500 | AN26: 1300 | AO26: 1400 | AP26: 1400 | AQ26: 8165 | AR26: 9065 | AS26: 9065 | AT26: 7650 | AU26: 8300 | AV26: 8300 | AW26: 8525 | AX26: 9100 | AY26: 9100 | AZ26: 8125 | BA26: 8925 | BB26: 8925 | BC26: 8275 | BD26: 8975 | BE26: 8975 | BF26: 8350 | BG26: 9300 | BH26: 9300 | BI26: 8725 | BJ26: 9300 | BK26: 9300 | BL26: 8725 | BM26: 9300 | BN26: 9300 | BO26: 8725 | BP26: 9300 | BQ26: 9300 | BU26: =(BO26+2791)-100 -> 11416 | BV26: =(BP26+2791)-100 -> 11991 | BW26: =(BQ26+2791)-100 -> 11991
A27: Changzhou | B27: Barge via Sha | C27: CNCZX | D27: 7425 | E27: 7875 | F27: 7875 | G27: 7400 | H27: 7800 | I27: 7800 | J27: 7425 | K27: 7875 | L27: 7875 | M27: 7425 | N27: 7875 | O27: 7875 | P27: 7425 | Q27: 7875 | R27: 7875 | S27: 7425 | T27: 7875 | U27: 7875 | V27: 7425 | W27: 7875 | X27: 7875 | Y27: 7425 | Z27: 7875 | AA27: 7875 | AB27: 7425 | AC27: 7875 | AD27: 7875 | AE27: 7425 | AF27: 7875 | AG27: 7875 | AH27: 7200 | AI27: 7600 | AJ27: 7600 | AK27: 7700 | AL27: 8200 | AM27: 8200 | AN27: 1300 | AO27: 1400 | AP27: 1400 | AQ27: 8040 | AR27: 8765 | AS27: 8765 | AT27: 7525 | AU27: 8000 | AV27: 8000 | AW27: 8400 | AX27: 8800 | AY27: 8800 | AZ27: 8000 | BA27: 8625 | BB27: 8625 | BC27: 8150 | BD27: 8675 | BE27: 8675 | BF27: 8225 | BG27: 9000 | BH27: 9000 | BI27: 8600 | BJ27: 9000 | BK27: 9000 | BL27: 8600 | BM27: 9000 | BN27: 9000 | BO27: 8600 | BP27: 9000 | BQ27: 9000 | BU27: =(BO27+2791)-100 -> 11291 | BV27: =(BP27+2791)-100 -> 11691 | BW27: =(BQ27+2791)-100 -> 11691
A28: Chengdu | B28: via CNYTN RAIL | C28: CNCTU | D28: 7800 | E28: 8250 | F28: 8250 | G28: 7800 | H28: 8250 | I28: 8250 | J28: 7800 | K28: 8250 | L28: 8250 | M28: 7800 | N28: 8250 | O28: 8250 | P28: 7800 | Q28: 8250 | R28: 8250 | S28: 7800 | T28: 8250 | U28: 8250 | V28: 7800 | W28: 8250 | X28: 8250 | Y28: 7800 | Z28: 8250 | AA28: 8250 | AB28: 7800 | AC28: 8250 | AD28: 8250 | AE28: 7800 | AF28: 8250 | AG28: 8250 | AH28: 7600 | AI28: 8050 | AJ28: 8050 | AK28: 8100 | AL28: 8650 | AM28: 8650 | AN28: 800 | AO28: 800 | AP28: 800 | AQ28: 8440 | AR28: 9215 | AS28: 9215 | AT28: 7925 | AU28: 8450 | AV28: 8450 | AW28: 8800 | AX28: 9250 | AY28: 9250 | AZ28: 8400 | BA28: 9075 | BB28: 9075 | BC28: 8550 | BD28: 9125 | BE28: 9125 | BF28: 8625 | BG28: 9450 | BH28: 9450 | BI28: 9000 | BJ28: 9450 | BK28: 9450 | BL28: 9000 | BM28: 9450 | BN28: 9450 | BO28: 9000 | BP28: 9450 | BQ28: 9450 | BU28: =(BO28+2791)-100 -> 11691 | BV28: =(BP28+2791)-100 -> 12141 | BW28: =(BQ28+2791)-100 -> 12141
A29: Chongqing | B29: Via SHA BARGE | C29: CNCKG | D29: 7500 | E29: 8420 | F29: 8350 | G29: 7375 | H29: 8395 | I29: 8325 | J29: 7500 | K29: 8420 | L29: 8350 | M29: 7500 | N29: 8420 | O29: 8350 | P29: 7500 | Q29: 8420 | R29: 8350 | S29: 7500 | T29: 8420 | U29: 8350 | V29: 7500 | W29: 8420 | X29: 8350 | Y29: 7500 | Z29: 8420 | AA29: 8350 | AB29: 7500 | AC29: 8420 | AD29: 8350 | AE29: 7500 | AF29: 8420 | AG29: 8350 | AH29: 7175 | AI29: 8195 | AJ29: 8125 | AK29: 7675 | AL29: 8795 | AM29: 8725 | AN29: 1300 | AO29: 1400 | AP29: 1400 | AQ29: 8015 | AR29: 9360 | AS29: 9290 | AT29: 7500 | AU29: 8595 | AV29: 8525 | AW29: 8375 | AX29: 9395 | AY29: 9325 | AZ29: 7975 | BA29: 9220 | BB29: 9150 | BC29: 8125 | BD29: 9270 | BE29: 9200 | BF29: 8200 | BG29: 9595 | BH29: 9525 | BI29: 8575 | BJ29: 9595 | BK29: 9525 | BL29: 8575 | BM29: 9595 | BN29: 9525 | BO29: 8575 | BP29: 9595 | BQ29: 9525 | BU29: =(BO29+2791)-100 -> 11266 | BV29: =(BP29+2791)-100 -> 12286 | BW29: =(BQ29+2791)-100 -> 12216
A30: Chongqing | B30: Via NGB RAIL | C30: CNCKG | D30: 7900 | E30: 8520 | F30: 8450 | G30: 7900 | H30: 8520 | I30: 8450 | J30: 7900 | K30: 8520 | L30: 8450 | M30: 7900 | N30: 8520 | O30: 8450 | P30: 7900 | Q30: 8520 | R30: 8450 | S30: 7900 | T30: 8520 | U30: 8450 | V30: 7900 | W30: 8520 | X30: 8450 | Y30: 7900 | Z30: 8520 | AA30: 8450 | AB30: 7900 | AC30: 8520 | AD30: 8450 | AE30: 7900 | AF30: 8520 | AG30: 8450 | AH30: 7700 | AI30: 8320 | AJ30: 8250 | AK30: 8200 | AL30: 8920 | AM30: 8850 | AN30: 1300 | AO30: 1400 | AP30: 1400 | AQ30: 8540 | AR30: 9485 | AS30: 9415 | AT30: 8025 | AU30: 8720 | AV30: 8650 | AW30: 8900 | AX30: 9520 | AY30: 9450 | AZ30: 8500 | BA30: 9345 | BB30: 9275 | BC30: 8650 | BD30: 9395 | BE30: 9325 | BF30: 8725 | BG30: 9720 | BH30: 9650 | BI30: 9100 | BJ30: 9720 | BK30: 9650 | BL30: 9100 | BM30: 9720 | BN30: 9650 | BO30: 9100 | BP30: 9720 | BQ30: 9650 | BU30: =(BO30+2791)-100 -> 11791 | BV30: =(BP30+2791)-100 -> 12411 | BW30: =(BQ30+2791)-100 -> 12341
A31: Chongqing | B31: Via YTN RAIL (move in pair only for D2) | C31: CNCKG | D31: 8200 | E31: 8450 | F31: 8450 | G31: 8200 | H31: 8450 | I31: 8450 | J31: 8200 | K31: 8450 | L31: 8450 | M31: 8200 | N31: 8450 | O31: 8450 | P31: 8200 | Q31: 8450 | R31: 8450 | S31: 8200 | T31: 8450 | U31: 8450 | V31: 8200 | W31: 8450 | X31: 8450 | Y31: 8200 | Z31: 8450 | AA31: 8450 | AB31: 8200 | AC31: 8450 | AD31: 8450 | AE31: 8200 | AF31: 8450 | AG31: 8450 | AH31: 8000 | AI31: 8250 | AJ31: 8250 | AK31: 8500 | AL31: 8850 | AM31: 8850 | AN31: 1300 | AO31: 1400 | AP31: 1400 | AQ31: 8840 | AR31: 9415 | AS31: 9415 | AT31: 8325 | AU31: 8650 | AV31: 8650 | AW31: 9200 | AX31: 9450 | AY31: 9450 | AZ31: 8800 | BA31: 9275 | BB31: 9275 | BC31: 8950 | BD31: 9325 | BE31: 9325 | BF31: 9025 | BG31: 9650 | BH31: 9650 | BI31: 9400 | BJ31: 9650 | BK31: 9650 | BL31: 9400 | BM31: 9650 | BN31: 9650 | BO31: 9400 | BP31: 9650 | BQ31: 9650 | BU31: =((BO31+2791)+150)-100 -> 12241 | BV31: =((BP31+2791)+150)-100 -> 12491 | BW31: =((BQ31+2791)+150)-100 -> 12491
A32: Changshu | C32: CNCGU | D32: 7375 | E32: 7750 | F32: 7750 | G32: 7375 | H32: 7750 | I32: 7750 | J32: 7375 | K32: 7750 | L32: 7750 | M32: 7375 | N32: 7750 | O32: 7750 | P32: 7375 | Q32: 7750 | R32: 7750 | S32: 7375 | T32: 7750 | U32: 7750 | V32: 7375 | W32: 7750 | X32: 7750 | Y32: 7375 | Z32: 7750 | AA32: 7750 | AB32: 7375 | AC32: 7750 | AD32: 7750 | AE32: 7375 | AF32: 7750 | AG32: 7750 | AH32: 7175 | AI32: 7550 | AJ32: 7550 | AK32: 7675 | AL32: 8150 | AM32: 8150 | AN32: 1300 | AO32: 1400 | AP32: 1400 | AQ32: 8015 | AR32: 8715 | AS32: 8715 | AT32: 7500 | AU32: 7950 | AV32: 7950 | AW32: 8375 | AX32: 8750 | AY32: 8750 | AZ32: 7975 | BA32: 8575 | BB32: 8575 | BC32: 8125 | BD32: 8625 | BE32: 8625 | BF32: 8200 | BG32: 8950 | BH32: 8950 | BI32: 8575 | BJ32: 8950 | BK32: 8950 | BL32: 8575 | BM32: 8950 | BN32: 8950 | BO32: 8575 | BP32: 8950 | BQ32: 8950 | BU32: =(BO32+2791)-100 -> 11266 | BV32: =(BP32+2791)-100 -> 11641 | BW32: =(BQ32+2791)-100 -> 11641
A33: Changxing | B33: Via NGB Barge | C33: CNCH1 | D33: 7800 | E33: 8150 | F33: 8150 | G33: 7800 | H33: 8150 | I33: 8150 | J33: 7800 | K33: 8150 | L33: 8150 | M33: 7800 | N33: 8150 | O33: 8150 | P33: 7800 | Q33: 8150 | R33: 8150 | S33: 7800 | T33: 8150 | U33: 8150 | V33: 7800 | W33: 8150 | X33: 8150 | Y33: 7800 | Z33: 8150 | AA33: 8150 | AB33: 7800 | AC33: 8150 | AD33: 8150 | AE33: 7800 | AF33: 8150 | AG33: 8150 | AH33: 7600 | AI33: 7950 | AJ33: 7950 | AK33: 8100 | AL33: 8550 | AM33: 8550 | AN33: 1300 | AO33: 1400 | AP33: 1400 | AQ33: 8440 | AR33: 9115 | AS33: 9115 | AT33: 7925 | AU33: 8350 | AV33: 8350 | AW33: 8900 | AX33: 9250 | AY33: 9250 | AZ33: 8400 | BA33: 8975 | BB33: 8975 | BC33: 8550 | BD33: 9025 | BE33: 9025 | BF33: 8625 | BG33: 9350 | BH33: 9350 | BI33: 9100 | BJ33: 9450 | BK33: 9450 | BL33: 9100 | BM33: 9450 | BN33: 9450 | BO33: 9100 | BP33: 9450 | BQ33: 9450 | BU33: =(BO33+2791)-100 -> 11791 | BV33: =(BP33+2791)-100 -> 12141 | BW33: =(BQ33+2791)-100 -> 12141
A34: Huzhou | B34: Via NGB rail | C34: CNHUZ | D34: 7915 | E34: 8230 | F34: 8230 | G34: 7915 | H34: 8230 | I34: 8230 | J34: 7915 | K34: 8230 | L34: 8230 | M34: 7915 | N34: 8230 | O34: 8230 | P34: 7915 | Q34: 8230 | R34: 8230 | S34: 7915 | T34: 8230 | U34: 8230 | V34: 7915 | W34: 8230 | X34: 8230 | Y34: 7915 | Z34: 8230 | AA34: 8230 | AB34: 7915 | AC34: 8230 | AD34: 8230 | AE34: 7915 | AF34: 8230 | AG34: 8230 | AH34: 7715 | AI34: 8030 | AJ34: 8030 | AK34: 8215 | AL34: 8630 | AM34: 8630 | AN34: 1300 | AO34: 1400 | AP34: 1400 | AQ34: 8555 | AR34: 9195 | AS34: 9195 | AT34: 8040 | AU34: 8430 | AV34: 8430 | AW34: 9015 | AX34: 9330 | AY34: 9330 | AZ34: 8515 | BA34: 9055 | BB34: 9055 | BC34: 8665 | BD34: 9105 | BE34: 9105 | BF34: 8740 | BG34: 9430 | BH34: 9430 | BI34: 9215 | BJ34: 9530 | BK34: 9530 | BL34: 9215 | BM34: 9530 | BN34: 9530 | BO34: 9215 | BP34: 9530 | BQ34: 9530 | BU34: =(BO34+2791)-100 -> 11906 | BV34: =(BP34+2791)-100 -> 12221 | BW34: =(BQ34+2791)-100 -> 12221
A35: Fuzhou/ Fuqing | C35: CNFOC/ CNFUG | D35: 7300 | E35: 7700 | F35: 7700 | G35: 7300 | H35: 7700 | I35: 7700 | J35: 7300 | K35: 7700 | L35: 7700 | M35: 7300 | N35: 7700 | O35: 7700 | P35: 7300 | Q35: 7700 | R35: 7700 | S35: 7300 | T35: 7700 | U35: 7700 | V35: 7300 | W35: 7700 | X35: 7700 | Y35: 7300 | Z35: 7700 | AA35: 7700 | AB35: 7300 | AC35: 7700 | AD35: 7700 | AE35: 7300 | AF35: 7700 | AG35: 7700 | AH35: 7100 | AI35: 7500 | AJ35: 7500 | AK35: 7600 | AL35: 8100 | AM35: 8100 | AN35: 1300 | AO35: 1400 | AP35: 1400 | AQ35: 7940 | AR35: 8665 | AS35: 8665 | AT35: 7425 | AU35: 7900 | AV35: 7900 | AW35: 8300 | AX35: 8700 | AY35: 8700 | AZ35: 7900 | BA35: 8525 | BB35: 8525 | BC35: 8050 | BD35: 8575 | BE35: 8575 | BF35: 8125 | BG35: 8900 | BH35: 8900 | BI35: 8500 | BJ35: 8900 | BK35: 8900 | BL35: 8500 | BM35: 8900 | BN35: 8900 | BO35: 8500 | BP35: 8900 | BQ35: 8900 | BU35: =(BO35+2791)-100 -> 11191 | BV35: =(BP35+2791)-100 -> 11591 | BW35: =(BQ35+2791)-100 -> 11591
A36: Foshan | C36: CNFOS | D36: 7350 | E36: 7750 | F36: 7750 | G36: 7350 | H36: 7750 | I36: 7750 | J36: 7350 | K36: 7750 | L36: 7750 | M36: 7350 | N36: 7750 | O36: 7750 | P36: 7350 | Q36: 7750 | R36: 7750 | S36: 7350 | T36: 7750 | U36: 7750 | V36: 7350 | W36: 7750 | X36: 7750 | Y36: 7350 | Z36: 7750 | AA36: 7750 | AB36: 7350 | AC36: 7750 | AD36: 7750 | AE36: 7350 | AF36: 7750 | AG36: 7750 | AH36: 7150 | AI36: 7550 | AJ36: 7550 | AK36: 7650 | AL36: 8150 | AM36: 8150 | AN36: 1300 | AO36: 1400 | AP36: 1400 | AQ36: 7990 | AR36: 8715 | AS36: 8715 | AT36: 7475 | AU36: 7950 | AV36: 7950 | AW36: 8350 | AX36: 8750 | AY36: 8750 | AZ36: 7950 | BA36: 8575 | BB36: 8575 | BC36: 8100 | BD36: 8625 | BE36: 8625 | BF36: 8175 | BG36: 8950 | BH36: 8950 | BI36: 8550 | BJ36: 8950 | BK36: 8950 | BL36: 8550 | BM36: 8950 | BN36: 8950 | BO36: 8550 | BP36: 8950 | BQ36: 8950 | BU36: =(BO36+2791)-100 -> 11241 | BV36: =(BP36+2791)-100 -> 11641 | BW36: =(BQ36+2791)-100 -> 11641
D37: 1400 | E37: 1500 | F37: 1500 | G37: 1400 | H37: 1500 | I37: 1500 | J37: 1400 | K37: 1500 | L37: 1500 | M37: 1400 | N37: 1500 | O37: 1500 | P37: 1400 | Q37: 1500 | R37: 1500 | S37: 1400 | T37: 1500 | U37: 1500 | V37: 1400 | W37: 1500 | X37: 1500 | Y37: 1400 | Z37: 1500 | AA37: 1500 | AB37: 1400 | AC37: 1500 | AD37: 1500 | AE37: 1400 | AF37: 1500 | AG37: 1500 | AH37: 1200 | AI37: 1300 | AJ37: 1300 | AK37: 1400 | AL37: 1500 | AM37: 1500 | AN37: 1400 | AO37: 1500 | AP37: 1500 | AQ37: 1400 | AR37: 1500 | AS37: 1500 | AT37: 1400 | AU37: 1500 | AV37: 1500 | AW37: 1500 | AX37: 1500 | AY37: 1500 | AZ37: 1400 | BA37: 1500 | BB37: 1500 | BC37: 1400 | BD37: 1500 | BE37: 1500 | BF37: 1400 | BG37: 1500 | BH37: 1500 | BI37: 1700 | BJ37: 1700 | BK37: 1700 | BL37: 1700 | BM37: 1700 | BN37: 1700 | BO37: 1700 | BP37: 1700 | BQ37: 1700
A38: Sanshui | C38: CNSJQ | D38: 7350 | E38: 7750 | F38: 7750 | G38: 7350 | H38: 7750 | I38: 7750 | J38: 7350 | K38: 7750 | L38: 7750 | M38: 7350 | N38: 7750 | O38: 7750 | P38: 7350 | Q38: 7750 | R38: 7750 | S38: 7350 | T38: 7750 | U38: 7750 | V38: 7350 | W38: 7750 | X38: 7750 | Y38: 7350 | Z38: 7750 | AA38: 7750 | AB38: 7350 | AC38: 7750 | AD38: 7750 | AE38: 7350 | AF38: 7750 | AG38: 7750 | AH38: 7150 | AI38: 7550 | AJ38: 7550 | AK38: 7650 | AL38: 8150 | AM38: 8150 | AN38: 1300 | AO38: 1400 | AP38: 1400 | AQ38: 7990 | AR38: 8715 | AS38: 8715 | AT38: 7475 | AU38: 7950 | AV38: 7950 | AW38: 8350 | AX38: 8750 | AY38: 8750 | AZ38: 7950 | BA38: 8575 | BB38: 8575 | BC38: 8100 | BD38: 8625 | BE38: 8625 | BF38: 8175 | BG38: 8950 | BH38: 8950 | BI38: 8550 | BJ38: 8950 | BK38: 8950 | BL38: 8550 | BM38: 8950 | BN38: 8950 | BO38: 8550 | BP38: 8950 | BQ38: 8950 | BR38: -100 | BS38: -100 | BT38: -100 | BU38: =(BO38+2791)-100 -> 11241 | BV38: =(BP38+2791)-100 -> 11641 | BW38: =(BQ38+2791)-100 -> 11641
A39: Beijiao | C39: CNYQS | D39: 7275 | E39: 7650 | F39: 7650 | G39: 7275 | H39: 7650 | I39: 7650 | J39: 7275 | K39: 7650 | L39: 7650 | M39: 7275 | N39: 7650 | O39: 7650 | P39: 7275 | Q39: 7650 | R39: 7650 | S39: 7275 | T39: 7650 | U39: 7650 | V39: 7275 | W39: 7650 | X39: 7650 | Y39: 7275 | Z39: 7650 | AA39: 7650 | AB39: 7275 | AC39: 7650 | AD39: 7650 | AE39: 7275 | AF39: 7650 | AG39: 7650 | AH39: 7075 | AI39: 7450 | AJ39: 7450 | AK39: 7575 | AL39: 8050 | AM39: 8050 | AN39: 1300 | AO39: 1400 | AP39: 1400 | AQ39: 7915 | AR39: 8615 | AS39: 8615 | AT39: 7400 | AU39: 7850 | AV39: 7850 | AW39: 8275 | AX39: 8650 | AY39: 8650 | AZ39: 7875 | BA39: 8475 | BB39: 8475 | BC39: 8025 | BD39: 8525 | BE39: 8525 | BF39: 8100 | BG39: 8850 | BH39: 8850 | BI39: 8475 | BJ39: 8850 | BK39: 8850 | BL39: 8475 | BM39: 8850 | BN39: 8850 | BO39: 8475 | BP39: 8850 | BQ39: 8850 | BR39: -100 | BS39: -100 | BT39: -100 | BU39: =(BO39+2791)-100 -> 11166 | BV39: =(BP39+2791)-100 -> 11541 | BW39: =(BQ39+2791)-100 -> 11541
A40: Leliu | C40: CNLUU | D40: 7300 | E40: 7700 | F40: 7700 | G40: 7300 | H40: 7700 | I40: 7700 | J40: 7300 | K40: 7700 | L40: 7700 | M40: 7300 | N40: 7700 | O40: 7700 | P40: 7300 | Q40: 7700 | R40: 7700 | S40: 7300 | T40: 7700 | U40: 7700 | V40: 7300 | W40: 7700 | X40: 7700 | Y40: 7300 | Z40: 7700 | AA40: 7700 | AB40: 7300 | AC40: 7700 | AD40: 7700 | AE40: 7300 | AF40: 7700 | AG40: 7700 | AH40: 7100 | AI40: 7500 | AJ40: 7500 | AK40: 7600 | AL40: 8100 | AM40: 8100 | AN40: 1300 | AO40: 1400 | AP40: 1400 | AQ40: 7940 | AR40: 8665 | AS40: 8665 | AT40: 7425 | AU40: 7900 | AV40: 7900 | AW40: 8300 | AX40: 8700 | AY40: 8700 | AZ40: 7900 | BA40: 8525 | BB40: 8525 | BC40: 8050 | BD40: 8575 | BE40: 8575 | BF40: 8125 | BG40: 8900 | BH40: 8900 | BI40: 8500 | BJ40: 8900 | BK40: 8900 | BL40: 8500 | BM40: 8900 | BN40: 8900 | BO40: 8500 | BP40: 8900 | BQ40: 8900 | BR40: -100 | BS40: -100 | BT40: -100 | BU40: =(BO40+2791)-100 -> 11191 | BV40: =(BP40+2791)-100 -> 11591 | BW40: =(BQ40+2791)-100 -> 11591
A41: Rongqi | C41: CNROQ | D41: 7300 | E41: 7700 | F41: 7700 | G41: 7300 | H41: 7700 | I41: 7700 | J41: 7300 | K41: 7700 | L41: 7700 | M41: 7300 | N41: 7700 | O41: 7700 | P41: 7300 | Q41: 7700 | R41: 7700 | S41: 7300 | T41: 7700 | U41: 7700 | V41: 7300 | W41: 7700 | X41: 7700 | Y41: 7300 | Z41: 7700 | AA41: 7700 | AB41: 7300 | AC41: 7700 | AD41: 7700 | AE41: 7300 | AF41: 7700 | AG41: 7700 | AH41: 7100 | AI41: 7500 | AJ41: 7500 | AK41: 7600 | AL41: 8100 | AM41: 8100 | AN41: 1300 | AO41: 1400 | AP41: 1400 | AQ41: 7940 | AR41: 8665 | AS41: 8665 | AT41: 7425 | AU41: 7900 | AV41: 7900 | AW41: 8300 | AX41: 8700 | AY41: 8700 | AZ41: 7900 | BA41: 8525 | BB41: 8525 | BC41: 8050 | BD41: 8575 | BE41: 8575 | BF41: 8125 | BG41: 8900 | BH41: 8900 | BI41: 8500 | BJ41: 8900 | BK41: 8900 | BL41: 8500 | BM41: 8900 | BN41: 8900 | BO41: 8500 | BP41: 8900 | BQ41: 8900 | BR41: -100 | BS41: -100 | BT41: -100 | BU41: =(BO41+2791)-100 -> 11191 | BV41: =(BP41+2791)-100 -> 11591 | BW41: =(BQ41+2791)-100 -> 11591
A42: Xiaolan | C42: CNXIL | D42: 7300 | E42: 7700 | F42: 7700 | G42: 7300 | H42: 7700 | I42: 7700 | J42: 7300 | K42: 7700 | L42: 7700 | M42: 7300 | N42: 7700 | O42: 7700 | P42: 7300 | Q42: 7700 | R42: 7700 | S42: 7300 | T42: 7700 | U42: 7700 | V42: 7300 | W42: 7700 | X42: 7700 | Y42: 7300 | Z42: 7700 | AA42: 7700 | AB42: 7300 | AC42: 7700 | AD42: 7700 | AE42: 7300 | AF42: 7700 | AG42: 7700 | AH42: 7100 | AI42: 7500 | AJ42: 7500 | AK42: 7600 | AL42: 8100 | AM42: 8100 | AN42: 1300 | AO42: 1400 | AP42: 1400 | AQ42: 7940 | AR42: 8665 | AS42: 8665 | AT42: 7425 | AU42: 7900 | AV42: 7900 | AW42: 8300 | AX42: 8700 | AY42: 8700 | AZ42: 7900 | BA42: 8525 | BB42: 8525 | BC42: 8050 | BD42: 8575 | BE42: 8575 | BF42: 8125 | BG42: 8900 | BH42: 8900 | BI42: 8500 | BJ42: 8900 | BK42: 8900 | BL42: 8500 | BM42: 8900 | BN42: 8900 | BO42: 8500 | BP42: 8900 | BQ42: 8900 | BR42: -100 | BS42: -100 | BT42: -100 | BU42: =(BO42+2791)-100 -> 11191 | BV42: =(BP42+2791)-100 -> 11591 | BW42: =(BQ42+2791)-100 -> 11591
A43: Gaoming | C43: CNGOM | D43: 7300 | E43: 7700 | F43: 7700 | G43: 7300 | H43: 7700 | I43: 7700 | J43: 7300 | K43: 7700 | L43: 7700 | M43: 7300 | N43: 7700 | O43: 7700 | P43: 7300 | Q43: 7700 | R43: 7700 | S43: 7300 | T43: 7700 | U43: 7700 | V43: 7300 | W43: 7700 | X43: 7700 | Y43: 7300 | Z43: 7700 | AA43: 7700 | AB43: 7300 | AC43: 7700 | AD43: 7700 | AE43: 7300 | AF43: 7700 | AG43: 7700 | AH43: 7100 | AI43: 7500 | AJ43: 7500 | AK43: 7600 | AL43: 8100 | AM43: 8100 | AN43: 1300 | AO43: 1400 | AP43: 1400 | AQ43: 7940 | AR43: 8665 | AS43: 8665 | AT43: 7425 | AU43: 7900 | AV43: 7900 | AW43: 8300 | AX43: 8700 | AY43: 8700 | AZ43: 7900 | BA43: 8525 | BB43: 8525 | BC43: 8050 | BD43: 8575 | BE43: 8575 | BF43: 8125 | BG43: 8900 | BH43: 8900 | BI43: 8500 | BJ43: 8900 | BK43: 8900 | BL43: 8500 | BM43: 8900 | BN43: 8900 | BO43: 8500 | BP43: 8900 | BQ43: 8900 | BR43: -100 | BS43: -100 | BT43: -100 | BU43: =(BO43+2791)-100 -> 11191 | BV43: =(BP43+2791)-100 -> 11591 | BW43: =(BQ43+2791)-100 -> 11591
A44: Nanhai | C44: CNNAH | D44: 7350 | E44: 7800 | F44: 7800 | G44: 7350 | H44: 7800 | I44: 7800 | J44: 7350 | K44: 7800 | L44: 7800 | M44: 7350 | N44: 7800 | O44: 7800 | P44: 7350 | Q44: 7800 | R44: 7800 | S44: 7350 | T44: 7800 | U44: 7800 | V44: 7350 | W44: 7800 | X44: 7800 | Y44: 7350 | Z44: 7800 | AA44: 7800 | AB44: 7350 | AC44: 7800 | AD44: 7800 | AE44: 7350 | AF44: 7800 | AG44: 7800 | AH44: 7150 | AI44: 7600 | AJ44: 7600 | AK44: 7650 | AL44: 8200 | AM44: 8200 | AN44: 1300 | AO44: 1400 | AP44: 1400 | AQ44: 7990 | AR44: 8765 | AS44: 8765 | AT44: 7475 | AU44: 8000 | AV44: 8000 | AW44: 8350 | AX44: 8800 | AY44: 8800 | AZ44: 7950 | BA44: 8625 | BB44: 8625 | BC44: 8100 | BD44: 8675 | BE44: 8675 | BF44: 8175 | BG44: 9000 | BH44: 9000 | BI44: 8550 | BJ44: 9000 | BK44: 9000 | BL44: 8550 | BM44: 9000 | BN44: 9000 | BO44: 8550 | BP44: 9000 | BQ44: 9000 | BR44: -100 | BS44: -100 | BT44: -100 | BU44: =(BO44+2791)-100 -> 11241 | BV44: =(BP44+2791)-100 -> 11691 | BW44: =(BQ44+2791)-100 -> 11691
...

Sheet S.E.A_JPN_SA_AU_NZ Dry 
C1: LAWC FAK Guideline rates
C3: From | D3: To
A4: Validity period | B4: ='China_TWN_SIN_HKG_KR Dry'!B4 -> FAK | C4: 46249 | D4: 46265
C6: POD
C7: Manzanillo,MX | F7: Lazaro Cardenas, MX | I7: Callao, PE | L7: Coronel CL | O7: San Vicente CL | R7: Lirquen, CL | U7: San Antonio, CL | X7: Valparaiso, CL | AA7: Buenaventura, CO | AD7: Guayaquil, EC | AG7: Posorja, EC | AJ7: Iquique, CL | AM7: Antofagasta, CL | AP7: Puerto Angamos, CL | AS7: Ensenada, MX | AV7: Puerto Quetzal, GT | AY7: Rodman , PA | BB7: Panama City, PA (Door) (via Rodman, PA) | BE7: Arica | BH7: Puerto Caldera, CR | BK7: Acajutla, SV | BN7: Corinto, NI | BQ7: San Lorenzo CY/CY , HN (Via NICIO using Marex service - Trucking )
C8: MXZLO | F8: MXLZC | I8: PECLL | L8: CLCNL | O8: CLSVE | R8: CLLQN | U8: CLSAI | X8: CLVAP | AA8: COBUN | AD8: ECGYE | AG8: ECPSJ | AJ8: CLIQQ | AM8: CLANF | AP8: CLPAG | AS8: MXESE | AV8: GTPRQ | AY8: PAROD | BB8: PAPTY | BE8: CLARI | BH8: CRCAL | BK8: SVAQJ | BN8: NICIO | BQ8: HNSLO
A9: POR | B9: POR CODE | C9: 20' | D9: 40' | E9: HCD | F9: 20' | G9: 40' | H9: HCD | I9: 20' | J9: 40' | K9: HCD | L9: 20' | M9: 40' | N9: HCD | O9: 20' | P9: 40' | Q9: HCD | R9: 20' | S9: 40' | T9: HCD | U9: 20' | V9: 40' | W9: HCD | X9: 20' | Y9: 40' | Z9: HCD | AA9: 20' | AB9: 40' | AC9: HCD | AD9: 20' | AE9: 40' | AF9: HCD | AG9: 20' | AH9: 40' | AI9: HCD | AJ9: 20' | AK9: 40' | AL9: HCD | AM9: 20' | AN9: 40' | AO9: HCD | AP9: 20' | AQ9: 40' | AR9: HCD | AS9: 20' | AT9: 40' | AU9: HCD | AV9: 20' | AW9: 40' | AX9: HCD | AY9: 20' | AZ9: 40' | BA9: HCD | BB9: 20' | BC9: 40' | BD9: HCD | BE9: 20' | BF9: 40' | BG9: HCD | BH9: 20' | BI9: 40' | BJ9: HCD | BK9: 20' | BL9: 40' | BM9: HCD | BN9: 20' | BO9: 40' | BP9: HCD | BQ9: 20' | BR9: 40' | BS9: HCD
A10: Laem Chabang | B10: THLCH | C10: 5800 | D10: 6100 | E10: 6100 | F10: 5800 | G10: 6100 | H10: 6100 | I10: 5800 | J10: 6100 | K10: 6100 | L10: 5800 | M10: 6100 | N10: 6100 | O10: 5800 | P10: 6100 | Q10: 6100 | R10: 5800 | S10: 6100 | T10: 6100 | U10: 5800 | V10: 6100 | W10: 6100 | X10: 5800 | Y10: 6100 | Z10: 6100 | AA10: 5800 | AB10: 6100 | AC10: 6100 | AD10: 5800 | AE10: 6100 | AF10: 6100 | AG10: 5600 | AH10: 5900 | AI10: 5900 | AJ10: 6000 | AK10: 6450 | AL10: 6450 | AM10: 900 | AN10: 1100 | AO10: 1100 | AP10: 6090 | AQ10: 6490 | AR10: 6490 | AS10: 5950 | AT10: 6300 | AU10: 6350 | AV10: 5950 | AW10: 6300 | AX10: 6350 | AY10: 6000 | AZ10: 6550 | BA10: 6550 | BB10: 6150 | BC10: 6600 | BD10: 6600 | BE10: 6375 | BF10: 6875 | BG10: 6875 | BH10: 6800 | BI10: 7100 | BJ10: 7100 | BK10: 6800 | BL10: 7100 | BM10: 7100 | BN10: 6800 | BO10: 7100 | BP10: 7100 | BQ10: =BH10+2791 -> 9591 | BR10: =BI10+2791 -> 9891 | BS10: =BJ10+2791 -> 9891
A11: Bangkok | B11: THBKK | C11: 5800 | D11: 6100 | E11: 6100 | F11: 5800 | G11: 6100 | H11: 6100 | I11: 5800 | J11: 6100 | K11: 6100 | L11: 5800 | M11: 6100 | N11: 6100 | O11: 5800 | P11: 6100 | Q11: 6100 | R11: 5800 | S11: 6100 | T11: 6100 | U11: 5800 | V11: 6100 | W11: 6100 | X11: 5800 | Y11: 6100 | Z11: 6100 | AA11: 5800 | AB11: 6100 | AC11: 6100 | AD11: 5800 | AE11: 6100 | AF11: 6100 | AG11: 5600 | AH11: 5900 | AI11: 5900 | AJ11: 6000 | AK11: 6450 | AL11: 6450 | AM11: 900 | AN11: 1100 | AO11: 1100 | AP11: 6090 | AQ11: 6490 | AR11: 6490 | AS11: 5950 | AT11: 6300 | AU11: 6350 | AV11: 5950 | AW11: 6300 | AX11: 6350 | AY11: 6000 | AZ11: 6550 | BA11: 6550 | BB11: 6150 | BC11: 6600 | BD11: 6600 | BE11: 6375 | BF11: 6875 | BG11: 6875 | BH11: 6800 | BI11: 7100 | BJ11: 7100 | BK11: 6800 | BL11: 7100 | BM11: 7100 | BN11: 6800 | BO11: 7100 | BP11: 7100 | BQ11: =BH11+2791 -> 9591 | BR11: =BI11+2791 -> 9891 | BS11: =BJ11+2791 -> 9891
A12: Lat Krabang | B12: THLKR | C12: 5875 | D12: 6200 | E12: 6200 | F12: 5875 | G12: 6200 | H12: 6200 | I12: 5875 | J12: 6200 | K12: 6200 | L12: 5875 | M12: 6200 | N12: 6200 | O12: 5875 | P12: 6200 | Q12: 6200 | R12: 5875 | S12: 6200 | T12: 6200 | U12: 5875 | V12: 6200 | W12: 6200 | X12: 5875 | Y12: 6200 | Z12: 6200 | AA12: 5875 | AB12: 6200 | AC12: 6200 | AD12: 5875 | AE12: 6200 | AF12: 6200 | AG12: 5675 | AH12: 6000 | AI12: 6000 | AJ12: 6075 | AK12: 6550 | AL12: 6550 | AM12: 900 | AN12: 1100 | AO12: 1100 | AP12: 6165 | AQ12: 6590 | AR12: 6590 | AS12: 6025 | AT12: 6400 | AU12: 6400 | AV12: 6025 | AW12: 6400 | AX12: 6400 | AY12: 6075 | AZ12: 6650 | BA12: 6650 | BB12: 6225 | BC12: 6700 | BD12: 6700 | BE12: 6450 | BF12: 6975 | BG12: 6975 | BH12: 6875 | BI12: 7200 | BJ12: 7200 | BK12: 6875 | BL12: 7200 | BM12: 7200 | BN12: 6875 | BO12: 7200 | BP12: 7200 | BQ12: =BH12+2791 -> 9666 | BR12: =BI12+2791 -> 9991 | BS12: =BJ12+2791 -> 9991
A13: Songkhla | B13: THSGZ | C13: 6000 | D13: 6500 | E13: 6500 | F13: 6000 | G13: 6500 | H13: 6500 | I13: 6000 | J13: 6500 | K13: 6500 | L13: 6000 | M13: 6500 | N13: 6500 | O13: 6000 | P13: 6500 | Q13: 6500 | R13: 6000 | S13: 6500 | T13: 6500 | U13: 6000 | V13: 6500 | W13: 6500 | X13: 6000 | Y13: 6500 | Z13: 6500 | AA13: 6000 | AB13: 6500 | AC13: 6500 | AD13: 6000 | AE13: 6500 | AF13: 6500 | AG13: 5800 | AH13: 6300 | AI13: 6300 | AJ13: 6200 | AK13: 6850 | AL13: 6850 | AM13: 900 | AN13: 1100 | AO13: 1100 | AP13: 6290 | AQ13: 6890 | AR13: 6890 | AS13: 6150 | AT13: 6700 | AU13: 6750 | AV13: 6150 | AW13: 6700 | AX13: 6750 | AY13: 6200 | AZ13: 6950 | BA13: 6950 | BB13: 6350 | BC13: 7000 | BD13: 7000 | BE13: 6575 | BF13: 7275 | BG13: 7275 | BH13: 7000 | BI13: 7500 | BJ13: 7500 | BK13: 7000 | BL13: 7500 | BM13: 7500 | BN13: 7000 | BO13: 7500 | BP13: 7500 | BQ13: =BH13+2791 -> 9791 | BR13: =BI13+2791 -> 10291 | BS13: =BJ13+2791 -> 10291
A14: Port Klang | B14: MYPKG | C14: 5800 | D14: 6100 | E14: 6100 | F14: 5800 | G14: 6100 | H14: 6100 | I14: 5800 | J14: 6100 | K14: 6100 | L14: 5800 | M14: 6100 | N14: 6100 | O14: 5800 | P14: 6100 | Q14: 6100 | R14: 5800 | S14: 6100 | T14: 6100 | U14: 5800 | V14: 6100 | W14: 6100 | X14: 5800 | Y14: 6100 | Z14: 6100 | AA14: 5800 | AB14: 6100 | AC14: 6100 | AD14: 5800 | AE14: 6100 | AF14: 6100 | AG14: 5600 | AH14: 5900 | AI14: 5900 | AJ14: 6000 | AK14: 6450 | AL14: 6450 | AM14: 1000 | AN14: 1200 | AO14: 1200 | AP14: 6090 | AQ14: 6490 | AR14: 6490 | AS14: 5950 | AT14: 6300 | AU14: 6350 | AV14: 5950 | AW14: 6300 | AX14: 6350 | AY14: 6200 | AZ14: 6750 | BA14: 6750 | BB14: 6350 | BC14: 6800 | BD14: 6800 | BE14: 6375 | BF14: 6875 | BG14: 6875 | BH14: 6800 | BI14: 7100 | BJ14: 7100 | BK14: 6800 | BL14: 7100 | BM14: 7100 | BN14: 6800 | BO14: 7100 | BP14: 7100 | BQ14: =BH14+2791 -> 9591 | BR14: =BI14+2791 -> 9891 | BS14: =BJ14+2791 -> 9891
A15: Penang | B15: MYPEN | C15: 5825 | D15: 6375 | E15: 6375 | F15: 5825 | G15: 6375 | H15: 6375 | I15: 5825 | J15: 6375 | K15: 6375 | L15: 5825 | M15: 6375 | N15: 6375 | O15: 5825 | P15: 6375 | Q15: 6375 | R15: 5825 | S15: 6375 | T15: 6375 | U15: 5825 | V15: 6375 | W15: 6375 | X15: 5825 | Y15: 6375 | Z15: 6375 | AA15: 5825 | AB15: 6375 | AC15: 6375 | AD15: 5825 | AE15: 6375 | AF15: 6375 | AG15: 5625 | AH15: 6175 | AI15: 6175 | AJ15: 6025 | AK15: 6725 | AL15: 6725 | AM15: 1000 | AN15: 1200 | AO15: 1200 | AP15: 6115 | AQ15: 6765 | AR15: 6765 | AS15: 5975 | AT15: 6575 | AU15: 6625 | AV15: 5975 | AW15: 6575 | AX15: 6625 | AY15: 6225 | AZ15: 7025 | BA15: 7025 | BB15: 6375 | BC15: 7075 | BD15: 7075 | BE15: 6400 | BF15: 7150 | BG15: 7150 | BH15: 6825 | BI15: 7375 | BJ15: 7375 | BK15: 6825 | BL15: 7375 | BM15: 7375 | BN15: 6825 | BO15: 7375 | BP15: 7375 | BQ15: =BH15+2791 -> 9616 | BR15: =BI15+2791 -> 10166 | BS15: =BJ15+2791 -> 10166
A16: Tanjong Pelepas | B16: MYTPP | C16: 5825 | D16: 6375 | E16: 6375 | F16: 5825 | G16: 6375 | H16: 6375 | I16: 5825 | J16: 6375 | K16: 6375 | L16: 5825 | M16: 6375 | N16: 6375 | O16: 5825 | P16: 6375 | Q16: 6375 | R16: 5825 | S16: 6375 | T16: 6375 | U16: 5825 | V16: 6375 | W16: 6375 | X16: 5825 | Y16: 6375 | Z16: 6375 | AA16: 5825 | AB16: 6375 | AC16: 6375 | AD16: 5825 | AE16: 6375 | AF16: 6375 | AG16: 5625 | AH16: 6175 | AI16: 6175 | AJ16: 6025 | AK16: 6725 | AL16: 6725 | AM16: 1000 | AN16: 1200 | AO16: 1200 | AP16: 6115 | AQ16: 6765 | AR16: 6765 | AS16: 5975 | AT16: 6575 | AU16: 6625 | AV16: 5975 | AW16: 6575 | AX16: 6625 | AY16: 6225 | AZ16: 7025 | BA16: 7025 | BB16: 6375 | BC16: 7075 | BD16: 7075 | BE16: 6400 | BF16: 7150 | BG16: 7150 | BH16: 6825 | BI16: 7375 | BJ16: 7375 | BK16: 6825 | BL16: 7375 | BM16: 7375 | BN16: 6825 | BO16: 7375 | BP16: 7375 | BQ16: =BH16+2791 -> 9616 | BR16: =BI16+2791 -> 10166 | BS16: =BJ16+2791 -> 10166
A17: Pasir Gudang | B17: MYPGU | C17: 5825 | D17: 6375 | E17: 6375 | F17: 5825 | G17: 6375 | H17: 6375 | I17: 5825 | J17: 6375 | K17: 6375 | L17: 5825 | M17: 6375 | N17: 6375 | O17: 5825 | P17: 6375 | Q17: 6375 | R17: 5825 | S17: 6375 | T17: 6375 | U17: 5825 | V17: 6375 | W17: 6375 | X17: 5825 | Y17: 6375 | Z17: 6375 | AA17: 5825 | AB17: 6375 | AC17: 6375 | AD17: 5825 | AE17: 6375 | AF17: 6375 | AG17: 5625 | AH17: 6175 | AI17: 6175 | AJ17: 6025 | AK17: 6725 | AL17: 6725 | AM17: 1000 | AN17: 1200 | AO17: 1200 | AP17: 6115 | AQ17: 6765 | AR17: 6765 | AS17: 5975 | AT17: 6575 | AU17: 6625 | AV17: 5975 | AW17: 6575 | AX17: 6625 | AY17: 6225 | AZ17: 7025 | BA17: 7025 | BB17: 6375 | BC17: 7075 | BD17: 7075 | BE17: 6400 | BF17: 7150 | BG17: 7150 | BH17: 6825 | BI17: 7375 | BJ17: 7375 | BK17: 6825 | BL17: 7375 | BM17: 7375 | BN17: 6825 | BO17: 7375 | BP17: 7375 | BQ17: =BH17+2791 -> 9616 | BR17: =BI17+2791 -> 10166 | BS17: =BJ17+2791 -> 10166
A18: Jakarta | B18: IDJKT | C18: 5800 | D18: 6100 | E18: 6100 | F18: 5800 | G18: 6100 | H18: 6100 | I18: 5800 | J18: 6100 | K18: 6100 | L18: 5800 | M18: 6100 | N18: 6100 | O18: 5800 | P18: 6100 | Q18: 6100 | R18: 5800 | S18: 6100 | T18: 6100 | U18: 5800 | V18: 6100 | W18: 6100 | X18: 5800 | Y18: 6100 | Z18: 6100 | AA18: 5800 | AB18: 6100 | AC18: 6100 | AD18: 5800 | AE18: 6100 | AF18: 6100 | AG18: 5600 | AH18: 5900 | AI18: 5900 | AJ18: 6025 | AK18: 6450 | AL18: 6450 | AM18: 900 | AN18: 1100 | AO18: 1100 | AP18: 6290 | AQ18: 6790 | AR18: 6790 | AS18: 6050 | AT18: 6500 | AU18: 6550 | AV18: 6050 | AW18: 6500 | AX18: 6550 | AY18: 6050 | AZ18: 6700 | BA18: 6700 | BB18: 6200 | BC18: 6750 | BD18: 6750 | BE18: 6400 | BF18: 6850 | BG18: 6850 | BH18: 6800 | BI18: 7100 | BJ18: 7100 | BK18: 6800 | BL18: 7100 | BM18: 7100 | BN18: 6800 | BO18: 7100 | BP18: 7100 | BQ18: =BH18+2791 -> 9591 | BR18: =BI18+2791 -> 9891 | BS18: =BJ18+2791 -> 9891
A19: Surabaya | B19: IDSUB | C19: 5800 | D19: 6100 | E19: 6100 | F19: 5800 | G19: 6100 | H19: 6100 | I19: 5800 | J19: 6100 | K19: 6100 | L19: 5800 | M19: 6100 | N19: 6100 | O19: 5800 | P19: 6100 | Q19: 6100 | R19: 5800 | S19: 6100 | T19: 6100 | U19: 5800 | V19: 6100 | W19: 6100 | X19: 5800 | Y19: 6100 | Z19: 6100 | AA19: 5800 | AB19: 6100 | AC19: 6100 | AD19: 5800 | AE19: 6100 | AF19: 6100 | AG19: 5600 | AH19: 5900 | AI19: 5900 | AJ19: 6025 | AK19: 6450 | AL19: 6450 | AM19: 900 | AN19: 1100 | AO19: 1100 | AP19: 6290 | AQ19: 6790 | AR19: 6790 | AS19: 6050 | AT19: 6500 | AU19: 6550 | AV19: 6050 | AW19: 6500 | AX19: 6550 | AY19: 6050 | AZ19: 6700 | BA19: 6700 | BB19: 6200 | BC19: 6750 | BD19: 6750 | BE19: 6400 | BF19: 6850 | BG19: 6850 | BH19: 6800 | BI19: 7100 | BJ19: 7100 | BK19: 6800 | BL19: 7100 | BM19: 7100 | BN19: 6800 | BO19: 7100 | BP19: 7100 | BQ19: =BH19+2791 -> 9591 | BR19: =BI19+2791 -> 9891 | BS19: =BJ19+2791 -> 9891
A20: Belawan | B20: IDBLW | C20: 6300 | D20: 7150 | E20: 7150 | F20: 6300 | G20: 7150 | H20: 7150 | I20: 6300 | J20: 7150 | K20: 7150 | L20: 6300 | M20: 7150 | N20: 7150 | O20: 6300 | P20: 7150 | Q20: 7150 | R20: 6300 | S20: 7150 | T20: 7150 | U20: 6300 | V20: 7150 | W20: 7150 | X20: 6300 | Y20: 7150 | Z20: 7150 | AA20: 6300 | AB20: 7150 | AC20: 7150 | AD20: 6300 | AE20: 7150 | AF20: 7150 | AG20: 6100 | AH20: 6950 | AI20: 6950 | AJ20: 6525 | AK20: 7500 | AL20: 7500 | AM20: 900 | AN20: 1100 | AO20: 1100 | AP20: 6790 | AQ20: 7840 | AR20: 7840 | AS20: 6550 | AT20: 7550 | AU20: 7600 | AV20: 6550 | AW20: 7550 | AX20: 7600 | AY20: 6550 | AZ20: 7750 | BA20: 7750 | BB20: 6700 | BC20: 7800 | BD20: 7800 | BE20: 6900 | BF20: 7900 | BG20: 7900 | BH20: 7300 | BI20: 8150 | BJ20: 8150 | BK20: 7300 | BL20: 8150 | BM20: 8150 | BN20: 7300 | BO20: 8150 | BP20: 8150 | BQ20: =BH20+2791 -> 10091 | BR20: =BI20+2791 -> 10941 | BS20: =BJ20+2791 -> 10941
A21: Semarang | B21: IDSRG | C21: 5800 | D21: 6100 | E21: 6100 | F21: 5800 | G21: 6100 | H21: 6100 | I21: 5800 | J21: 6100 | K21: 6100 | L21: 5800 | M21: 6100 | N21: 6100 | O21: 5800 | P21: 6100 | Q21: 6100 | R21: 5800 | S21: 6100 | T21: 6100 | U21: 5800 | V21: 6100 | W21: 6100 | X21: 5800 | Y21: 6100 | Z21: 6100 | AA21: 5800 | AB21: 6100 | AC21: 6100 | AD21: 5800 | AE21: 6100 | AF21: 6100 | AG21: 5600 | AH21: 5900 | AI21: 5900 | AJ21: 6025 | AK21: 6450 | AL21: 6450 | AM21: 900 | AN21: 1100 | AO21: 1100 | AP21: 6290 | AQ21: 6790 | AR21: 6790 | AS21: 6050 | AT21: 6500 | AU21: 6550 | AV21: 6050 | AW21: 6500 | AX21: 6550 | AY21: 6050 | AZ21: 6700 | BA21: 6700 | BB21: 6200 | BC21: 6750 | BD21: 6750 | BE21: 6400 | BF21: 6850 | BG21: 6850 | BH21: 6800 | BI21: 7100 | BJ21: 7100 | BK21: 6800 | BL21: 7100 | BM21: 7100 | BN21: 6800 | BO21: 7100 | BP21: 7100 | BQ21: =BH21+2791 -> 9591 | BR21: =BI21+2791 -> 9891 | BS21: =BJ21+2791 -> 9891
... A28: Haiphong | B28: VNHPH | C28: 5800 | D28: 6100 | E28: 6100 | F28: 5800 | G28: 6100 | H28: 6100 | I28: 5800 | J28: 6100 | K28: 6100 | L28: 5800 | M28: 6100 | N28: 6100 | O28: 5800 | P28: 6100 | Q28: 6100 | R28: 5800 | S28: 6100 | T28: 6100 | U28: 5800 | V28: 6100 | W28: 6100 | X28: 5800 | Y28: 6100 | Z28: 6100 | AA28: 5800 | AB28: 6100 | AC28: 6100 | AD28: 5800 | AE28: 6100 | AF28: 6100 | AG28: 5600 | AH28: 5900 | AI28: 5900 | AJ28: 6000 | AK28: 6450 | AL28: 6450 | AM28: 900 | AN28: 1100 | AO28: 1100 | AP28: 6385 | AQ28: 6890 | AR28: 6890 | AS28: 5950 | AT28: 6250 | AU28: 6300 | AV28: 5950 | AW28: 6250 | AX28: 6300 | AY28: 5950 | AZ28: 6450 | BA28: 6450 | BB28: 6800 | BC28: 7200 | BD28: 7200 | BE28: 6375 | BF28: 6875 | BG28: 6875 | BH28: 6800 | BI28: 7100 | BJ28: 7100 | BK28: 6800 | BL28: 7100 | BM28: 7100 | BN28: 6800 | BO28: 7100 | BP28: 7100 | BQ28: =BH28+2791 -> 9591 | BR28: =BI28+2791 -> 9891 | BS28: =BJ28+2791 -> 9891
A29: Jeddah | B29: SAJED | C29: 0 | D29: 0 | E29: 0 | F29: 0 | G29: 0 | H29: 0 | I29: 0 | J29: 0 | K29: 0 | L29: 0 | M29: 0 | N29: 0 | O29: 0 | P29: 0 | Q29: 0 | R29: 0 | S29: 0 | T29: 0 | U29: 0 | V29: 0 | W29: 0 | X29: 0 | Y29: 0 | Z29: 0 | AA29: 0 | AB29: 0 | AC29: 0 | AD29: 0 | AE29: 0 | AF29: 0 | AG29: 0 | AH29: 0 | AI29: 0 | AJ29: 0 | AK29: 0 | AL29: 0 | AM29: 0 | AN29: 0 | AO29: 0 | AP29: 0 | AQ29: 0 | AR29: 0 | AS29: 0 | AT29: 0 | AU29: 0 | AV29: 0 | AW29: 0 | AX29: 0 | AY29: 0 | AZ29: 0 | BA29: 0 | BB29: 0 | BC29: 0 | BD29: 0 | BE29: 0 | BF29: 0 | BG29: 0 | BH29: 0 | BI29: 0 | BJ29: 0 | BK29: 0 | BL29: 0 | BM29: 0 | BN29: 0 | BO29: 0 | BP29: 0
A30: Melbourne | B30: AUMEL | C30: 7675 | D30: 8600 | E30: 8600 | F30: 7575 | G30: 8500 | H30: 8500 | I30: 7675 | J30: 8600 | K30: 8600 | L30: 7675 | M30: 8600 | N30: 8600 | O30: 7675 | P30: 8600 | Q30: 8600 | R30: 7675 | S30: 8600 | T30: 8600 | U30: 7675 | V30: 8600 | W30: 8600 | X30: 7675 | Y30: 8600 | Z30: 8600 | AA30: 7675 | AB30: 8600 | AC30: 8600 | AD30: 7675 | AE30: 8600 | AF30: 8600 | AG30: 7475 | AH30: 8400 | AI30: 8400 | AJ30: 7975 | AK30: 8950 | AL30: 8950 | AM30: 1600 | AN30: 1800 | AO30: 1800 | AP30: 7990 | AQ30: 9165 | AR30: 9165 | AS30: 7700 | AT30: 8775 | AU30: 8775 | AV30: 7700 | AW30: 8775 | AX30: 8775 | AY30: 7750 | AZ30: 8825 | BA30: 8825 | BB30: 8000 | BC30: 9075 | BD30: 9075 | BE30: 8325 | BF30: 9400 | BG30: 9400 | BH30: 8675 | BI30: 10100 | BJ30: 10100 | BK30: 8675 | BL30: 10100 | BM30: 10100 | BN30: 8675 | BO30: 10100 | BP30: 10100 | BQ30: =BH30+2791 -> 11466 | BR30: =BI30+2791 -> 12891 | BS30: =BJ30+2791 -> 12891
A31: Adelaide | B31: AUADL | C31: 8275 | D31: 9200 | E31: 9200 | F31: 8175 | G31: 9100 | H31: 9100 | I31: 8275 | J31: 9200 | K31: 9200 | L31: 8275 | M31: 9200 | N31: 9200 | O31: 8275 | P31: 9200 | Q31: 9200 | R31: 8275 | S31: 9200 | T31: 9200 | U31: 8275 | V31: 9200 | W31: 9200 | X31: 8275 | Y31: 9200 | Z31: 9200 | AA31: 8275 | AB31: 9200 | AC31: 9200 | AD31: 8275 | AE31: 9200 | AF31: 9200 | AG31: 8075 | AH31: 9000 | AI31: 9000 | AJ31: 8575 | AK31: 9550 | AL31: 9550 | AM31: 1600 | AN31: 1800 | AO31: 1800 | AP31: 8590 | AQ31: 9765 | AR31: 9765 | AS31: 8300 | AT31: 9375 | AU31: 9375 | AV31: 8300 | AW31: 9375 | AX31: 9375 | AY31: 8350 | AZ31: 9425 | BA31: 9425 | BB31: 8600 | BC31: 9675 | BD31: 9675 | BE31: 8925 | BF31: 10000 | BG31: 10000 | BH31: 9275 | BI31: 10700 | BJ31: 10700 | BK31: 9275 | BL31: 10700 | BM31: 10700 | BN31: 9275 | BO31: 10700 | BP31: 10700 | BQ31: =BH31+2791 -> 12066 | BR31: =BI31+2791 -> 13491 | BS31: =BJ31+2791 -> 13491
A32: Sydney | B32: AUSYD | C32: 7675 | D32: 8600 | E32: 8600 | F32: 7575 | G32: 8500 | H32: 8500 | I32: 7675 | J32: 8600 | K32: 8600 | L32: 7675 | M32: 8600 | N32: 8600 | O32: 7675 | P32: 8600 | Q32: 8600 | R32: 7675 | S32: 8600 | T32: 8600 | U32: 7675 | V32: 8600 | W32: 8600 | X32: 7675 | Y32: 8600 | Z32: 8600 | AA32: 7675 | AB32: 8600 | AC32: 8600 | AD32: 7675 | AE32: 8600 | AF32: 8600 | AG32: 7475 | AH32: 8400 | AI32: 8400 | AJ32: 7975 | AK32: 8950 | AL32: 8950 | AM32: 1600 | AN32: 1800 | AO32: 1800 | AP32: 7990 | AQ32: 9165 | AR32: 9165 | AS32: 7700 | AT32: 8775 | AU32: 8775 | AV32: 7700 | AW32: 8775 | AX32: 8775 | AY32: 7750 | AZ32: 8825 | BA32: 8825 | BB32: 8000 | BC32: 9075 | BD32: 9075 | BE32: 8325 | BF32: 9400 | BG32: 9400 | BH32: 8675 | BI32: 10100 | BJ32: 10100 | BK32: 8675 | BL32: 10100 | BM32: 10100 | BN32: 8675 | BO32: 10100 | BP32: 10100 | BQ32: =BH32+2791 -> 11466 | BR32: =BI32+2791 -> 12891 | BS32: =BJ32+2791 -> 12891
A33: Brisbane | B33: AUBNE | C33: 7675 | D33: 8600 | E33: 8600 | F33: 7575 | G33: 8500 | H33: 8500 | I33: 7675 | J33: 8600 | K33: 8600 | L33: 7675 | M33: 8600 | N33: 8600 | O33: 7675 | P33: 8600 | Q33: 8600 | R33: 7675 | S33: 8600 | T33: 8600 | U33: 7675 | V33: 8600 | W33: 8600 | X33: 7675 | Y33: 8600 | Z33: 8600 | AA33: 7675 | AB33: 8600 | AC33: 8600 | AD33: 7675 | AE33: 8600 | AF33: 8600 | AG33: 7475 | AH33: 8400 | AI33: 8400 | AJ33: 7975 | AK33: 8950 | AL33: 8950 | AM33: 1600 | AN33: 1800 | AO33: 1800 | AP33: 7990 | AQ33: 9165 | AR33: 9165 | AS33: 7700 | AT33: 8775 | AU33: 8775 | AV33: 7700 | AW33: 8775 | AX33: 8775 | AY33: 7750 | AZ33: 8825 | BA33: 8825 | BB33: 8000 | BC33: 9075 | BD33: 9075 | BE33: 8325 | BF33: 9400 | BG33: 9400 | BH33: 8675 | BI33: 10100 | BJ33: 10100 | BK33: 8675 | BL33: 10100 | BM33: 10100 | BN33: 8675 | BO33: 10100 | BP33: 10100 | BQ33: =BH33+2791 -> 11466 | BR33: =BI33+2791 -> 12891 | BS33: =BJ33+2791 -> 12891
A34: Fremantle | B34: AUFRE | C34: 7675 | D34: 8600 | E34: 8600 | F34: 7575 | G34: 8500 | H34: 8500 | I34: 7675 | J34: 8600 | K34: 8600 | L34: 7675 | M34: 8600 | N34: 8600 | O34: 7675 | P34: 8600 | Q34: 8600 | R34: 7675 | S34: 8600 | T34: 8600 | U34: 7675 | V34: 8600 | W34: 8600 | X34: 7675 | Y34: 8600 | Z34: 8600 | AA34: 7675 | AB34: 8600 | AC34: 8600 | AD34: 7675 | AE34: 8600 | AF34: 8600 | AG34: 7475 | AH34: 8400 | AI34: 8400 | AJ34: 7975 | AK34: 8950 | AL34: 8950 | AM34: 1600 | AN34: 1800 | AO34: 1800 | AP34: 7990 | AQ34: 9165 | AR34: 9165 | AS34: 7700 | AT34: 8775 | AU34: 8775 | AV34: 7700 | AW34: 8775 | AX34: 8775 | AY34: 7750 | AZ34: 8825 | BA34: 8825 | BB34: 8000 | BC34: 9075 | BD34: 9075 | BE34: 8325 | BF34: 9400 | BG34: 9400 | BH34: 8675 | BI34: 10100 | BJ34: 10100 | BK34: 8675 | BL34: 10100 | BM34: 10100 | BN34: 8675 | BO34: 10100 | BP34: 10100 | BQ34: =BH34+2791 -> 11466 | BR34: =BI34+2791 -> 12891 | BS34: =BJ34+2791 -> 12891
A35: Auckland | B35: NZAKL | C35: 7675 | D35: 8600 | E35: 8600 | F35: 7575 | G35: 8500 | H35: 8500 | I35: 7675 | J35: 8600 | K35: 8600 | L35: 7675 | M35: 8600 | N35: 8600 | O35: 7675 | P35: 8600 | Q35: 8600 | R35: 7675 | S35: 8600 | T35: 8600 | U35: 7675 | V35: 8600 | W35: 8600 | X35: 7675 | Y35: 8600 | Z35: 8600 | AA35: 7675 | AB35: 8600 | AC35: 8600 | AD35: 7675 | AE35: 8600 | AF35: 8600 | AG35: 7475 | AH35: 8400 | AI35: 8400 | AJ35: 7975 | AK35: 8950 | AL35: 8950 | AM35: 1600 | AN35: 1800 | AO35: 1800 | AP35: 7990 | AQ35: 9165 | AR35: 9165 | AS35: 7700 | AT35: 8775 | AU35: 8775 | AV35: 7700 | AW35: 8775 | AX35: 8775 | AY35: 7750 | AZ35: 8825 | BA35: 8825 | BB35: 8000 | BC35: 9075 | BD35: 9075 | BE35: 8325 | BF35: 9400 | BG35: 9400 | BH35: 8675 | BI35: 10100 | BJ35: 10100 | BK35: 8675 | BL35: 10100 | BM35: 10100 | BN35: 8675 | BO35: 10100 | BP35: 10100 | BQ35: =BH35+2791 -> 11466 | BR35: =BI35+2791 -> 12891 | BS35: =BJ35+2791 -> 12891
A36: Tauranga | B36: NZTRG | C36: 7875 | D36: 9000 | E36: 9000 | F36: 7775 | G36: 8900 | H36: 8900 | I36: 7875 | J36: 9000 | K36: 9000 | L36: 7875 | M36: 9000 | N36: 9000 | O36: 7875 | P36: 9000 | Q36: 9000 | R36: 7875 | S36: 9000 | T36: 9000 | U36: 7875 | V36: 9000 | W36: 9000 | X36: 7875 | Y36: 9000 | Z36: 9000 | AA36: 7875 | AB36: 9000 | AC36: 9000 | AD36: 7875 | AE36: 9000 | AF36: 9000 | AG36: 7675 | AH36: 8800 | AI36: 8800 | AJ36: 8175 | AK36: 9350 | AL36: 9350 | AM36: 1600 | AN36: 1800 | AO36: 1800 | AP36: 8190 | AQ36: 9565 | AR36: 9565 | AS36: 7900 | AT36: 9175 | AU36: 9175 | AV36: 7900 | AW36: 9175 | AX36: 9175 | AY36: 7950 | AZ36: 9225 | BA36: 9225 | BB36: 8200 | BC36: 9475 | BD36: 9475 | BE36: 8525 | BF36: 9800 | BG36: 9800 | BH36: 8875 | BI36: 10500 | BJ36: 10500 | BK36: 8875 | BL36: 10500 | BM36: 10500 | BN36: 8875 | BO36: 10500 | BP36: 10500 | BQ36: =BH36+2791 -> 11666 | BR36: =BI36+2791 -> 13291 | BS36: =BJ36+2791 -> 13291
A37: Lyttelton | B37: NZLYT | C37: 7675 | D37: 8600 | E37: 8600 | F37: 7575 | G37: 8500 | H37: 8500 | I37: 7675 | J37: 8600 | K37: 8600 | L37: 7675 | M37: 8600 | N37: 8600 | O37: 7675 | P37: 8600 | Q37: 8600 | R37: 7675 | S37: 8600 | T37: 8600 | U37: 7675 | V37: 8600 | W37: 8600 | X37: 7675 | Y37: 8600 | Z37: 8600 | AA37: 7675 | AB37: 8600 | AC37: 8600 | AD37: 7675 | AE37: 8600 | AF37: 8600 | AG37: 7475 | AH37: 8400 | AI37: 8400 | AJ37: 7975 | AK37: 8950 | AL37: 8950 | AM37: 1600 | AN37: 1800 | AO37: 1800 | AP37: 7990 | AQ37: 9165 | AR37: 9165 | AS37: 7700 | AT37: 8775 | AU37: 8775 | AV37: 7700 | AW37: 8775 | AX37: 8775 | AY37: 7750 | AZ37: 8825 | BA37: 8825 | BB37: 8000 | BC37: 9075 | BD37: 9075 | BE37: 8325 | BF37: 9400 | BG37: 9400 | BH37: 8675 | BI37: 10100 | BJ37: 10100 | BK37: 8675 | BL37: 10100 | BM37: 10100 | BN37: 8675 | BO37: 10100 | BP37: 10100 | BQ37: =BH37+2791 -> 11466 | BR37: =BI37+2791 -> 12891 | BS37: =BJ37+2791 -> 12891
A38: Napier | B38: NZNPE | C38: 8085 | D38: 9225 | E38: 9225 | F38: 7985 | G38: 9125 | H38: 9125 | I38: 8085 | J38: 9225 | K38: 9225 | L38: 8085 | M38: 9225 | N38: 9225 | O38: 8085 | P38: 9225 | Q38: 9225 | R38: 8085 | S38: 9225 | T38: 9225 | U38: 8085 | V38: 9225 | W38: 9225 | X38: 8085 | Y38: 9225 | Z38: 9225 | AA38: 8085 | AB38: 9225 | AC38: 9225 | AD38: 8085 | AE38: 9225 | AF38: 9225 | AG38: 7885 | AH38: 9025 | AI38: 9025 | AJ38: 8385 | AK38: 9575 | AL38: 9575 | AM38: 1600 | AN38: 1800 | AO38: 1800 | AP38: 8400 | AQ38: 9790 | AR38: 9790 | AS38: 8110 | AT38: 9400 | AU38: 9400 | AV38: 8110 | AW38: 9400 | AX38: 9400 | AY38: 8160 | AZ38: 9450 | BA38: 9450 | BB38: 8410 | BC38: 9700 | BD38: 9700 | BE38: 8735 | BF38: 10025 | BG38: 10025 | BH38: 9085 | BI38: 10725 | BJ38: 10725 | BK38: 9085 | BL38: 10725 | BM38: 10725 | BN38: 9085 | BO38: 10725 | BP38: 10725 | BQ38: =BH38+2791 -> 11876 | BR38: =BI38+2791 -> 13516 | BS38: =BJ38+2791 -> 13516
A39: Yokohama | B39: JPYOK
A40: Tokyo | B40: JPTYO
A41: Nagoya* | B41: JPNGO
A42: Kobe* | B42: JPUKB
A43: Osaka* | B43: JPOSA
A44: Hakata* | B44: JPHKT
A45: *via Pusan only
A48: https://www.one-line.com/en/news/notice-emergency-fuel-surcharge-efs-implementation
A50: All POL except Ex JPN : Rates are inclusive of BRS/PSS/BAF/OBS/MBS/EFS subj HEA. LSF , CSS, SLF, THCS both end , Doc fees both end , prevailing surcharges in Opus and local charges
A51: Ex JPN : Rates are inclusive of BRS/ BAF / LSF only subj OBS , HEA ** CSS, SLF, THCS both end , Doc fees, PSS both end , prevailing surcharges in Opus and local charges
...

Sheet ISC_LK_BD_AE_PK
C1: From | D1: To
A2: Validity period | B2: ='China_TWN_SIN_HKG_KR Dry'!B4 -> FAK | C2: ='S.E.A_JPN_SA_AU_NZ Dry '!C4 -> 46249 | D2: ='S.E.A_JPN_SA_AU_NZ Dry '!D4 -> 46265
C4: POD
C5: Manzanillo,MX | F5: Lazaro Cardenas, MX | I5: San Antonio, CL | L5: Valparaiso, CL | O5: Callao, PE | R5: Coronel CL | U5: San Vicente CL | X5: Liquren, CL | AA5: Buenaventura, CO | AD5: Guayaquil, EC | AG5: Posorja, EC | AJ5: Iquique, CL | AM5: Antofagasta, CL | AP5: Puerto Angamos, CL | AS5: Ensenada, MX | AV5: Puerto Quetzal, GT | AY5: Rodman , PA | BB5: Panama City, PA (Door) (via Rodman, PA) | BE5: Arica | BH5: Puerto Caldera, CR | BK5: Acajutla, SV | BN5: Corinto, NI | BQ5: San Lorenzo CY/CY , HN (Via NICIO using Marex service - Trucking )
C6: MXZLO | F6: MXLZC | I6: CLSAI | L6: CLVAP | O6: PECLL | R6: CLCNL | U6: CLSVE | X6: CLLQN | AA6: COBUN | AD6: ECGYE | AG6: ECPSJ | AJ6: CLIQQ | AM6: CLANF | AP6: CLPAG | AS6: MXESE | AV6: GTPRQ | AY6: PAROD | BB6: PAPTY | BE6: CLARI | BH6: CRCAL | BK6: SVAQJ | BN6: NICIO | BQ6: HNSLO
A7: POR | B7: POR CODE | C7: 20' | D7: 40' | E7: HCD | F7: 20' | G7: 40' | H7: HCD | I7: 20' | J7: 40' | K7: HCD | L7: 20' | M7: 40' | N7: HCD | O7: 20' | P7: 40' | Q7: HCD | R7: 20' | S7: 40' | T7: HCD | U7: 20' | V7: 40' | W7: HCD | X7: 20' | Y7: 40' | Z7: HCD | AA7: 20' | AB7: 40' | AC7: HCD | AD7: 20' | AE7: 40' | AF7: HCD | AG7: 20' | AH7: 40' | AI7: HCD | AJ7: 20' | AK7: 40' | AL7: HCD | AM7: 20' | AN7: 40' | AO7: HCD | AP7: 20' | AQ7: 40' | AR7: HCD | AS7: 20' | AT7: 40' | AU7: HCD | AV7: 20' | AW7: 40' | AX7: HCD | AY7: 20' | AZ7: 40' | BA7: HCD | BB7: 20' | BC7: 40' | BD7: HCD | BE7: 20' | BF7: 40' | BG7: HCD | BH7: 20' | BI7: 40' | BJ7: HCD | BK7: 20' | BL7: 40' | BM7: HCD | BN7: 20' | BO7: 40' | BP7: HCD | BQ7: 20' | BR7: 40' | BS7: HCD
