Workbook

Sheet ex NEA to AUBNE_AUMEL
A1: ONE AU Minimum Rate Guideline
I3: ISSUE DATE: | J3: 46258
A4: Validity: | B4: 01 Sept to 14 Sept 2026 | D4: POD: Melbourne/Brisbane | G4: POD: Melbourne/Brisbane | I4: POD: Melbourne/Brisbane
B5: POL | C5: Service (for reference only, no need to file in rate filing) | D5: 20' | E5: 40' | F5: 40'HC | G5: 20'RF | H5: 40'HC RF | I5: 20'RAD | J5: 40'HC RAD | L5: Add-on Table
D6: USD | E6: USD | F6: USD | G6: USD | H6: USD | I6: USD | J6: USD
A7: North & Central China | B7: Qingdao | C7: AUN / AUE | D7: 2425 | E7: 4850 | F7: =E7 -> 4850 | G7: =D7+100 -> 2525 | H7: =F7+200 -> 5050 | I7: 1775 | J7: 3550
B8: Shanghai | C8: AUN / AUE / AUX | D8: =D7 -> 2425 | E8: =D8*2 -> 4850 | F8: =E8 -> 4850 | G8: =D8+100 -> 2525 | H8: =F8+200 -> 5050 | I8: =I7 -> 1775 | J8: =J7 -> 3550
B9: Ningbo | C9: AUN / AUE | D9: =D7 -> 2425 | E9: =D9*2 -> 4850 | F9: =E9 -> 4850 | G9: =D9+100 -> 2525 | H9: =F9+200 -> 5050 | I9: =I7 -> 1775 | J9: =J7 -> 3550
B10: Xingang | C10: AUN / AUE | D10: =D7+L10 -> 2625 | E10: =E7+M10 -> 5150 | F10: =F7+N10 -> 5150 | G10: =D10+100 -> 2725 | H10: =F10+200 -> 5350 | I10: =I7+L10 -> 1975 | J10: =J7+N10 -> 3850 | L10: 200 | M10: 300 | N10: 300 | P10: on top of Qingdao
B11: Dalian | C11: AUN / AUE | D11: =D7+L11 -> 2625 | E11: =E7+M11 -> 5150 | F11: =F7+N11 -> 5150 | L11: 200 | M11: 300 | N11: 300 | P11: on top of Qingdao
B12: Changsha | C12: AUN / AUE / AUX | D12: =$D$8+L12 -> 2825 | E12: =$E$8+M12 -> 5550 | F12: =E12 -> 5550 | L12: 400 | M12: 700 | N12: 700 | P12: on top of Shanghai
B13: Changshu | C13: AUN / AUE / AUX | D13: =$D$8+L13 -> 2625 | E13: =$E$8+M13 -> 5150 | F13: =E13 -> 5150 | L13: 200 | M13: 300 | N13: 300 | P13: on top of Shanghai
B14: Changzhou | C14: AUN / AUE / AUX | D14: =$D$8+L14 -> 2675 | E14: =$E$8+M14 -> 5250 | F14: =E14 -> 5250 | L14: 250 | M14: 400 | N14: 400 | P14: on top of Shanghai
B15: Chengdu | C15: AUN / AUE / AUX | D15: =$D$8+L15 -> 3625 | E15: =$E$8+M15 -> 6750 | F15: =E15 -> 6750 | L15: 1200 | M15: 1900 | N15: 1900 | P15: on top of Shanghai
B16: Chengdu (via CNYTN by rail) | C16: AUN / AUE | E16: =E44+M16 -> 5900 | F16: =E16 -> 5900 | M16: 1050 | N16: 1050 | P16: on top of Yantian
B17: Chongqing (via CNSHA) | C17: AUN / AUE / AUX | D17: =$D$8+L17 -> 2775 | E17: =$E$8+M17 -> 5750 | F17: =E17 -> 5750 | L17: 350 | M17: 900 | N17: 900 | P17: on top of Shanghai
B18: Chongqing (via CNYTN by rail) | C18: AUN / AUE | D18: =D44+1000 -> 3425 | E18: =E44+950 -> 5800 | F18: =E18 -> 5800
B19: Guiyang (via CNYTN by rail) | C19: AUN / AUE | D19: =D44+900 -> 3325 | E19: =E44+1000 -> 5850 | F19: =E19 -> 5850
B20: Jiangyin | C20: AUN / AUE / AUX | D20: =$D$8+L20 -> 2625 | E20: =$E$8+M20 -> 5150 | F20: =E20 -> 5150 | L20: 200 | M20: 300 | N20: 300 | P20: on top of Shanghai
B21: Jiujiang (CNJIU) | C21: AUN / AUE / AUX | D21: =$D$8+L21 -> 2775 | E21: =$E$8+M21 -> 5400 | F21: =E21 -> 5400 | L21: 350 | M21: 550 | N21: 550 | P21: on top of Shanghai
B22: Lianyungang | C22: AUN / AUE / AUX | D22: =D7+100 -> 2525 | E22: =E7+150 -> 5000 | F22: =F7+150 -> 5000 | L22: 200 | M22: 350 | N22: 350 | P22: on top of Qingdao
B23: Nanchang (via CNSHA) | C23: AUN / AUE / AUX | D23: =$D$8+L23 -> 2810 | E23: =$E$8+M23 -> 5500 | F23: =E23 -> 5500 | L23: 385 | M23: 650 | N23: 650 | P23: on top of Shanghai
B24: Nanchang (via CNYTN by rail) | C24: AUN / AUE | D24: =D44+645 -> 3070 | E24: =E44+825 -> 5675 | F24: =F44+825 -> 5675
B25: Nanjing | C25: AUN / AUE / AUX | D25: =D7+L25 -> 2675 | E25: =E7+M25 -> 5250 | F25: =F7+N25 -> 5250 | L25: 250 | M25: 400 | N25: 400 | P25: on top of Shanghai
B26: Nantong | C26: AUN / AUE / AUX | D26: =$D$8+L26 -> 2675 | E26: =$E$8+M26 -> 5250 | F26: =E26 -> 5250 | L26: 250 | M26: 400 | N26: 400 | P26: on top of Shanghai
B27: Shidao | C27: AUN / AUE | D27: =$D$7+L27 -> 2625 | E27: =$E$7+M27 -> 5150 | F27: =E27 -> 5150 | L27: 200 | M27: 300 | N27: 300 | P27: on top of Qingdao
B28: Taicang | C28: AUN / AUE / AUX | D28: =$D$8+L28 -> 2625 | E28: =$E$8+M28 -> 5150 | F28: =E28 -> 5150 | L28: 200 | M28: 300 | N28: 300 | P28: on top of Shanghai
B29: Taizhou, Jiangsu | C29: AUN / AUE / AUX | D29: =$D$8+L29 -> 2675 | E29: =$E$8+M29 -> 5250 | F29: =E29 -> 5250 | L29: 250 | M29: 400 | N29: 400 | P29: on top of Shanghai
B30: Wenzhou | C30: AUN / AUE | D30: =$D$9+L30 -> 2625 | E30: =$E$9+M30 -> 5150 | F30: =E30 -> 5150 | L30: 200 | M30: 300 | N30: 300 | P30: on top of Ningbo
B31: Wuhan | C31: AUN / AUE / AUX | D31: =$D$8+L31 -> 2725 | E31: =$E$8+M31 -> 5425 | F31: =E31 -> 5425 | L31: 300 | M31: 575 | N31: 575 | P31: on top of Shanghai
B32: Wuhu | C32: AUN / AUE / AUX | D32: =$D$8+L32 -> 2725 | E32: =$E$8+M32 -> 5225 | F32: =E32 -> 5225 | L32: 300 | M32: 375 | N32: 375 | P32: on top of Shanghai
B33: Yangzhou | C33: AUN / AUE / AUX | D33: =$D$8+L33 -> 2700 | E33: =$E$8+M33 -> 5225 | F33: =E33 -> 5225 | L33: 275 | M33: 375 | N33: 375 | P33: on top of Shanghai
B34: Yantai | C34: AUN / AUE | D34: =$D$7+L34 -> 2625 | E34: =$E$7+M34 -> 5150 | F34: =E34 -> 5150 | L34: 200 | M34: 300 | N34: 300 | P34: on top of Qingdao
B35: Yueyang | C35: AUN / AUE / AUX | D35: =$D$8+L35 -> 2700 | E35: =$E$8+M35 -> 5525 | F35: =E35 -> 5525 | L35: 275 | M35: 675 | N35: 675 | P35: on top of Shanghai
B36: Zhangjiagang | C36: AUN / AUE / AUX | D36: =$D$8+L36 -> 2700 | E36: =$E$8+M36 -> 5225 | F36: =E36 -> 5225 | L36: 275 | M36: 375 | N36: 375 | P36: on top of Shanghai
B37: Zhenjiang | C37: AUN / AUE / AUX | D37: =$D$8+L37 -> 2675 | E37: =$E$8+M37 -> 5200 | F37: =E37 -> 5200 | L37: 250 | M37: 350 | N37: 350 | P37: on top of Shanghai
B38: Zhapu | C38: AUN / AUE | D38: =$D$9+L38 -> 2500 | E38: =$E$9+M38 -> 4975 | F38: =E38 -> 4975 | L38: 75 | M38: 125 | N38: 125 | P38: on top of Ningbo
A39: Fujian | B39: Xiamen | C39: AUN / AUE | D39: =D44+L39 -> 2575 | E39: =E44+200 -> 5050 | F39: =E39 -> 5050 | G39: =D39+100 -> 2675 | H39: =F39+200 -> 5250 | I39: =I44+L39 -> 1925 | J39: =J44+N39 -> 3750 | L39: 150 | M39: 200 | N39: 200
B40: Fuqing | C40: AUN / AUE | D40: =$D$39+L40 -> 2675 | E40: =$E$39+M40 -> 5250 | F40: =E40 -> 5250 | L40: 100 | M40: 200 | N40: 200
B41: Fuzhou | C41: AUN / AUE | D41: =$D$39+L41 -> 2825 | E41: =$E$39+M41 -> 5550 | F41: =E41 -> 5550 | L41: 250 | M41: 500 | N41: 500
...

Sheet ex NEA to AUSYD
A1: ONE AU Minimum Rate Guideline
I3: ISSUE DATE: | J3: ='ex NEA to AUBNE_AUMEL'!J3 -> 46258
A4: Validity: | B4: ='ex NEA to AUBNE_AUMEL'!B4 -> 01 Sept to 14 Sept 2026 | D4: POD: Sydney | G4: POD: Sydney | I4: POD: Sydney
B5: POL | C5: Service (for reference only, no need to file in rate filing) | D5: 20' | E5: 40' | F5: 40'HC | G5: 20'RF | H5: 40'HC RF | I5: 20'RAD | J5: 40'HC RAD | L5: Add-on Table
D6: USD | E6: USD | F6: USD | G6: USD | H6: USD | I6: USD | J6: USD
A7: North & Central China | B7: Qingdao | C7: AUN / AUE | D7: ='ex NEA to AUBNE_AUMEL'!D7 -> 2425 | E7: ='ex NEA to AUBNE_AUMEL'!E7 -> 4850 | F7: =E7 -> 4850 | G7: =D7+150 -> 2575 | H7: =E7+300 -> 5150 | I7: ='ex NEA to AUBNE_AUMEL'!I7+50 -> 1825 | J7: ='ex NEA to AUBNE_AUMEL'!J7+100 -> 3650
B8: Shanghai | C8: AUN / AUE / AUX | D8: =D7 -> 2425 | E8: ='ex NEA to AUBNE_AUMEL'!E8 -> 4850 | F8: =E8 -> 4850 | G8: =G7 -> 2575 | H8: =E8+300 -> 5150 | I8: ='ex NEA to AUBNE_AUMEL'!I8+50 -> 1825 | J8: ='ex NEA to AUBNE_AUMEL'!J8+100 -> 3650
B9: Ningbo | C9: AUN / AUE | D9: =D7 -> 2425 | E9: ='ex NEA to AUBNE_AUMEL'!E9 -> 4850 | F9: =E9 -> 4850 | G9: =G7 -> 2575 | H9: =E9+300 -> 5150 | I9: ='ex NEA to AUBNE_AUMEL'!I9+50 -> 1825 | J9: ='ex NEA to AUBNE_AUMEL'!J9+100 -> 3650
B10: Xingang | C10: AUN / AUE | D10: =D7+L10 -> 2625 | E10: =E7+M10 -> 5150 | F10: =F7+N10 -> 5150 | G10: =D10+150 -> 2775 | H10: =E10+300 -> 5450 | I10: ='ex NEA to AUBNE_AUMEL'!I10+50 -> 2025 | J10: ='ex NEA to AUBNE_AUMEL'!J10+100 -> 3950 | L10: 200 | M10: 300 | N10: 300 | P10: on top of Qingdao
B11: Dalian | C11: AUN / AUE | D11: =D7+L11 -> 2625 | E11: =E7+M11 -> 5150 | F11: =F7+N11 -> 5150 | L11: 200 | M11: 300 | N11: 300 | P11: on top of Qingdao
B12: Changsha | C12: AUN / AUE / AUX | D12: =$D$8+L12 -> 2825 | E12: =$E$8+M12 -> 5550 | F12: =E12 -> 5550 | L12: 400 | M12: 700 | N12: 700 | P12: on top of Shanghai
B13: Changshu | C13: AUN / AUE / AUX | D13: =$D$8+L13 -> 2625 | E13: =$E$8+M13 -> 5150 | F13: =E13 -> 5150 | L13: 200 | M13: 300 | N13: 300 | P13: on top of Shanghai
B14: Changzhou | C14: AUN / AUE / AUX | D14: =$D$8+L14 -> 2675 | E14: =$E$8+M14 -> 5250 | F14: =E14 -> 5250 | L14: 250 | M14: 400 | N14: 400 | P14: on top of Shanghai
B15: Chengdu | C15: AUN / AUE / AUX | D15: =$D$8+L15 -> 3625 | E15: =$E$8+M15 -> 6750 | F15: =E15 -> 6750 | L15: 1200 | M15: 1900 | N15: 1900 | P15: on top of Shanghai
B16: Chengdu (via CNYTN by rail) | C16: AUN / AUE | E16: =E44+M16 -> 5900 | F16: =E16 -> 5900 | M16: 1050 | N16: 1050
B17: Chongqing (via CNSHA) | C17: AUN / AUE / AUX | D17: =$D$8+L17 -> 2775 | E17: =$E$8+M17 -> 5750 | F17: =E17 -> 5750 | L17: 350 | M17: 900 | N17: 900 | P17: on top of Shanghai
B18: Chongqing (via CNYTN by rail) | C18: AUN / AUE | D18: =D44+1000 -> 3425 | E18: =E44+950 -> 5800 | F18: =E18 -> 5800
B19: Guiyang (via CNYTN by rail) | C19: AUN / AUE | D19: =D44+900 -> 3325 | E19: =E44+1000 -> 5850 | F19: =E19 -> 5850
B20: Jiangyin | C20: AUN / AUE / AUX | D20: =$D$8+L20 -> 2625 | E20: =$E$8+M20 -> 5150 | F20: =E20 -> 5150 | L20: 200 | M20: 300 | N20: 300 | P20: on top of Shanghai
B21: Jiujiang (CNJIU) | C21: AUN / AUE / AUX | D21: =$D$8+L21 -> 2775 | E21: =$E$8+M21 -> 5400 | F21: =E21 -> 5400 | L21: 350 | M21: 550 | N21: 550 | P21: on top of Shanghai
B22: Lianyungang | C22: AUN / AUE / AUX | D22: =D7+100 -> 2525 | E22: =E7+150 -> 5000 | F22: =F7+150 -> 5000 | L22: 200 | M22: 350 | N22: 350 | P22: on top of Qingdao
B23: Nanchang (via CNSHA) | C23: AUN / AUE / AUX | D23: =$D$8+L23 -> 2810 | E23: =$E$8+M23 -> 5500 | F23: =E23 -> 5500 | L23: 385 | M23: 650 | N23: 650 | P23: on top of Shanghai
B24: Nanchang (via CNYTN by rail) | C24: AUN / AUE | D24: =D44+645 -> 3070 | E24: =E44+825 -> 5675 | F24: =F44+825 -> 5675
B25: Nanjing | C25: AUN / AUE / AUX | D25: =D7+L25 -> 2675 | E25: =E7+M25 -> 5250 | F25: =F7+N25 -> 5250 | L25: 250 | M25: 400 | N25: 400 | P25: on top of Shanghai
B26: Nantong | C26: AUN / AUE / AUX | D26: =$D$8+L26 -> 2675 | E26: =$E$8+M26 -> 5250 | F26: =E26 -> 5250 | L26: 250 | M26: 400 | N26: 400 | P26: on top of Shanghai
B27: Shidao | C27: AUN / AUE | D27: =$D$7+L27 -> 2625 | E27: =$E$7+M27 -> 5150 | F27: =E27 -> 5150 | L27: 200 | M27: 300 | N27: 300 | P27: on top of Qingdao
B28: Taicang | C28: AUN / AUE / AUX | D28: =$D$8+L28 -> 2625 | E28: =$E$8+M28 -> 5150 | F28: =E28 -> 5150 | L28: 200 | M28: 300 | N28: 300 | P28: on top of Shanghai
B29: Taizhou, Jiangsu | C29: AUN / AUE / AUX | D29: =$D$8+L29 -> 2675 | E29: =$E$8+M29 -> 5250 | F29: =E29 -> 5250 | L29: 250 | M29: 400 | N29: 400 | P29: on top of Shanghai
B30: Wenzhou | C30: AUN / AUE | D30: =$D$9+L30 -> 2625 | E30: =$E$9+M30 -> 5150 | F30: =E30 -> 5150 | L30: 200 | M30: 300 | N30: 300 | P30: on top of Ningbo
B31: Wuhan | C31: AUN / AUE / AUX | D31: =$D$8+L31 -> 2725 | E31: =$E$8+M31 -> 5425 | F31: =E31 -> 5425 | L31: 300 | M31: 575 | N31: 575 | P31: on top of Shanghai
B32: Wuhu | C32: AUN / AUE / AUX | D32: =$D$8+L32 -> 2725 | E32: =$E$8+M32 -> 5225 | F32: =E32 -> 5225 | L32: 300 | M32: 375 | N32: 375 | P32: on top of Shanghai
B33: Yangzhou | C33: AUN / AUE / AUX | D33: =$D$8+L33 -> 2700 | E33: =$E$8+M33 -> 5225 | F33: =E33 -> 5225 | L33: 275 | M33: 375 | N33: 375 | P33: on top of Shanghai
B34: Yantai | C34: AUN / AUE | D34: =$D$7+L34 -> 2625 | E34: =$E$7+M34 -> 5150 | F34: =E34 -> 5150 | L34: 200 | M34: 300 | N34: 300 | P34: on top of Qingdao
B35: Yueyang | C35: AUN / AUE / AUX | D35: =$D$8+L35 -> 2700 | E35: =$E$8+M35 -> 5525 | F35: =E35 -> 5525 | L35: 275 | M35: 675 | N35: 675 | P35: on top of Shanghai
B36: Zhangjiagang | C36: AUN / AUE / AUX | D36: =$D$8+L36 -> 2700 | E36: =$E$8+M36 -> 5225 | F36: =E36 -> 5225 | L36: 275 | M36: 375 | N36: 375 | P36: on top of Shanghai
B37: Zhenjiang | C37: AUN / AUE / AUX | D37: =$D$8+L37 -> 2675 | E37: =$E$8+M37 -> 5200 | F37: =E37 -> 5200 | L37: 250 | M37: 350 | N37: 350 | P37: on top of Shanghai
B38: Zhapu | C38: AUN / AUE | D38: =$D$9+L38 -> 2500 | E38: =$E$9+M38 -> 4975 | F38: =E38 -> 4975 | L38: 75 | M38: 125 | N38: 125 | P38: on top of Ningbo
A39: Fujian | B39: Xiamen | C39: AUN / AUE | D39: ='ex NEA to AUBNE_AUMEL'!D39 -> 2575 | E39: ='ex NEA to AUBNE_AUMEL'!E39 -> 5050 | F39: =E39 -> 5050 | G39: =D39+150 -> 2725 | H39: =E39+300 -> 5350 | I39: ='ex NEA to AUBNE_AUMEL'!I39+50 -> 1975 | J39: ='ex NEA to AUBNE_AUMEL'!J39+100 -> 3850 | L39: 150 | M39: 200 | N39: 200
B40: Fuqing | C40: AUN / AUE | D40: =$D$39+L40 -> 2675 | E40: =$E$39+M40 -> 5250 | F40: =E40 -> 5250 | L40: 100 | M40: 200 | N40: 200
B41: Fuzhou | C41: AUN / AUE | D41: =$D$39+L41 -> 2825 | E41: =$E$39+M41 -> 5550 | F41: =E41 -> 5550 | L41: 250 | M41: 500 | N41: 500
...

Sheet ex NEA to AUBNE on NZJ
A1: ONE AU Minimum Rate Guideline (NZJ)
I3: ISSUE DATE: | J3: ='ex NEA to AUBNE_AUMEL'!J3 -> 46258
A4: Validity: | B4: ='ex NEA to AUBNE_AUMEL'!B4 -> 01 Sept to 14 Sept 2026 | D4: POD: Brisbane | G4: POD: Brisbane | I4: POD: Brisbane
B5: POL | C5: Service | D5: 20' | E5: 40' | F5: 40'HC | G5: 20'RF | H5: 40'HC RF | I5: 20'RAD | J5: 40'HC RAD | N5: Add-on table
D6: USD | E6: USD | F6: USD | G6: USD | H6: USD | I6: USD | J6: USD
A7: China | B7: Qingdao | C7: NZJ (only) | D7: =D8+N7 -> 2525 | E7: =E8+O7 -> 5050 | F7: =F8+P7 -> 5050 | N7: 100 | O7: 200 | P7: 200
B8: Shanghai | C8: NZJ (only) | D8: ='ex NEA to AUBNE_AUMEL'!D8 -> 2425 | E8: ='ex NEA to AUBNE_AUMEL'!E8 -> 4850 | F8: =E8 -> 4850 | G8: ='ex NEA to AUBNE_AUMEL'!G8 -> 2525 | H8: ='ex NEA to AUBNE_AUMEL'!H8 -> 5050 | I8: ='ex NEA to AUBNE_AUMEL'!I8 -> 1775 | J8: ='ex NEA to AUBNE_AUMEL'!J8 -> 3550
B9: Ningbo | C9: NZJ (only) | D9: =D8+N9 -> 2525 | E9: =E8+O9 -> 5050 | F9: =F8+P9 -> 5050 | N9: 100 | O9: 200 | P9: 200
B10: Xingang | C10: NZJ (only) | D10: =D7+N10 -> 2725 | E10: =E7+O10 -> 5350 | F10: =F7+P10 -> 5350 | N10: 200 | O10: 300 | P10: 300 | Q10: on top of Qingdao
B11: Dalian | C11: NZJ (only) | D11: =D7+N11 -> 2725 | E11: =E7+O11 -> 5350 | F11: =F7+P11 -> 5350 | N11: 200 | O11: 300 | P11: 300 | Q11: on top of Qingdao
B12: Changsha | C12: NZJ (only) | D12: =$D$8+N12 -> 2825 | E12: =$E$8+O12 -> 5550 | F12: =E12 -> 5550 | N12: 400 | O12: 700 | P12: 700 | Q12: on top of Shanghai
B13: Changshu | C13: NZJ (only) | D13: =$D$8+N13 -> 2625 | E13: =$E$8+O13 -> 5150 | F13: =E13 -> 5150 | N13: 200 | O13: 300 | P13: 300 | Q13: on top of Shanghai
B14: Changzhou | C14: NZJ (only) | D14: =$D$8+N14 -> 2675 | E14: =$E$8+O14 -> 5250 | F14: =E14 -> 5250 | N14: 250 | O14: 400 | P14: 400 | Q14: on top of Shanghai
B15: Chengdu | C15: NZJ (only) | D15: =$D$8+N15 -> 3625 | E15: =$E$8+O15 -> 6750 | F15: =E15 -> 6750 | N15: 1200 | O15: 1900 | P15: 1900 | Q15: on top of Shanghai
B16: Chengdu (via CNYTN by rail) | C16: NZJ (only) | E16: =$E$44+O16 -> 5900 | F16: =E16 -> 5900 | O16: 1050 | P16: 1050
B17: Chongqing (via CNSHA) | C17: NZJ (only) | D17: =$D$8+N17 -> 2775 | E17: =$E$8+O17 -> 5750 | F17: =E17 -> 5750 | N17: 350 | O17: 900 | P17: 900 | Q17: on top of Shanghai
B18: Chongqing (via CNYTN by rail) | C18: NZJ (only) | D18: =D44+1000 -> 3425 | E18: =E44+950 -> 5800 | F18: =E18 -> 5800
B19: Guiyang (via CNYTN by rail) | C19: NZJ (only) | D19: =D44+900 -> 3325 | E19: =E44+1000 -> 5850 | F19: =E19 -> 5850
B20: Jiangyin | C20: NZJ (only) | D20: =$D$8+N20 -> 2625 | E20: =$E$8+O20 -> 5150 | F20: =E20 -> 5150 | N20: 200 | O20: 300 | P20: 300 | Q20: on top of Shanghai
B21: Jiujiang (CNJIU) | C21: NZJ (only) | D21: =$D$8+N21 -> 2775 | E21: =$E$8+O21 -> 5400 | F21: =E21 -> 5400 | N21: 350 | O21: 550 | P21: 550 | Q21: on top of Shanghai
B22: Lianyungang | C22: NZJ (only) | D22: =D7+100 -> 2625 | E22: =E7+150 -> 5200 | F22: =F7+150 -> 5200 | N22: 200 | O22: 350 | P22: 350 | Q22: on top of Qingdao
B23: Nanchang (via CNSHA) | C23: NZJ (only) | D23: =$D$8+N23 -> 2810 | E23: =$E$8+O23 -> 5500 | F23: =E23 -> 5500 | N23: 385 | O23: 650 | P23: 650 | Q23: on top of Shanghai
B24: Nanchang (via CNYTN by rail) | C24: NZJ (only) | D24: =D44+645 -> 3070 | E24: =E44+825 -> 5675 | F24: =F44+825 -> 5675
B25: Nanjing | C25: NZJ (only) | D25: =D8+N25 -> 2675 | E25: =E8+O25 -> 5250 | F25: =F8+P25 -> 5250 | N25: 250 | O25: 400 | P25: 400 | Q25: on top of Shanghai
B26: Nantong | C26: NZJ (only) | D26: =$D$8+N26 -> 2675 | E26: =$E$8+O26 -> 5250 | F26: =E26 -> 5250 | N26: 250 | O26: 400 | P26: 400 | Q26: on top of Shanghai
B27: Shidao | C27: NZJ (only) | D27: =D7+N27 -> 2725 | E27: =E7+O27 -> 5350 | F27: =F7+P27 -> 5350 | N27: 200 | O27: 300 | P27: 300 | Q27: on top of Qingdao
B28: Taicang | C28: NZJ (only) | D28: =$D$8+N28 -> 2625 | E28: =$E$8+O28 -> 5150 | F28: =E28 -> 5150 | N28: 200 | O28: 300 | P28: 300 | Q28: on top of Shanghai
B29: Taizhou, Jiangsu | C29: NZJ (only) | D29: =$D$8+N29 -> 2675 | E29: =$E$8+O29 -> 5250 | F29: =E29 -> 5250 | N29: 250 | O29: 400 | P29: 400 | Q29: on top of Shanghai
B30: Wenzhou | C30: NZJ (only) | D30: =D9+N30 -> 2725 | E30: =E9+O30 -> 5350 | F30: =F9+P30 -> 5350 | N30: 200 | O30: 300 | P30: 300 | Q30: on top of Ningbo
B31: Wuhan | C31: NZJ (only) | D31: =$D$8+N31 -> 2725 | E31: =$E$8+O31 -> 5425 | F31: =E31 -> 5425 | N31: 300 | O31: 575 | P31: 575 | Q31: on top of Shanghai
B32: Wuhu | C32: NZJ (only) | D32: =$D$8+N32 -> 2725 | E32: =$E$8+O32 -> 5225 | F32: =E32 -> 5225 | N32: 300 | O32: 375 | P32: 375 | Q32: on top of Shanghai
B33: Yangzhou | C33: NZJ (only) | D33: =$D$8+N33 -> 2700 | E33: =$E$8+O33 -> 5225 | F33: =E33 -> 5225 | N33: 275 | O33: 375 | P33: 375 | Q33: on top of Shanghai
B34: Yantai | C34: NZJ (only) | D34: =D7+N34 -> 2725 | E34: =E7+O34 -> 5350 | F34: =F7+P34 -> 5350 | N34: 200 | O34: 300 | P34: 300 | Q34: on top of Qingdao
B35: Yueyang | C35: NZJ (only) | D35: =$D$8+N35 -> 2700 | E35: =$E$8+O35 -> 5525 | F35: =E35 -> 5525 | N35: 275 | O35: 675 | P35: 675 | Q35: on top of Shanghai
B36: Zhangjiagang | C36: NZJ (only) | D36: =$D$8+N36 -> 2700 | E36: =$E$8+O36 -> 5225 | F36: =E36 -> 5225 | N36: 275 | O36: 375 | P36: 375 | Q36: on top of Shanghai
B37: Zhenjiang | C37: NZJ (only) | D37: =$D$8+N37 -> 2675 | E37: =$E$8+O37 -> 5200 | F37: =E37 -> 5200 | N37: 250 | O37: 350 | P37: 350 | Q37: on top of Shanghai
B38: Zhapu | C38: NZJ (only) | D38: =D9+N38 -> 2600 | E38: =E9+O38 -> 5175 | F38: =E38 -> 5175 | N38: 75 | O38: 125 | P38: 125 | Q38: on top of Ningbo
A39: Fujian | B39: Xiamen | C39: NZJ (only) | D39: ='ex NEA to AUBNE_AUMEL'!D39 -> 2575 | E39: ='ex NEA to AUBNE_AUMEL'!E39 -> 5050 | F39: =E39 -> 5050 | G39: ='ex NEA to AUBNE_AUMEL'!G39 -> 2675 | H39: ='ex NEA to AUBNE_AUMEL'!H39 -> 5250 | I39: ='ex NEA to AUBNE_AUMEL'!I39 -> 1925 | J39: ='ex NEA to AUBNE_AUMEL'!J39 -> 3750 | N39: 150 | O39: 200 | P39: 200
B40: Fuqing | C40: NZJ (only) | D40: =$D$39+N40 -> 2675 | E40: =$E$39+O40 -> 5250 | F40: =E40 -> 5250 | N40: 100 | O40: 200 | P40: 200
B41: Fuzhou | C41: NZJ (only) | D41: =$D$39+N41 -> 2825 | E41: =$E$39+O41 -> 5550 | F41: =E41 -> 5550 | N41: 250 | O41: 500 | P41: 500
...
