Workbook

Sheet ex NEA to AUFRE
A1: ONE Minimum Rate Guideline
A3: Validity: | B3: 15 Aug to 31 Aug 2026 | I3: ISSUE DATE: | J3: 46241
B4: POL | C4: POD | D4: Service | E4: 20' | F4: 40' | G4: 40'HC | H4: 20'Reefer | I4: 40'HC Reefer | J4: 20'NOR | K4: 40'HC NOR
E5: USD | F5: USD | G5: USD | H5: USD | I5: USD | J5: USD | K5: USD
A6: China | B6: Qingdao | C6: Fremantle | D6: WAU | E6: 2200 | F6: 4400 | G6: =F6 -> 4400 | H6: =E6+100 -> 2300 | I6: =G6+200 -> 4600 | J6: 1900
B7: Shanghai | C7: Fremantle | D7: WAU | E7: =E6 -> 2200 | F7: =F6 -> 4400 | G7: =F7 -> 4400 | H7: =H6 -> 2300 | I7: =I6 -> 4600 | J7: =J6 -> 1900
B8: Ningbo | C8: Fremantle | D8: WAU | E8: =E6 -> 2200 | F8: =F6 -> 4400 | G8: =F8 -> 4400 | H8: =H6 -> 2300 | I8: =I6 -> 4600 | J8: =J6 -> 1900
B9: Xingang | C9: Fremantle | D9: WAU | E9: =E6 -> 2200 | F9: =F6 -> 4400 | G9: =F9 -> 4400 | H9: =H6 -> 2300 | I9: =I6 -> 4600 | J9: =J6 -> 1900
B10: Dalian | C10: Fremantle | D10: WAU | E10: =E6+M10 -> 2400 | F10: =F6+N10 -> 4600 | G10: =F10 -> 4600 | M10: 200 | N10: 200 | O10: 200 | P10: on top of Qingdao
B11: Changsha | C11: Fremantle | D11: WAU | E11: =$E$7+M11 -> 2600 | F11: =$F$7+N11 -> 5100 | G11: =F11 -> 5100 | M11: 400 | N11: 700 | O11: 700 | P11: on top of Shanghai
B12: Changshu | C12: Fremantle | D12: WAU | E12: =$E$7+M12 -> 2400 | F12: =$F$7+N12 -> 4600 | G12: =F12 -> 4600 | M12: 200 | N12: 200 | O12: 200 | P12: on top of Shanghai
B13: Changzhou | C13: Fremantle | D13: WAU | E13: =$E$7+M13 -> 2450 | F13: =$F$7+N13 -> 4800 | G13: =F13 -> 4800 | M13: 250 | N13: 400 | O13: 400 | P13: on top of Shanghai
B14: Chengdu | C14: Fremantle | D14: WAU | E14: =$E$7+M14 -> 3700 | F14: =$F$7+N14 -> 6900 | G14: =F14 -> 6900 | M14: 1500 | N14: 2500 | O14: 2500 | P14: on top of Shanghai
B15: Chengdu (via CNYTN by rail) | C15: Fremantle | D15: WAU | F15: =F43+N15 -> 5450 | G15: =F15 -> 5450 | N15: 1050 | O15: 1050 | P15: on top of Yantian
B16: Chongqing (via CNSHA) | C16: Fremantle | D16: WAU | E16: =$E$7+M16 -> 2550 | F16: =$F$7+N16 -> 5300 | G16: =F16 -> 5300 | M16: 350 | N16: 900 | O16: 900 | P16: on top of Shanghai
B17: Chongqing (via CNYTN by rail) | C17: Fremantle | D17: WAU | E17: =E43+M17 -> 3200 | F17: =F43+N17 -> 5350 | G17: =F17 -> 5350 | I17: =IFERROR(__xludf.DUMMYFUNCTION("AI(""Fill an appropriate value for this cell based on the table context"")"),"") | M17: 1000 | N17: 950 | O17: 950 | P17: on top of Yantian
B18: Guiyang (via CNYTN by rail) | C18: Fremantle | D18: WAU | E18: =E42+900 -> 3100 | F18: =F42+1000 -> 5400 | G18: =G42+1000 -> 5400
B19: Jiangyin | C19: Fremantle | D19: WAU | E19: =$E$7+M19 -> 2400 | F19: =$F$7+N19 -> 4650 | G19: =F19 -> 4650 | M19: 200 | N19: 250 | O19: 250 | P19: on top of Shanghai
B20: Jiujiang (CNJIU) | C20: Fremantle | D20: WAU | E20: =$E$7+M20 -> 2550 | F20: =$F$7+N20 -> 4950 | G20: =F20 -> 4950 | M20: 350 | N20: 550 | O20: 550 | P20: on top of Shanghai
B21: Lianyungang | C21: Fremantle | D21: WAU | E21: =$E$6+M21 -> 2300 | F21: =$F$6+N21 -> 4550 | G21: =F21 -> 4550 | M21: 100 | N21: 150 | O21: 150 | P21: on top of Qingdao
B22: Nanchang (via CNSHA) | C22: Fremantle | D22: WAU | E22: =$E$7+M22 -> 2585 | F22: =$F$7+N22 -> 5050 | G22: =F22 -> 5050 | M22: 385 | N22: 650 | O22: 650 | P22: on top of Shanghai
B23: Nanchang (via CNYTN by rail) | C23: Fremantle | D23: WAU | E23: =E43+M23 -> 2845 | F23: =F43+N23 -> 5225 | G23: =G43+O23 -> 5225 | M23: 645 | N23: 825 | O23: 825 | P23: on top of Yantian
B24: Nanjing | C24: Fremantle | D24: WAU | E24: =$E$7+M24 -> 2450 | F24: =$F$7+N24 -> 4800 | G24: =F24 -> 4800 | M24: 250 | N24: 400 | O24: 400 | P24: on top of Shanghai
B25: Nantong | C25: Fremantle | D25: WAU | E25: =$E$7+M25 -> 2450 | F25: =$F$7+N25 -> 4800 | G25: =F25 -> 4800 | M25: 250 | N25: 400 | O25: 400 | P25: on top of Shanghai
B26: Shidao | C26: Fremantle | D26: WAU | E26: =$E$6+M26 -> 2400 | F26: =$F$6+N26 -> 4650 | G26: =F26 -> 4650 | M26: 200 | N26: 250 | O26: 250 | P26: on top of Qingdao
B27: Taicang | C27: Fremantle | D27: WAU | E27: =$E$7+M27 -> 2400 | F27: =$F$7+N27 -> 4700 | G27: =F27 -> 4700 | M27: 200 | N27: 300 | O27: 300 | P27: on top of Shanghai
B28: Taizhou, Jiangsu | C28: Fremantle | D28: WAU | E28: =$E$7+M28 -> 2450 | F28: =$F$7+N28 -> 4800 | G28: =F28 -> 4800 | M28: 250 | N28: 400 | O28: 400 | P28: on top of Shanghai
B29: Wenzhou | C29: Fremantle | D29: WAU | E29: =$E$8+M29 -> 2400 | F29: =$F$8+N29 -> 4600 | G29: =F29 -> 4600 | M29: 200 | N29: 200 | O29: 200 | P29: on top of Ningbo
B30: Wuhan | C30: Fremantle | D30: WAU | E30: =$E$7+M30 -> 2500 | F30: =$F$7+N30 -> 4975 | G30: =F30 -> 4975 | M30: 300 | N30: 575 | O30: 575 | P30: on top of Shanghai
B31: Wuhu | C31: Fremantle | D31: WAU | E31: =$E$7+M31 -> 2500 | F31: =$F$7+N31 -> 4775 | G31: =F31 -> 4775 | M31: 300 | N31: 375 | O31: 375 | P31: on top of Shanghai
B32: Yangzhou | C32: Fremantle | D32: WAU | E32: =$E$7+M32 -> 2475 | F32: =$F$7+N32 -> 4775 | G32: =F32 -> 4775 | M32: 275 | N32: 375 | O32: 375 | P32: on top of Shanghai
B33: Yantai | C33: Fremantle | D33: WAU | E33: =$E$6+M33 -> 2400 | F33: =$F$6+N33 -> 4600 | G33: =F33 -> 4600 | M33: 200 | N33: 200 | O33: 200 | P33: on top of Qingdao
B34: Yueyang | C34: Fremantle | D34: WAU | E34: =$E$7+M34 -> 2475 | F34: =$F$7+N34 -> 5075 | G34: =F34 -> 5075 | M34: 275 | N34: 675 | O34: 675 | P34: on top of Shanghai
B35: Zhangjiagang | C35: Fremantle | D35: WAU | E35: =$E$7+M35 -> 2475 | F35: =$F$7+N35 -> 4775 | G35: =F35 -> 4775 | M35: 275 | N35: 375 | O35: 375 | P35: on top of Shanghai
B36: Zhenjiang | C36: Fremantle | D36: WAU | E36: =$E$7+M36 -> 2450 | F36: =$F$7+N36 -> 4750 | G36: =F36 -> 4750 | M36: 250 | N36: 350 | O36: 350 | P36: on top of Shanghai
B37: Zhapu | C37: Fremantle | D37: WAU | E37: =$E$8+M37 -> 2300 | F37: =$F$8+N37 -> 4525 | G37: =F37 -> 4525 | M37: 100 | N37: 125 | O37: 125 | P37: on top of Ningbo
A38: Fujian | B38: Xiamen | C38: Fremantle | D38: WAU | E38: =E6 -> 2200 | F38: =F6 -> 4400 | G38: =F38 -> 4400 | H38: =H6 -> 2300 | I38: =I6 -> 4600 | J38: =J6 -> 1900 | K38: =K6
B39: Fuqing | C39: Fremantle | D39: WAU | E39: =$E$38+M39 -> 2300 | F39: =$F$38+N39 -> 4600 | G39: =F39 -> 4600 | M39: 100 | N39: 200 | O39: 200
B40: Fuzhou | C40: Fremantle | D40: WAU | E40: =$E$38+M40 -> 2450 | F40: =$F$38+N40 -> 4900 | G40: =F40 -> 4900 | M40: 250 | N40: 500 | O40: 500
B41: Mawei | C41: Fremantle | D41: WAU | E41: =$E$38+M41 -> 2450 | F41: =$F$38+N41 -> 4900 | G41: =F41 -> 4900 | M41: 250 | N41: 500 | O41: 500
...

Sheet ex NEA to AUADL 
A1: ONE Minimum Rate Guideline
A3: Validity: | B3: ='ex NEA to AUFRE'!B3 -> 15 Aug to 31 Aug 2026 | J3: ISSUE DATE: | K3: ='ex NEA to AUFRE'!J3 -> 46241
B4: POL | C4: POD | D4: Service | E4: 20' | F4: 40' | G4: 40'HC | H4: 20'Reefer | I4: 40'HC Reefer | J4: 20'NOR | K4: 40'HC NOR
E5: USD | F5: USD | G5: USD | H5: USD | I5: USD | J5: USD | K5: USD
A6: China | B6: Qingdao | C6: Adelaide | D6: AU1 | E6: ='ex NEA to AUFRE'!E6+50 -> 2250 | F6: =E6*2 -> 4500 | G6: =F6 -> 4500 | H6: =E6+150 -> 2400 | I6: =G6+300 -> 4800 | J6: ='ex NEA to AUFRE'!J6+50 -> 1950
B7: Shanghai | C7: Adelaide | D7: AU1 | E7: =E6 -> 2250 | F7: =F6 -> 4500 | G7: =F7 -> 4500 | H7: =H6 -> 2400 | I7: =I6 -> 4800 | J7: =J6 -> 1950
B8: Ningbo | C8: Adelaide | D8: AU1 | E8: =E6 -> 2250 | F8: =F6 -> 4500 | G8: =F8 -> 4500 | H8: =H6 -> 2400 | I8: =I6 -> 4800 | J8: =J6 -> 1950
B9: Xingang | C9: Adelaide | D9: AU1 | E9: =E6 -> 2250 | F9: =F6 -> 4500 | G9: =F9 -> 4500 | H9: =H6 -> 2400 | I9: =I6 -> 4800 | J9: =J6 -> 1950
B10: Dalian | C10: Adelaide | D10: AU1 | E10: =E6+M10 -> 2450 | F10: =F6+N10 -> 4700 | G10: =F10 -> 4700 | M10: 200 | N10: 200 | O10: 200 | P10: on top of Qingdao
B11: Changsha | C11: Adelaide | D11: AU1 | E11: =$E$7+M11 -> 2650 | F11: =$F$7+N11 -> 5200 | G11: =F11 -> 5200 | M11: 400 | N11: 700 | O11: 700 | P11: on top of Shanghai
B12: Changshu | C12: Adelaide | D12: AU1 | E12: =$E$7+M12 -> 2450 | F12: =$F$7+N12 -> 4700 | G12: =F12 -> 4700 | M12: 200 | N12: 200 | O12: 200 | P12: on top of Shanghai
B13: Changzhou | C13: Adelaide | D13: AU1 | E13: =$E$7+M13 -> 2500 | F13: =$F$7+N13 -> 4900 | G13: =F13 -> 4900 | M13: 250 | N13: 400 | O13: 400 | P13: on top of Shanghai
B14: Chengdu | C14: Adelaide | D14: AU1 | E14: =$E$7+M14 -> 3750 | F14: =$F$7+N14 -> 7000 | G14: =F14 -> 7000 | M14: 1500 | N14: 2500 | O14: 2500 | P14: on top of Shanghai
B15: Chengdu (via CNYTN by rail) | C15: Adelaide | D15: AU1 | F15: =F43+N15 -> 5550 | G15: =F15 -> 5550 | N15: 1050 | O15: 1050 | P15: on top of Yantian
B16: Chongqing (via CNSHA) | C16: Adelaide | D16: AU1 | E16: =$E$7+M16 -> 2600 | F16: =$F$7+N16 -> 5400 | G16: =F16 -> 5400 | M16: 350 | N16: 900 | O16: 900 | P16: on top of Shanghai
B17: Chongqing (via CNYTN by rail) | C17: Adelaide | D17: AU1 | E17: =E43+M17 -> 3250 | F17: =F44+N17 -> 5450 | G17: =F17 -> 5450 | M17: 1000 | N17: 950 | O17: 950 | P17: on top of Yantian
B18: Guiyang (via CNYTN by rail) | C18: Adelaide | D18: AU1 | E18: =E42+900 -> 3150 | F18: =F42+1000 -> 5500 | G18: =G42+1000 -> 5500
B19: Jiangyin | C19: Adelaide | D19: AU1 | E19: =$E$7+M19 -> 2450 | F19: =$F$7+N19 -> 4750 | G19: =F19 -> 4750 | M19: 200 | N19: 250 | O19: 250 | P19: on top of Shanghai
B20: Jiujiang (CNJIU) | C20: Adelaide | D20: AU1 | E20: =$E$7+M20 -> 2600 | F20: =$F$7+N20 -> 5050 | G20: =F20 -> 5050 | M20: 350 | N20: 550 | O20: 550 | P20: on top of Shanghai
B21: Lianyungang | C21: Adelaide | D21: AU1 | E21: =$E$6+M21 -> 2350 | F21: =$F$6+N21 -> 4650 | G21: =F21 -> 4650 | M21: 100 | N21: 150 | O21: 150 | P21: on top of Qingdao
B22: Nanchang | C22: Adelaide | D22: AU1 | E22: =$E$7+M22 -> 2635 | F22: =$F$7+N22 -> 5150 | G22: =F22 -> 5150 | M22: 385 | N22: 650 | O22: 650 | P22: on top of Shanghai
B23: Nanchang (via CNYTN by rail) | C23: Adelaide | D23: AU1 | E23: =E43+M23 -> 2895 | F23: =F43+N23 -> 5325 | G23: =G43+O23 -> 5325 | M23: 645 | N23: 825 | O23: 825 | P23: on top of Yantian
B24: Nanjing | C24: Adelaide | D24: AU1 | E24: =$E$7+M24 -> 2500 | F24: =$F$7+N24 -> 4900 | G24: =F24 -> 4900 | M24: 250 | N24: 400 | O24: 400 | P24: on top of Shanghai
B25: Nantong | C25: Adelaide | D25: AU1 | E25: =$E$7+M25 -> 2500 | F25: =$F$7+N25 -> 4900 | G25: =F25 -> 4900 | M25: 250 | N25: 400 | O25: 400 | P25: on top of Shanghai
B26: Shidao | C26: Adelaide | D26: AU1 | E26: =$E$6+M26 -> 2450 | F26: =$F$6+N26 -> 4750 | G26: =F26 -> 4750 | M26: 200 | N26: 250 | O26: 250 | P26: on top of Qingdao
B27: Taicang | C27: Adelaide | D27: AU1 | E27: =$E$7+M27 -> 2450 | F27: =$F$7+N27 -> 4800 | G27: =F27 -> 4800 | M27: 200 | N27: 300 | O27: 300 | P27: on top of Shanghai
B28: Taizhou, Jiangsu | C28: Adelaide | D28: AU1 | E28: =$E$7+M28 -> 2500 | F28: =$F$7+N28 -> 4900 | G28: =F28 -> 4900 | M28: 250 | N28: 400 | O28: 400 | P28: on top of Shanghai
B29: Wenzhou | C29: Adelaide | D29: AU1 | E29: =$E$8+M29 -> 2450 | F29: =$F$8+N29 -> 4700 | G29: =F29 -> 4700 | M29: 200 | N29: 200 | O29: 200 | P29: on top of Ningbo
B30: Wuhan | C30: Adelaide | D30: AU1 | E30: =$E$7+M30 -> 2550 | F30: =$F$7+N30 -> 5075 | G30: =F30 -> 5075 | M30: 300 | N30: 575 | O30: 575 | P30: on top of Shanghai
B31: Wuhu | C31: Adelaide | D31: AU1 | E31: =$E$7+M31 -> 2550 | F31: =$F$7+N31 -> 4875 | G31: =F31 -> 4875 | M31: 300 | N31: 375 | O31: 375 | P31: on top of Shanghai
B32: Yangzhou | C32: Adelaide | D32: AU1 | E32: =$E$7+M32 -> 2525 | F32: =$F$7+N32 -> 4875 | G32: =F32 -> 4875 | M32: 275 | N32: 375 | O32: 375 | P32: on top of Shanghai
B33: Yantai | C33: Adelaide | D33: AU1 | E33: =$E$6+M33 -> 2450 | F33: =$F$6+N33 -> 4700 | G33: =F33 -> 4700 | M33: 200 | N33: 200 | O33: 200 | P33: on top of Qingdao
B34: Yueyang | C34: Adelaide | D34: AU1 | E34: =$E$7+M34 -> 2525 | F34: =$F$7+N34 -> 5175 | G34: =F34 -> 5175 | M34: 275 | N34: 675 | O34: 675 | P34: on top of Shanghai
B35: Zhangjiagang | C35: Adelaide | D35: AU1 | E35: =$E$7+M35 -> 2525 | F35: =$F$7+N35 -> 4875 | G35: =F35 -> 4875 | M35: 275 | N35: 375 | O35: 375 | P35: on top of Shanghai
B36: Zhenjiang | C36: Adelaide | D36: AU1 | E36: =$E$7+M36 -> 2500 | F36: =$F$7+N36 -> 4850 | G36: =F36 -> 4850 | M36: 250 | N36: 350 | O36: 350 | P36: on top of Shanghai
B37: Zhapu | C37: Adelaide | D37: AU1 | E37: =$E$8+M37 -> 2350 | F37: =$F$8+N37 -> 4625 | G37: =F37 -> 4625 | M37: 100 | N37: 125 | O37: 125 | P37: on top of Ningbo
A38: Fujian | B38: Xiamen | C38: Adelaide | D38: AU1 | E38: =E6 -> 2250 | F38: =F6 -> 4500 | G38: =F38 -> 4500 | H38: =H6 -> 2400 | I38: =I6 -> 4800 | J38: =J6 -> 1950 | K38: =K6
B39: Fuqing | C39: Adelaide | D39: AU1 | E39: =$E$38+M39 -> 2350 | F39: =$F$38+N39 -> 4700 | G39: =F39 -> 4700 | M39: 100 | N39: 200 | O39: 200
B40: Fuzhou | C40: Adelaide | D40: AU1 | E40: =$E$38+M40 -> 2500 | F40: =$F$38+N40 -> 5000 | G40: =F40 -> 5000 | M40: 250 | N40: 500 | O40: 500
B41: Mawei | C41: Adelaide | D41: AU1 | E41: =$E$38+M41 -> 2500 | F41: =$F$38+N41 -> 5000 | G41: =F41 -> 5000 | M41: 250 | N41: 500 | O41: 500
...
